Workbook

Sheet Audiobook Inputs
B2: Audiobook Assumptions | C2: FY'24 | D2: FY'25 | E2: FY'26E | F2: FY'27E | H2: Notes
B4: Case selector (repoint to Valuation!$C$3 when the tabs are added to the model) | C4: Base | H4: Drives the licensing-cost growth assumption in section E. Bear = adverse for SPOT (faster cost growth).
B6: A. Group revenue, €M (denominator for basis points)
B7: Total revenue | C7: 15673 | D7: 17186 | E7: 19500 | F7: 21300 | H7: FY'24-FY'25: Form 20-F. FY'26E-FY'27E: placeholders, link to IS total revenue.
B9: B. Bundle royalty saving: MLC contingency disclosed in Spotify filings, €M cumulative from 1 Mar 2024
B10: 6-K Q2-24: cumulative to 30 Jun 2024 | C10: 46 | H10: 6-K Q2-24 legal proceedings note: 'approximately €46 million, of which approximately €35 million relates to the three months ended June 30, 2024'. Additional royalties due to the MLC if Premium were not a bundle.
B11: of which Apr-Jun 2024 | C11: 35 | H11: Same sentence; implies March 2024 alone was about €11M.
B12: 6-K Q3-24: cumulative to 30 Sep 2024 | C12: 94 | H12: 6-K Q3-24 legal proceedings note.
B13: 20-F FY24: cumulative to 31 Dec 2024 | C13: 150 | H13: Form 20-F FY2024, legal proceedings.
B14: 6-K Q1-25: cumulative to 31 Mar 2025 | C14: 205 | H14: 6-K Q1-25 legal proceedings note.
B15: 6-K Q2-25: cumulative to 30 Jun 2025 | C15: 256 | H15: 6-K Q2-25 legal proceedings note.
B16: 6-K Q3-25: cumulative to 30 Sep 2025 | C16: 308 | H16: 6-K Q3-25: first filing to add 'any liability would be partially offset by direct deals with publishers'.
B17: 20-F FY25: cumulative to 31 Dec 2025 | C17: 358 | H17: Form 20-F FY2025, legal proceedings.
B18: 6-K Q1-26: cumulative to 31 Mar 2026 | C18: 410 | H18: 6-K Q1-26 (about $473M at the time; NMPA cited 'nearly $480 million by Spotify's own admission').
B19: 6-K Q2-26: cumulative to 30 Jun 2026 (verify) | C19: 437 | H19: Quoted by Music Ally, 7 Sep 2026, as €437M. A second reading of the same filing gives €473M, which is also the dollar value of the Q1-26 figure. Verify in the Q2-26 6-K before quoting.
B20: Gross bundle saving, forecast placeholders | E20: 205 | F20: 205 | H20: FY'26E: 4 x the average quarterly increment from Q2-25 to Q1-26 (€51M). FY'27E: flat; the Phonorecords IV settlement that permits the bundle rate runs to end-2027. Link to model.
B22: C. Bundle saving cross-check: Billboard analysis of Spotify's MLC reports, paid tiers
B23: Mechanical royalties paid to the MLC, Q4-23, $M | C23: 97.3 | H23: Billboard, 'How Much Have Spotify Bundles Decreased the Mechanical Per-Stream Rate? (Analysis)'.
B24: Mechanical royalties paid to the MLC, Q4-25, $M | C24: 53.3 | H24: Same analysis; down 45%.
B25: Blended per-stream mechanical rate, Q4-23, $ | C25: 0.00068 | H25: Same analysis.
B26: Blended per-stream mechanical rate, Q4-25, $ | C26: 0.00033 | H26: Same analysis; down 51%. Streams grew about 19bn between the two quarters.
B27: EUR/USD, Q4-25 average | C27: 1.16 | H27: Approximate.
B29: D. Direct publisher deals that hand part of the saving back (share of US mechanicals in FY'24 column; start month in FY'25 column)
B30: Universal Music Publishing Group | C30: 0.22 | D30: 2 | H30: Announced 26 Jan 2025 (MBW); reported to nullify the bundle discount going forward. Share: estimate from US publishing market rankings (range 20-25%).
B31: Warner Chappell Music | C31: 0.13 | D31: 3 | H31: Announced 6 Feb 2025 (MBW): 'supersedes the bundling payment structure'; terms 'continue to recognize a difference between bundled and music-only listeners'. Share: estimate (11-15%).
B32: Kobalt | C32: 0.05 | D32: 9 | H32: Announced 13 Aug 2025 (CMU, MBW): 'bespoke terms rather than the compulsory licence rates'. Share: estimate (4-7%).
B33: Sony Music Publishing | C33: 0.26 | D33: 10 | H33: Announced 18 Sep 2025 (MBW, Variety); SMP ranked #1 publisher in every quarter of 2025. Share: estimate (23-28%).
B34: BMG | C34: 0.03 | D34: 11 | H34: Announced 9 Oct 2025 (CMU). Share: estimate (2-4%).
B35: Restoration of the bundle discount in the direct deals | C35: 0.75 | H35: Estimate. Spotify calls the offset 'partial'; the Warner terms still distinguish bundled from music-only listeners while payments are 'substantially improved'. Range 50-100%.
B36: MLC amended complaint succeeds in FY'27 (1 = yes) | C36: 0 | H36: Scenario switch: the independents' share of the saving goes to zero. Dismissed Jan 2025; amended complaint Oct 2025; interlocutory appeal denied 1 Sep 2026; fact discovery cutoff 13 Mar 2027; no trial date.
B38: E. Audiobook licensing cost paid to book publishers (included and paid hours)
B39: FY'24 cost anchor, €M | C39: 190 | H39: Spotify via Axios, 15 Oct 2024: paying publishers 'hundreds of millions of dollars a year' (repeated Mar-25; 'tens of millions' by Feb-24 per Digital Music News). Read as about $205M for the full year at a 1.08 average rate. Cross-check: APA 2025 US publisher receipts $2.43B x 10-14% Spotify share x 1.4 non-US / 1.13 = €301-421M for 2025 vs €300M modelled.
B40: Licensing cost growth, % y/y | D40: 0.58 | E40: =IF('Audiobook Inputs'!$C$4="Bear",E41,IF('Audiobook Inputs'!$C$4="Bull",E43,E42)) -> 0.43 | F40: =IF('Audiobook Inputs'!$C$4="Bear",F41,IF('Audiobook Inputs'!$C$4="Bull",F43,F42)) -> 0.3 | H40: FY'25: Spotify newsroom Oct 2025, hours +37% like-for-like, times about 1.15 for the wider paying base (Family and Duo members, DACH, France and Benelux annualising). FY'26E: Investor Day May 2026, listeners +60%, cost at about 0.7x listener growth. FY'27E: assumed deceleration. Scenario rows below; Bear = faster cost growth.
B41: Bear | E41: 0.6 | F41: 0.45
B42: Base | E42: 0.43 | F42: 0.3
B43: Bull | E43: 0.3 | F43: 0.2
B45: F. Paid audiobook revenue, €M (Audiobooks+, top-ups, a la carte)
B46: Paid audiobook revenue | C46: 5 | D46: 30 | E46: 75 | F46: 120 | H46: FY'24: top-ups only from Mar-24, estimate. FY'25: US Audiobooks+ from Aug-25 at $11.99 plus 11 EU markets late in the year, estimate. FY'26E: $100M ARR reached Jul-26 (Q2-26 call) is about €88M run-rate; full year lower. FY'27E: +60%. Link to model.
B47: Context: Audiobooks+ ARR, $M (Jul-26) and paying users, M (May-26) | C47: 100 | D47: 1 | H47: Investor Day 21 May 2026 via Publishers Weekly: 'more than one million' payers, 'on track for $100M ARR in July'; Q2-26 call: reached.
B49: G. Consensus gross-margin expansion, bp (context only)
...

Sheet Audiobook GM Bridge
B2: Audiobook Gross Margin Bridge | C2: FY'24 | D2: FY'25 | E2: FY'26E | F2: FY'27E | H2: Notes
B4: € in millions unless stated. N = B + A - C: B = bundle royalty saving retained, A = paid audiobook revenue, C = audiobook licensing cost paid to book publishers.
B6: 1. Bundle Royalty Saving (B)
B7: MLC contingency by filing, €M | C7: Cumulative | D7: Increment | E7: Months | F7: €M / month
B8: 6-K Q2-24 (30 Jun 2024) | C8: ='Audiobook Inputs'!$C$10 -> 46 | D8: =C8 -> 46 | E8: 4 | F8: =D8/E8 -> 11.5
B9: 6-K Q3-24 (30 Sep 2024) | C9: ='Audiobook Inputs'!$C$12 -> 94 | D9: =C9-C8 -> 48 | E9: 3 | F9: =D9/E9 -> 16
B10: 20-F FY24 (31 Dec 2024) | C10: ='Audiobook Inputs'!$C$13 -> 150 | D10: =C10-C9 -> 56 | E10: 3 | F10: =D10/E10 -> 18.666667
B11: 6-K Q1-25 (31 Mar 2025) | C11: ='Audiobook Inputs'!$C$14 -> 205 | D11: =C11-C10 -> 55 | E11: 3 | F11: =D11/E11 -> 18.333333
B12: 6-K Q2-25 (30 Jun 2025) | C12: ='Audiobook Inputs'!$C$15 -> 256 | D12: =C12-C11 -> 51 | E12: 3 | F12: =D12/E12 -> 17
B13: 6-K Q3-25 (30 Sep 2025) | C13: ='Audiobook Inputs'!$C$16 -> 308 | D13: =C13-C12 -> 52 | E13: 3 | F13: =D13/E13 -> 17.333333
B14: 20-F FY25 (31 Dec 2025) | C14: ='Audiobook Inputs'!$C$17 -> 358 | D14: =C14-C13 -> 50 | E14: 3 | F14: =D14/E14 -> 16.666667
B15: 6-K Q1-26 (31 Mar 2026) | C15: ='Audiobook Inputs'!$C$18 -> 410 | D15: =C15-C14 -> 52 | E15: 3 | F15: =D15/E15 -> 17.333333
B16: 6-K Q2-26 (30 Jun 2026): verify | C16: ='Audiobook Inputs'!$C$19 -> 437 | D16: =C16-C15 -> 27 | E16: 3 | F16: =D16/E16 -> 9
B17: of which Apr-Jun 2024 (March 2024 alone about €11M) | C17: ='Audiobook Inputs'!$C$11 -> 35 | E17: 3 | F17: =C17/E17 -> 11.666667
B18: Average quarterly increment, Q2-25 to Q1-26 (x4 annualised in next column) | C18: =AVERAGE(D12:D15) -> 51.25 | D18: =C18*4 -> 205 | H18: Increments ran €50-56M a quarter with no step down after the direct deals, so the figure is gross: every paid-tier stream is still reported through the MLC at the bundle rate and the direct-licensed publishers receive a top-up outside it.
B20: Billboard cross-check (paid tiers) | C20: Q4-23 | D20: Q4-25
B21: Mechanical royalties paid to the MLC, $M | C21: ='Audiobook Inputs'!$C$23 -> 97.3 | D21: ='Audiobook Inputs'!$C$24 -> 53.3
B22: Blended per-stream rate, $ | C22: ='Audiobook Inputs'!$C$25 -> 0.00068 | D22: ='Audiobook Inputs'!$C$26 -> 0.00033
B23: Implied streams, bn | C23: =C21/C22/1000 -> 143.08824 | D23: =D21/D22/1000 -> 161.51515
B24: Implied Q4-25 discount: streams x Q4-23 rate less paid, $M (col D); in €M (col E) vs 20-F FY25 increment (col F) | D24: =D23*C22*1000-D21 -> 56.530303 | E24: =D24/'Audiobook Inputs'!$C$27 -> 48.73302 | F24: =D14 -> 50 | H24: Two sources that share no inputs agree on a gross discount of about €50M a quarter. Streams grew between the quarters, so direct-licensed publishers have not left the blanket licence.
B26: Gross saving, hand-back, B | C26: FY'24 | D26: FY'25 | E26: FY'26E | F26: FY'27E
B27: Gross bundle saving | C27: ='Audiobook Inputs'!$C$13 -> 150 | D27: ='Audiobook Inputs'!$C$17-'Audiobook Inputs'!$C$13 -> 208 | E27: ='Audiobook Inputs'!$E$20 -> 205 | F27: ='Audiobook Inputs'!$F$20 -> 205 | H27: FY'24 and FY'25 straight from the filings; FY'26E-FY'27E are placeholders on the inputs tab.
B28: Months on direct licence by publisher | G28: Share
B29: Universal Music Publishing Group | C29: 0 | D29: =13-'Audiobook Inputs'!$D$30 -> 11 | E29: 12 | F29: 12 | G29: ='Audiobook Inputs'!$C$30 -> 0.22
B30: Warner Chappell Music | C30: 0 | D30: =13-'Audiobook Inputs'!$D$31 -> 10 | E30: 12 | F30: 12 | G30: ='Audiobook Inputs'!$C$31 -> 0.13
B31: Kobalt | C31: 0 | D31: =13-'Audiobook Inputs'!$D$32 -> 4 | E31: 12 | F31: 12 | G31: ='Audiobook Inputs'!$C$32 -> 0.05
B32: Sony Music Publishing | C32: 0 | D32: =13-'Audiobook Inputs'!$D$33 -> 3 | E32: 12 | F32: 12 | G32: ='Audiobook Inputs'!$C$33 -> 0.26
B33: BMG | C33: 0 | D33: =13-'Audiobook Inputs'!$D$34 -> 2 | E33: 12 | F33: 12 | G33: ='Audiobook Inputs'!$C$34 -> 0.03
B34: Sum of shares on direct licences (independents are the remainder) | G34: =SUM(G29:G33) -> 0.69
B35: Restoration of the discount in the direct deals | G35: ='Audiobook Inputs'!$C$35 -> 0.75
B36: Hand-back = gross x sum(share x months / 12) x restoration | C36: =C27*SUMPRODUCT($G$29:$G$33,C29:C33)/12*$G$35 -> 0 | D36: =D27*SUMPRODUCT($G$29:$G$33,D29:D33)/12*$G$35 -> 61.88 | E36: =E27*SUMPRODUCT($G$29:$G$33,E29:E33)/12*$G$35 -> 106.0875 | F36: =F27*SUMPRODUCT($G$29:$G$33,F29:F33)/12*$G$35 -> 106.0875
B37: B: Net bundle saving retained by Spotify | C37: =C27-C36 -> 150 | D37: =D27-D36 -> 146.12 | E37: =E27-E36 -> 98.9125 | F37: =IF('Audiobook Inputs'!$C$36=1,F27*$G$34*(1-$G$35),F27-F36) -> 98.9125 | H37: FY'27E: if the MLC switch on the inputs tab is 1, the independents' share of the saving goes to zero.
B39: 2. Audiobook Licensing Cost (C)
B40: % y/y Growth | D40: ='Audiobook Inputs'!$D$40 -> 0.58 | E40: ='Audiobook Inputs'!$E$40 -> 0.43 | F40: ='Audiobook Inputs'!$F$40 -> 0.3 | H40: FY'26E-FY'27E follow the case selector on the inputs tab (Bear / Base / Bull rows).
B41: C: Licensing cost paid to book publishers | C41: ='Audiobook Inputs'!$C$39 -> 190 | D41: =C41*(1+D40) -> 300.2 | E41: =D41*(1+E40) -> 429.286 | F41: =E41*(1+F40) -> 558.0718 | H41: FY'24 anchored on Spotify's 'hundreds of millions of dollars a year' (Oct-24); grown by consumption.
B43: 3. Paid Audiobook Revenue (A)
B44: A: Paid audiobook revenue | C44: ='Audiobook Inputs'!$C$46 -> 5 | D44: ='Audiobook Inputs'!$D$46 -> 30 | E44: ='Audiobook Inputs'!$E$46 -> 75 | F44: ='Audiobook Inputs'!$F$46 -> 120 | H44: Counted in full: C is grown on total consumption, so it already carries the publisher cost of paid hours.
B46: 4. Net Contribution to Gross Profit and Gross Margin
B47: B: Net bundle saving retained | C47: =C37 -> 150 | D47: =D37 -> 146.12 | E47: =E37 -> 98.9125 | F47: =F37 -> 98.9125
B48: A: Paid audiobook revenue | C48: =C44 -> 5 | D48: =D44 -> 30 | E48: =E44 -> 75 | F48: =F44 -> 120
...
