Workbook

Sheet Audiobook Inputs
B2: Audiobook Assumptions | C2: FY'24 | D2: FY'25 | E2: FY'26E | F2: FY'27E | G2: FY'28E | H2: FY'29E | I2: FY'30E | K2: Notes
B4: Case selector | C4: =Valuation!$C$3 -> Base | K4: Linked to Valuation!C3. Drives the licensing-cost growth assumption in section E. Bear = adverse for SPOT (faster cost growth).
B6: A. Group revenue, €M (denominator for basis points)
B7: Total revenue | C7: =RPM!L58 -> 15673 | D7: =RPM!Q58 -> 17186 | E7: =RPM!V58 -> 19410 | F7: =RPM!AA58 -> 21172 | G7: =RPM!AB58 -> 23166 | H7: =RPM!AC58 -> 25017 | I7: =RPM!AD58 -> 26482 | K7: Linked to RPM row 58 (FY'24-FY'25 actual, FY'26-FY'30 projection).
B9: B. Bundle royalty saving: MLC contingency disclosed in Spotify filings, €M cumulative from 1 Mar 2024
B10: 6-K Q2-24: cumulative to 30 Jun 2024 | C10: 46 | K10: 6-K Q2-24 legal proceedings note: 'approximately €46 million, of which approximately €35 million relates to the three months ended June 30, 2024'.
B11: of which Apr-Jun 2024 | C11: 35 | K11: Same sentence; implies March 2024 alone was about €11M.
B12: 6-K Q3-24: cumulative to 30 Sep 2024 | C12: 94 | K12: 6-K Q3-24 legal proceedings note.
B13: 20-F FY24: cumulative to 31 Dec 2024 | C13: 150 | K13: Form 20-F FY2024, legal proceedings.
B14: 6-K Q1-25: cumulative to 31 Mar 2025 | C14: 205 | K14: 6-K Q1-25 legal proceedings note.
B15: 6-K Q2-25: cumulative to 30 Jun 2025 | C15: 256 | K15: 6-K Q2-25 legal proceedings note.
B16: 6-K Q3-25: cumulative to 30 Sep 2025 | C16: 308 | K16: 6-K Q3-25: first filing to add 'any liability would be partially offset by direct deals with publishers'.
B17: 20-F FY25: cumulative to 31 Dec 2025 | C17: 358 | K17: Form 20-F FY2025, legal proceedings.
B18: 6-K Q1-26: cumulative to 31 Mar 2026 | C18: 410 | K18: 6-K Q1-26 (about $473M at the time).
B19: 6-K Q2-26: cumulative to 30 Jun 2026 (verify) | C19: 437 | K19: Quoted by Music Ally, 7 Sep 2026, as €437M; a second reading gives €473M. Verify in the Q2-26 6-K before quoting.
B20: Gross bundle saving, forecast placeholders | E20: 205 | F20: 205 | G20: 205 | H20: 205 | I20: 205 | K20: FY'26E: 4 x the average quarterly increment Q2-25 to Q1-26 (€51M). FY'27E-FY'30E: held flat; the Phonorecords IV settlement that permits the bundle rate runs to end-2027 and Phonorecords V is open, so flat is the neutral assumption.
B22: C. Bundle saving cross-check: Billboard analysis of Spotify's MLC reports, paid tiers
B23: Mechanical royalties paid to the MLC, Q4-23, $M | C23: 97.3 | K23: Billboard, 'How Much Have Spotify Bundles Decreased the Mechanical Per-Stream Rate? (Analysis)'.
B24: Mechanical royalties paid to the MLC, Q4-25, $M | C24: 53.3 | K24: Same analysis; down 45%.
B25: Blended per-stream mechanical rate, Q4-23, $ | C25: 0.00068 | K25: Same analysis.
B26: Blended per-stream mechanical rate, Q4-25, $ | C26: 0.00033 | K26: Same analysis; down 51%.
B27: EUR/USD, Q4-25 average | C27: 1.16 | K27: Approximate.
B29: D. Direct publisher deals that hand part of the saving back (share of US mechanicals in FY'24 column; start month in FY'25 column)
B30: Universal Music Publishing Group | C30: 0.22 | D30: 2 | K30: Announced 26 Jan 2025 (MBW). Share: estimate (20-25%).
B31: Warner Chappell Music | C31: 0.13 | D31: 3 | K31: Announced 6 Feb 2025 (MBW). Share: estimate (11-15%).
B32: Kobalt | C32: 0.05 | D32: 9 | K32: Announced 13 Aug 2025 (CMU, MBW). Share: estimate (4-7%).
B33: Sony Music Publishing | C33: 0.26 | D33: 10 | K33: Announced 18 Sep 2025 (MBW, Variety). Share: estimate (23-28%).
B34: BMG | C34: 0.03 | D34: 11 | K34: Announced 9 Oct 2025 (CMU). Share: estimate (2-4%).
B35: Restoration of the bundle discount in the direct deals | C35: 0.75 | K35: Estimate; range 50-100%.
B36: MLC amended complaint succeeds in FY'27 (1 = yes) | C36: 0 | K36: Scenario switch: from FY'27E the independents' share of the saving goes to zero.
B38: E. Audiobook licensing cost paid to book publishers (included and paid hours)
B39: FY'24 cost anchor, €M | C39: 190 | K39: Spotify via Axios, 15 Oct 2024: 'hundreds of millions of dollars a year'; read as ~$205M at 1.08.
B40: Licensing cost growth, % y/y | D40: 0.58 | E40: =IF('Audiobook Inputs'!$C$4="Bear",E41,IF('Audiobook Inputs'!$C$4="Bull",E43,E42)) -> 0.43 | F40: =IF('Audiobook Inputs'!$C$4="Bear",F41,IF('Audiobook Inputs'!$C$4="Bull",F43,F42)) -> 0.3 | G40: =IF('Audiobook Inputs'!$C$4="Bear",G41,IF('Audiobook Inputs'!$C$4="Bull",G43,G42)) -> 0.2 | H40: =IF('Audiobook Inputs'!$C$4="Bear",H41,IF('Audiobook Inputs'!$C$4="Bull",H43,H42)) -> 0.14 | I40: =IF('Audiobook Inputs'!$C$4="Bear",I41,IF('Audiobook Inputs'!$C$4="Bull",I43,I42)) -> 0.1 | K40: FY'25: hours +37% like-for-like (Spotify newsroom Oct 2025) x ~1.15 for the wider paying base. FY'26E: Investor Day May 2026, listeners +60%, cost at ~0.7x. FY'27E-FY'30E: deceleration toward revenue growth as the hour cap binds and the listener base matures. Scenario rows below; Bear = faster cost growth.
B41: Bear | E41: 0.6 | F41: 0.45 | G41: 0.3 | H41: 0.22 | I41: 0.15
B42: Base | E42: 0.43 | F42: 0.3 | G42: 0.2 | H42: 0.14 | I42: 0.1
B43: Bull | E43: 0.3 | F43: 0.2 | G43: 0.15 | H43: 0.1 | I43: 0.07
B45: F. Paid audiobook revenue, €M (Audiobooks+, top-ups, a la carte)
B46: Paid audiobook revenue | C46: 5 | D46: 30 | E46: 75 | F46: 120 | G46: 165 | H46: 210 | I46: 250 | K46: FY'24-FY'25 estimates; FY'26E: $100M ARR reached Jul-26; FY'27E +60%; FY'28E-FY'30E +38%, +27%, +19% as payer growth decelerates. Placeholders; link to model.
B47: Context: Audiobooks+ ARR, $M (Jul-26) and paying users, M (May-26) | C47: 100 | D47: 1 | K47: Investor Day 21 May 2026 via Publishers Weekly; Q2-26 call: $100M ARR reached.
B49: G. Consensus gross-margin expansion, bp (context only)
...

Sheet Audiobook GM Bridge
B2: Audiobook Gross Margin Bridge | C2: FY'24 | D2: FY'25 | E2: FY'26E | F2: FY'27E | G2: FY'28E | H2: FY'29E | I2: FY'30E | K2: Notes
B4: € in millions unless stated. N = B + A - C: B = bundle royalty saving retained, A = paid audiobook revenue, C = audiobook licensing cost paid to book publishers.
B6: 1. Bundle Royalty Saving (B)
B7: MLC contingency by filing, €M | C7: Cumulative | D7: Increment | E7: Months | F7: €M / month
B8: 6-K Q2-24 (30 Jun 2024) | C8: ='Audiobook Inputs'!$C$10 -> 46 | D8: =C8 -> 46 | E8: 4 | F8: =D8/E8 -> 11.5
B9: 6-K Q3-24 (30 Sep 2024) | C9: ='Audiobook Inputs'!$C$12 -> 94 | D9: =C9-C8 -> 48 | E9: 3 | F9: =D9/E9 -> 16
B10: 20-F FY24 (31 Dec 2024) | C10: ='Audiobook Inputs'!$C$13 -> 150 | D10: =C10-C9 -> 56 | E10: 3 | F10: =D10/E10 -> 18.666667
B11: 6-K Q1-25 (31 Mar 2025) | C11: ='Audiobook Inputs'!$C$14 -> 205 | D11: =C11-C10 -> 55 | E11: 3 | F11: =D11/E11 -> 18.333333
B12: 6-K Q2-25 (30 Jun 2025) | C12: ='Audiobook Inputs'!$C$15 -> 256 | D12: =C12-C11 -> 51 | E12: 3 | F12: =D12/E12 -> 17
B13: 6-K Q3-25 (30 Sep 2025) | C13: ='Audiobook Inputs'!$C$16 -> 308 | D13: =C13-C12 -> 52 | E13: 3 | F13: =D13/E13 -> 17.333333
B14: 20-F FY25 (31 Dec 2025) | C14: ='Audiobook Inputs'!$C$17 -> 358 | D14: =C14-C13 -> 50 | E14: 3 | F14: =D14/E14 -> 16.666667
B15: 6-K Q1-26 (31 Mar 2026) | C15: ='Audiobook Inputs'!$C$18 -> 410 | D15: =C15-C14 -> 52 | E15: 3 | F15: =D15/E15 -> 17.333333
B16: 6-K Q2-26 (30 Jun 2026): verify | C16: ='Audiobook Inputs'!$C$19 -> 437 | D16: =C16-C15 -> 27 | E16: 3 | F16: =D16/E16 -> 9
B17: of which Apr-Jun 2024 (March 2024 alone about €11M) | C17: ='Audiobook Inputs'!$C$11 -> 35 | E17: 3 | F17: =C17/E17 -> 11.666667
B18: Average quarterly increment, Q2-25 to Q1-26 (x4 annualised in next column) | C18: =AVERAGE(D12:D15) -> 51.25 | D18: =C18*4 -> 205 | K18: Increments ran €50-56M a quarter with no step down after the direct deals, so the figure is gross.
B20: Billboard cross-check (paid tiers) | C20: Q4-23 | D20: Q4-25
B21: Mechanical royalties paid to the MLC, $M | C21: ='Audiobook Inputs'!$C$23 -> 97.3 | D21: ='Audiobook Inputs'!$C$24 -> 53.3
B22: Blended per-stream rate, $ | C22: ='Audiobook Inputs'!$C$25 -> 0.00068 | D22: ='Audiobook Inputs'!$C$26 -> 0.00033
B23: Implied streams, bn | C23: =C21/C22/1000 -> 143.08824 | D23: =D21/D22/1000 -> 161.51515
B24: Implied Q4-25 discount: streams x Q4-23 rate less paid, $M (col D); in €M (col E) vs 20-F FY25 increment (col F) | D24: =D23*C22*1000-D21 -> 56.530303 | E24: =D24/'Audiobook Inputs'!$C$27 -> 48.73302 | F24: =D14 -> 50 | K24: Two independent sources agree on a gross discount of about €50M a quarter.
B26: Gross saving, hand-back, B | C26: FY'24 | D26: FY'25 | E26: FY'26E | F26: FY'27E | G26: FY'28E | H26: FY'29E | I26: FY'30E
B27: Gross bundle saving | C27: ='Audiobook Inputs'!$C$13 -> 150 | D27: ='Audiobook Inputs'!$C$17-'Audiobook Inputs'!$C$13 -> 208 | E27: ='Audiobook Inputs'!$E$20 -> 205 | F27: ='Audiobook Inputs'!$F$20 -> 205 | G27: ='Audiobook Inputs'!$G$20 -> 205 | H27: ='Audiobook Inputs'!$H$20 -> 205 | I27: ='Audiobook Inputs'!$I$20 -> 205 | K27: FY'24 and FY'25 from the filings; FY'26E-FY'30E placeholders on the inputs tab.
B28: Months on direct licence by publisher | J28: Share
B29: Universal Music Publishing Group | C29: 0 | D29: =13-'Audiobook Inputs'!$D$30 -> 11 | E29: 12 | F29: 12 | G29: 12 | H29: 12 | I29: 12 | J29: ='Audiobook Inputs'!$C$30 -> 0.22
B30: Warner Chappell Music | C30: 0 | D30: =13-'Audiobook Inputs'!$D$31 -> 10 | E30: 12 | F30: 12 | G30: 12 | H30: 12 | I30: 12 | J30: ='Audiobook Inputs'!$C$31 -> 0.13
B31: Kobalt | C31: 0 | D31: =13-'Audiobook Inputs'!$D$32 -> 4 | E31: 12 | F31: 12 | G31: 12 | H31: 12 | I31: 12 | J31: ='Audiobook Inputs'!$C$32 -> 0.05
B32: Sony Music Publishing | C32: 0 | D32: =13-'Audiobook Inputs'!$D$33 -> 3 | E32: 12 | F32: 12 | G32: 12 | H32: 12 | I32: 12 | J32: ='Audiobook Inputs'!$C$33 -> 0.26
B33: BMG | C33: 0 | D33: =13-'Audiobook Inputs'!$D$34 -> 2 | E33: 12 | F33: 12 | G33: 12 | H33: 12 | I33: 12 | J33: ='Audiobook Inputs'!$C$34 -> 0.03
B34: Sum of shares on direct licences (independents are the remainder) | J34: =SUM(J29:J33) -> 0.69
B35: Restoration of the discount in the direct deals | J35: ='Audiobook Inputs'!$C$35 -> 0.75
B36: Hand-back = gross x sum(share x months / 12) x restoration | C36: =C27*SUMPRODUCT($J$29:$J$33,C29:C33)/12*$J$35 -> 0 | D36: =D27*SUMPRODUCT($J$29:$J$33,D29:D33)/12*$J$35 -> 61.88 | E36: =E27*SUMPRODUCT($J$29:$J$33,E29:E33)/12*$J$35 -> 106.0875 | F36: =F27*SUMPRODUCT($J$29:$J$33,F29:F33)/12*$J$35 -> 106.0875 | G36: =G27*SUMPRODUCT($J$29:$J$33,G29:G33)/12*$J$35 -> 106.0875 | H36: =H27*SUMPRODUCT($J$29:$J$33,H29:H33)/12*$J$35 -> 106.0875 | I36: =I27*SUMPRODUCT($J$29:$J$33,I29:I33)/12*$J$35 -> 106.0875
B37: B: Net bundle saving retained by Spotify | C37: =C27-C36 -> 150 | D37: =D27-D36 -> 146.12 | E37: =E27-E36 -> 98.9125 | F37: =IF('Audiobook Inputs'!$C$36=1,F27*$J$34*(1-$J$35),F27-F36) -> 98.9125 | G37: =IF('Audiobook Inputs'!$C$36=1,G27*$J$34*(1-$J$35),G27-G36) -> 98.9125 | H37: =IF('Audiobook Inputs'!$C$36=1,H27*$J$34*(1-$J$35),H27-H36) -> 98.9125 | I37: =IF('Audiobook Inputs'!$C$36=1,I27*$J$34*(1-$J$35),I27-I36) -> 98.9125 | K37: From FY'27E: if the MLC switch on the inputs tab is 1, the independents' share of the saving goes to zero.
B39: 2. Audiobook Licensing Cost (C)
B40: % y/y Growth | D40: ='Audiobook Inputs'!$D$40 -> 0.58 | E40: ='Audiobook Inputs'!$E$40 -> 0.43 | F40: ='Audiobook Inputs'!$F$40 -> 0.3 | G40: ='Audiobook Inputs'!$G$40 -> 0.2 | H40: ='Audiobook Inputs'!$H$40 -> 0.14 | I40: ='Audiobook Inputs'!$I$40 -> 0.1 | K40: Follows the case selector on the inputs tab.
B41: C: Licensing cost paid to book publishers | C41: ='Audiobook Inputs'!$C$39 -> 190 | D41: =C41*(1+D40) -> 300.2 | E41: =D41*(1+E40) -> 429.286 | F41: =E41*(1+F40) -> 558.0718 | G41: =F41*(1+G40) -> 669.68616 | H41: =G41*(1+H40) -> 763.44222 | I41: =H41*(1+I40) -> 839.78644 | K41: FY'24 anchored on Spotify's 'hundreds of millions of dollars a year'; grown by consumption.
B43: 3. Paid Audiobook Revenue (A)
B44: A: Paid audiobook revenue | C44: ='Audiobook Inputs'!$C$46 -> 5 | D44: ='Audiobook Inputs'!$D$46 -> 30 | E44: ='Audiobook Inputs'!$E$46 -> 75 | F44: ='Audiobook Inputs'!$F$46 -> 120 | G44: ='Audiobook Inputs'!$G$46 -> 165 | H44: ='Audiobook Inputs'!$H$46 -> 210 | I44: ='Audiobook Inputs'!$I$46 -> 250 | K44: Counted in full: C is grown on total consumption, so it already carries the publisher cost of paid hours.
B46: 4. Net Contribution to Gross Profit and Gross Margin
B47: B: Net bundle saving retained | C47: =C37 -> 150 | D47: =D37 -> 146.12 | E47: =E37 -> 98.9125 | F47: =F37 -> 98.9125 | G47: =G37 -> 98.9125 | H47: =H37 -> 98.9125 | I47: =I37 -> 98.9125
B48: A: Paid audiobook revenue | C48: =C44 -> 5 | D48: =D44 -> 30 | E48: =E44 -> 75 | F48: =F44 -> 120 | G48: =G44 -> 165 | H48: =H44 -> 210 | I48: =I44 -> 250
...

Sheet COGS Build
B1: FY25 | C1: FY26 | D1: FY27 | E1: FY28 | F1: FY29 | G1: FY30 | H1: Notes
A2: Revenue | B2: =RPM!Q58 -> 17186 | C2: =RPM!V58 -> 19410 | D2: =RPM!AA58 -> 21172 | E2: =RPM!AB58 -> 23166 | F2: =RPM!AC58 -> 25017 | G2: =RPM!AD58 -> 26482 | H2: RPM row 58.
A3: Label % | B3: 0.48 | C3: =B3+C4/10000 -> 0.468 | D3: =C3+D4/10000 -> 0.461 | E3: =D3+E4/10000 -> 0.4575 | F3: =E3+F4/10000 -> 0.4555 | G3: =F3+G4/10000 -> 0.4545 | H3: Recording-royalty rate before the Discovery Mode haircut, % of total revenue. FY25 input. Later years glide down by the bp in the row below: price increases lift revenue faster than the per-subscriber minimums in the label deals, so the effective rate converges on the headline %; the steps shrink as the Sep-25 and Feb-26 hikes lap. This is the main source of margin expansion and the row to tune.
A4: y/y change, bp | C4: -120 | D4: -70 | E4: -35 | F4: -20 | G4: -10
A5: Publisher % | B5: 0.11 | C5: =B5+C6/10000 -> 0.1105 | D5: =C5+D6/10000 -> 0.111 | E5: =D5+E6/10000 -> 0.111 | F5: =E5+F6/10000 -> 0.111 | G5: =F5+G6/10000 -> 0.111 | H5: Mechanical + performance royalties, % of total revenue, after the bundle discount. Phonorecords IV escalator adds ~5 bp a year through FY27; flat after. The bundle hand-back is a separate line below.
A6: y/y change, bp | C6: 5 | D6: 5 | E6: 0 | F6: 0 | G6: 0
A7: Royalties | B7: =(B3+B5)*B2 -> 10139.74 | C7: =(C3+C5)*C2 -> 11228.685 | D7: =(D3+D5)*D2 -> 12110.384 | E7: =(E3+E5)*E2 -> 13169.871 | F7: =(F3+F5)*F2 -> 14172.13 | G7: =(G3+G5)*G2 -> 14975.571 | H7: (Label % + publisher %) x revenue, before the Discovery Mode haircut.
A9: Discovery Mode Eligible Streams | B9: ='DM Inputs'!D30 -> 0.512 | C9: ='DM Inputs'!E31 -> 0.52 | D9: ='DM Inputs'!F31 -> 0.525 | E9: ='DM Inputs'!G31 -> 0.5275 | F9: ='DM Inputs'!H31 -> 0.529 | G9: ='DM Inputs'!I31 -> 0.53 | H9: DM Inputs: FY25 D30, FY26-FY30 the active case rows (row 31).
A10: DM % of DM-eligible streams | B10: ='DM Inputs'!D35 -> 0.33 | C10: ='DM Inputs'!E36 -> 0.33 | D10: ='DM Inputs'!F36 -> 0.335 | E10: ='DM Inputs'!G36 -> 0.337 | F10: ='DM Inputs'!H36 -> 0.339 | G10: ='DM Inputs'!I36 -> 0.34 | H10: DM Inputs: FY25 D35, FY26-FY30 row 36.
A11: DM haircut | B11: 0.3 | C11: =B11 -> 0.3 | D11: =C11 -> 0.3 | E11: =D11 -> 0.3 | F11: =E11 -> 0.3 | G11: =F11 -> 0.3 | H11: 30% lower recording royalty on DM-context streams; held flat.
A12: DM royalties | B12: =B2*B3*B9*B10 -> 1393.7983 | C12: =C2*C3*C9*C10 -> 1558.7938 | D12: =D2*D3*D9*D10 -> 1716.5914 | E12: =E2*E3*E9*E10 -> 1884.0591 | F12: =F2*F3*F9*F10 -> 2043.5204 | G12: =G2*G3*G9*G10 -> 2168.8996 | H12: Label royalties on Discovery Mode streams before the haircut = revenue x label % x eligible share x DM share. Publishing is not discounted.
A13: DM saving | B13: =B12*B11 -> 418.1395 | C13: =C12*C11 -> 467.63814 | D13: =D12*D11 -> 514.97741 | E13: =E12*E11 -> 565.21772 | F13: =F12*F11 -> 613.05612 | G13: =G12*G11 -> 650.66989 | H13: DM royalties x haircut: the cost-of-revenue reduction.
A14: DM netted royalties | B14: =B7-B13 -> 9721.6005 | C14: =C7-C13 -> 10761.047 | D14: =D7-D13 -> 11595.407 | E14: =E7-E13 -> 12604.653 | F14: =F7-F13 -> 13559.074 | G14: =G7-G13 -> 14324.901 | H14: Royalties less the DM saving = royalties actually paid. (Was royalties less 70% of DM royalties, which removed the paid part instead of the saving and understated royalties by ~€560M in FY25.)
A16: Audiobook licensing | B16: ='Audiobook GM Bridge'!D41 -> 300.2 | C16: ='Audiobook GM Bridge'!E41 -> 429.286 | D16: ='Audiobook GM Bridge'!F41 -> 558.0718 | E16: ='Audiobook GM Bridge'!G41 -> 669.68616 | F16: ='Audiobook GM Bridge'!H41 -> 763.44222 | G16: ='Audiobook GM Bridge'!I41 -> 839.78644 | H16: Audiobook GM Bridge, C: licensing cost paid to book publishers, now extended to FY'30E. (Was the bridge's net contribution N, which nets paid audiobook revenue and the bundle saving into a cost line.)
A17: Bundle saving hand-back vs FY25 | B17: ='Audiobook GM Bridge'!$D$37-'Audiobook GM Bridge'!D37 -> 0 | C17: ='Audiobook GM Bridge'!$D$37-'Audiobook GM Bridge'!E37 -> 47.2075 | D17: ='Audiobook GM Bridge'!$D$37-'Audiobook GM Bridge'!F37 -> 47.2075 | E17: ='Audiobook GM Bridge'!$D$37-'Audiobook GM Bridge'!G37 -> 47.2075 | F17: ='Audiobook GM Bridge'!$D$37-'Audiobook GM Bridge'!H37 -> 47.2075 | G17: ='Audiobook GM Bridge'!$D$37-'Audiobook GM Bridge'!I37 -> 47.2075 | H17: Audiobook GM Bridge, B: the FY25 net bundle saving is already inside the 11% publisher rate; as the direct deals (and any MLC outcome) hand it back, publisher cost rises by FY25 B less the year's B.
A19: Other, as a % of revenue | B19: =(-IS!AA12-B14-B16-B17)/B2 -> 0.097067352 | C19: =B19+C20/10000 -> 0.093067352 | D19: =C19+D20/10000 -> 0.090567352 | E19: =D19+E20/10000 -> 0.089067352 | F19: =E19+F20/10000 -> 0.088067352 | G19: =F19+G20/10000 -> 0.087567352 | H19: FY25 = plug to reported cost of revenue (IS 2025, €11,690M): payment processing (~3%), podcast content and production (~2%), streaming delivery, hosting and support, Partner Program. Glides down with scale by the bp below; payment fees stay proportional, the rest does not.
A20: y/y change, bp | C20: -40 | D20: -25 | E20: -15 | F20: -10 | G20: -5
A21: Other | B21: =B19*B2 -> 1668.1995 | C21: =C19*C2 -> 1806.4373 | D21: =D19*D2 -> 1917.492 | E21: =E19*E2 -> 2063.3343 | F21: =F19*F2 -> 2203.1809 | G21: =G19*G2 -> 2318.9586 | H21: Other % x revenue. (Was circular: % = €/revenue while € = % x revenue.)
A23: COGS | B23: =B14+B16+B17+B21 -> 11690 | C23: =C14+C16+C17+C21 -> 13043.978 | D23: =D14+D16+D17+D21 -> 14118.178 | E23: =E14+E16+E17+E21 -> 15384.881 | F23: =F14+F16+F17+F21 -> 16572.905 | G23: =G14+G16+G17+G21 -> 17530.854 | H23: DM netted royalties + audiobook licensing + bundle hand-back + other.
A24: GP | B24: =B2-B23 -> 5496 | C24: =C2-C23 -> 6366.0223 | D24: =D2-D23 -> 7053.8221 | E24: =E2-E23 -> 7781.1188 | F24: =F2-F23 -> 8444.095 | G24: =G2-G23 -> 8951.1463
A25: GM % | B25: =B24/B2 -> 0.31979518 | C25: =C24/C2 -> 0.32797642 | D25: =D24/D2 -> 0.33316749 | E25: =E24/E2 -> 0.3358853 | F25: =F24/F2 -> 0.33753428 | G25: =G24/G2 -> 0.3380087 | H25: FY25 reproduces the reported 32.0% by construction.
A26: y/y change, bp | C26: =(C25-B25)*10000 -> 81.812397 | D26: =(D25-C25)*10000 -> 51.910701 | E26: =(E25-D25)*10000 -> 27.178053 | F26: =(F25-E25)*10000 -> 16.489782 | G26: =(G25-F25)*10000 -> 4.7442266
A28: Memo: what moves gross margin each year, bp
A29: Label rate glide | C29: =-C4 -> 120 | D29: =-D4 -> 70 | E29: =-E4 -> 35 | F29: =-F4 -> 20 | G29: =-G4 -> 10
A30: Publisher rate | C30: =-C6 -> -5 | D30: =-D6 -> -5 | E30: =-E6 -> 0 | F30: =-F6 -> 0 | G30: =-G6 -> 0
A31: Discovery Mode saving | C31: =(C13/C2-B13/B2)*10000 -> -2.376 | D31: =(D13/D2-C13/C2)*10000 -> 2.308725 | E31: =(E13/E2-D13/D2)*10000 -> 0.75076875 | F31: =(F13/F2-E13/E2)*10000 -> 1.0699177 | G31: =(G13/G2-F13/F2)*10000 -> 0.6468885
A32: Audiobook licensing | C32: =-(C16/C2-B16/B2)*10000 -> -46.490377 | D32: =-(D16/D2-C16/C2)*10000 -> -42.422113 | E32: =-(E16/E2-D16/D2)*10000 -> -25.491929 | F32: =-(F16/F2-E16/E2)*10000 -> -16.087892 | G32: =-(G16/G2-F16/F2)*10000 -> -11.946571
A33: Bundle hand-back | C33: =-(C17/C2-B17/B2)*10000 -> -24.321226 | D33: =-(D17/D2-C17/C2)*10000 -> 2.0240884 | E33: =-(E17/E2-D17/D2)*10000 -> 1.9192132 | F33: =-(F17/F2-E17/E2)*10000 -> 1.5077563 | G33: =-(G17/G2-F17/F2)*10000 -> 1.0439089
A34: Other cost of revenue glide | C34: =-C20 -> 40 | D34: =-D20 -> 25 | E34: =-E20 -> 15 | F34: =-F20 -> 10 | G34: =-G20 -> 5
A35: Check: sum = y/y change | C35: =SUM(C29:C34)-C26 -> 0 | D35: =SUM(D29:D34)-D26 -> -4.0500936e-13 | E35: =SUM(E29:E34)-E26 -> 8.0646601e-13 | F35: =SUM(F29:F34)-F26 -> -2.0783375e-12 | G35: =SUM(G29:G34)-G26 -> 1.762146e-12 | H35: Should be ~0 (rounding from the interaction of label % and DM share).
A36: Reported COGS FY25 (IS) | B36: =-IS!AA12 -> 11690 | H36: IS 2025 cost of revenue.
A37: Royalties after Discovery Mode, % of revenue | B37: =B14/B2 -> 0.56566976 | C37: =C14/C2 -> 0.55440736 | D37: =D14/D2 -> 0.54767649 | E37: =E14/E2 -> 0.54410141 | F37: =F14/F2 -> 0.54199442 | G37: =G14/G2 -> 0.54092973 | H37: Loud & Clear: €10.1bn paid to the music industry in 2025 = 58.8% of revenue; at 48% + 11% before the haircut this reads 56.6%, so ~2 points of music cost sit in 'Other'. Raise label % toward 50% to close it.
A38: Blue = input; gold = held flat / glide; black = formula. After pasting, Find & Replace "[SPOT_COGS_Build_Tabs.xlsx]" with nothing so links point at the model's own tabs.

Sheet RPM
B2: STUB | L2: FY'24 | Q2: FY'25 | V2: FY'26E | AA2: FY'27E | AB2: FY'28E | AC2: FY'29E | AD2: FY'30E
B58: Total Revenue | L58: 15673 | Q58: 17186 | V58: 19410 | AA58: 21172 | AB58: 23166 | AC58: 25017 | AD58: 26482

Sheet Valuation
B2: Case Selector
B3: Toggle | C3: Base | E3: STUB

Sheet DM Inputs
B2: STUB
D30: 0.512
E31: 0.52 | F31: 0.525 | G31: 0.5275 | H31: 0.529 | I31: 0.53
D35: 0.33
E36: 0.33 | F36: 0.335 | G36: 0.337 | H36: 0.339 | I36: 0.34

Sheet IS
B2: STUB
AA3: 2025
B12: Cost of Revenue | AA12: -11690
