Workbook

Sheet DM Premium GM
B2: Discovery Mode: Premium Gross Margin Build | C2: FY'25 | D2: FY'26E | E2: FY'27E | F2: FY'28E | G2: FY'29E | H2: FY'30E | I2: Notes
B4: € in millions unless stated. Premium revenue from the RPM; the normal label royalty rate is cut by 30% on the share of premium streams that are Discovery Mode streams (e x s); the royalty pool after the haircut over premium revenue, plus other premium cost of revenue, gives premium gross margin.
B6: A. Premium revenue (RPM)
B7: Premium revenue | C7: =RPM!Q55 -> 15350 | D7: =RPM!V55 -> 17502 | E7: =RPM!AA55 -> 18991 | F7: =RPM!AB55 -> 20723 | G7: =RPM!AC55 -> 22331 | H7: =RPM!AD55 -> 23581 | I7: RPM row 55 (FY'25 actual; FY'26-FY'30 projection, case-driven through the RPM assumptions).
B8: Total revenue (memo) | C8: =RPM!Q58 -> 17186 | D8: =RPM!V58 -> 19410 | E8: =RPM!AA58 -> 21175 | F8: =RPM!AB58 -> 23169 | G8: =RPM!AC58 -> 25017 | H8: =RPM!AD58 -> 26482
B9: % y/y premium revenue growth | D9: =D7/C7-1 -> 0.14019544 | E9: =E7/D7-1 -> 0.085075991 | F9: =F7/E7-1 -> 0.091201095 | G9: =G7/F7-1 -> 0.077594943 | H9: =H7/G7-1 -> 0.055975997
B11: B. Normal royalty rate (before Discovery Mode)
B12: Label and publisher royalties, % of premium revenue, before Discovery Mode | C12: 0.61 | D12: =C12 -> 0.61 | E12: =D12 -> 0.61 | F12: =E12 -> 0.61 | G12: =F12 -> 0.61 | H12: =G12 -> 0.61 | I12: Input. Calibration: Loud & Clear puts music royalties at €10.1bn in 2025 (58.8% of total revenue); the premium tier carries a higher rate than the ad tier. 61% leaves ~8% of premium revenue for other cost of revenue at the reported 34% premium gross margin. Replace with the model's own royalty-rate line if one exists; held flat.
B14: C. Discovery Mode stream shares (FY'25 from DM Inputs; cases FY'26E-FY'27E as on DM Inputs; faded to flat by FY'30E)
B15: Fade factor: share of the FY'27E increment added in each later year | F15: 0.667 | G15: 0.333 | H15: 0 | I15: Linear fade: FY'28E adds two thirds of the FY'27E step, FY'29E one third, FY'30E nothing, so both shares are flat by FY'30E. Set all three to 0 for flat from FY'28E, or to 1 to keep the FY'27E step going.
B16: e: % of premium streams served in DM-eligible contexts (Radio, Autoplay, Mixes) | C16: ='DM Inputs'!D30 -> 0.512 | D16: =CHOOSE(MATCH(Valuation!$C$3, {"Bear","Base","Bull"}, 0), D17, D18, D19) -> 0.52 | E16: =CHOOSE(MATCH(Valuation!$C$3, {"Bear","Base","Bull"}, 0), E17, E18, E19) -> 0.525 | F16: =CHOOSE(MATCH(Valuation!$C$3, {"Bear","Base","Bull"}, 0), F17, F18, F19) -> 0.528335 | G16: =CHOOSE(MATCH(Valuation!$C$3, {"Bear","Base","Bull"}, 0), G17, G18, G19) -> 0.53 | H16: =CHOOSE(MATCH(Valuation!$C$3, {"Bear","Base","Bull"}, 0), H17, H18, H19) -> 0.53 | I16: FY'25 links to DM Inputs D30. Bear/Base/Bull FY'26E-FY'27E are the levels on DM Inputs rows 32-34 (typed here so the tab does not depend on that tab's layout). Active row follows Valuation!C3 like the Assumptions tab.
B17: Bear | C17: =C16 -> 0.512 | D17: 0.515 | E17: 0.52 | F17: =E17+(E17-D17)*F$15 -> 0.523335 | G17: =F17+(E17-D17)*G$15 -> 0.525 | H17: =G17+(E17-D17)*H$15 -> 0.525
B18: Base | C18: =C16 -> 0.512 | D18: 0.52 | E18: 0.525 | F18: =E18+(E18-D18)*F$15 -> 0.528335 | G18: =F18+(E18-D18)*G$15 -> 0.53 | H18: =G18+(E18-D18)*H$15 -> 0.53
B19: Bull | C19: =C16 -> 0.512 | D19: 0.525 | E19: 0.53 | F19: =E19+(E19-D19)*F$15 -> 0.533335 | G19: =F19+(E19-D19)*G$15 -> 0.535 | H19: =G19+(E19-D19)*H$15 -> 0.535
B20: s: % of DM-eligible-context streams that are Discovery Mode streams | C20: ='DM Inputs'!D35 -> 0.33 | D20: =CHOOSE(MATCH(Valuation!$C$3, {"Bear","Base","Bull"}, 0), D21, D22, D23) -> 0.33 | E20: =CHOOSE(MATCH(Valuation!$C$3, {"Bear","Base","Bull"}, 0), E21, E22, E23) -> 0.335 | F20: =CHOOSE(MATCH(Valuation!$C$3, {"Bear","Base","Bull"}, 0), F21, F22, F23) -> 0.338335 | G20: =CHOOSE(MATCH(Valuation!$C$3, {"Bear","Base","Bull"}, 0), G21, G22, G23) -> 0.34 | H20: =CHOOSE(MATCH(Valuation!$C$3, {"Bear","Base","Bull"}, 0), H21, H22, H23) -> 0.34 | I20: FY'25 links to DM Inputs D35 (burner-account sampling). Bear/Base/Bull FY'26E-FY'27E from DM Inputs rows 37-39.
B21: Bear | C21: =C20 -> 0.33 | D21: 0.32 | E21: 0.32 | F21: =E21+(E21-D21)*F$15 -> 0.32 | G21: =F21+(E21-D21)*G$15 -> 0.32 | H21: =G21+(E21-D21)*H$15 -> 0.32
B22: Base | C22: =C20 -> 0.33 | D22: 0.33 | E22: 0.335 | F22: =E22+(E22-D22)*F$15 -> 0.338335 | G22: =F22+(E22-D22)*G$15 -> 0.34 | H22: =G22+(E22-D22)*H$15 -> 0.34
B23: Bull | C23: =C20 -> 0.33 | D23: 0.34 | E23: 0.35 | F23: =E23+(E23-D23)*F$15 -> 0.35667 | G23: =F23+(E23-D23)*G$15 -> 0.36 | H23: =G23+(E23-D23)*H$15 -> 0.36
B24: e x s: Discovery Mode streams, % of premium streams | C24: =C16*C20 -> 0.16896 | D24: =D16*D20 -> 0.1716 | E24: =E16*E20 -> 0.175875 | F24: =F16*F20 -> 0.17875422 | G24: =G16*G20 -> 0.1802 | H24: =H16*H20 -> 0.1802 | I24: The share of the royalty pool that takes the haircut.
B26: D. Royalty haircut
B27: Discovery Mode royalty haircut | C27: 0.3 | D27: 0.3 | E27: 0.3 | F27: 0.3 | G27: 0.3 | H27: 0.3 | I27: Program term: 30% lower royalty on streams served in DM contexts. Set a lower later-year value to model a claw-back at the major-label renewals.
B28: Royalty % after Discovery Mode haircut = normal royalty % x (1 - e x s x haircut) | C28: =C12*(1-C24*C27) -> 0.57908032 | D28: =D12*(1-D24*D27) -> 0.5785972 | E28: =E12*(1-E24*E27) -> 0.57781487 | F28: =F12*(1-F24*F27) -> 0.57728798 | G28: =G12*(1-G24*G27) -> 0.5770234 | H28: =H12*(1-H24*H27) -> 0.5770234
B29: Royalty pool after haircut, €M = premium revenue x royalty % after haircut | C29: =C7*C28 -> 8888.8829 | D29: =D7*D28 -> 10126.608 | E29: =E7*E28 -> 10973.282 | F29: =F7*F28 -> 11963.139 | G29: =G7*G28 -> 12885.51 | H29: =H7*H28 -> 13606.789
B30: Discovery Mode saving, €M = premium revenue x normal royalty % x e x s x haircut | C30: =C7*C12*C24*C27 -> 474.61709 | D30: =D7*D12*D24*D27 -> 549.61181 | E30: =E7*E12*E24*E27 -> 611.22771 | F30: =F7*F12*F24*F27 -> 677.89125 | G30: =G7*G12*G24*G27 -> 736.40045 | H30: =H7*H12*H24*H27 -> 777.6212
B32: E. Premium gross margin
B33: Reported premium gross margin, FY'25 (calibration) | C33: 0.34 | I33: 20-F FY2025: Premium gross margin 34% (33% in FY'24). Used only to size other cost of revenue in FY'25.
B34: Other premium cost of revenue, % of premium revenue (payment fees, audiobook and podcast content, delivery) | C34: =1-C33-C28 -> 0.08091968 | D34: =C34 -> 0.08091968 | E34: =D34 -> 0.08091968 | F34: =E34 -> 0.08091968 | G34: =F34 -> 0.08091968 | H34: =G34 -> 0.08091968 | I34: FY'25 is the plug that reproduces the reported 34%; held flat after. Audiobook cost growth is modelled on the audiobook tabs: apply that bridge's y/y headwind on top of this margin rather than raising this line.
B35: Premium cost of revenue, €M = premium revenue x (royalty % after haircut + other %) | C35: =C7*(C28+C34) -> 10131 | D35: =D7*(D28+D34) -> 11542.864 | E35: =E7*(E28+E34) -> 12510.028 | F35: =F7*(F28+F34) -> 13640.037 | G35: =G7*(G28+G34) -> 14692.527 | H35: =H7*(H28+H34) -> 15514.956
B36: Premium gross profit, €M | C36: =C7-C35 -> 5219 | D36: =D7-D35 -> 5959.1356 | E36: =E7-E35 -> 6480.9721 | F36: =F7-F35 -> 7082.9627 | G36: =G7-G35 -> 7638.4731 | H36: =H7-H35 -> 8066.0442
B37: Premium Gross Margin % | C37: =C36/C7 -> 0.34 | D37: =D36/D7 -> 0.34048312 | E37: =E36/E7 -> 0.34126545 | F37: =F36/F7 -> 0.34179234 | G37: =G36/G7 -> 0.34205692 | H37: =H36/H7 -> 0.34205692 | I37: Equals 1 - royalty % after haircut - other %. FY'25 reproduces the reported 34% by construction. Link the IS premium gross margin (or the Model gross-margin row, weighted with ad-supported) to this row.
B38: y/y change, bp | D38: =(D37-C37)*10000 -> 4.8312 | E38: =(E37-D37)*10000 -> 7.82325 | F38: =(F37-E37)*10000 -> 5.2689767 | G38: =(G37-F37)*10000 -> 2.6457733 | H38: =(H37-G37)*10000 -> 0
B40: F. Memo: what Discovery Mode is worth inside that margin
B41: Premium gross margin with no Discovery Mode = 1 - normal royalty % - other % | C41: =1-C12-C34 -> 0.30908032 | D41: =1-D12-D34 -> 0.30908032 | E41: =1-E12-E34 -> 0.30908032 | F41: =1-F12-F34 -> 0.30908032 | G41: =1-G12-G34 -> 0.30908032 | H41: =1-H12-H34 -> 0.30908032
B42: Discovery Mode contribution to premium gross margin, bp = normal royalty % x e x s x haircut | C42: =(C37-C41)*10000 -> 309.1968 | D42: =(D37-D41)*10000 -> 314.028 | E42: =(E37-E41)*10000 -> 321.85125 | F42: =(F37-F41)*10000 -> 327.12023 | G42: =(G37-G41)*10000 -> 329.766 | H42: =(H37-H41)*10000 -> 329.766
B43: y/y change in the contribution, bp (what the fade does) | D43: =D42-C42 -> 4.8312 | E43: =E42-D42 -> 7.82325 | F43: =F42-E42 -> 5.2689767 | G43: =G42-F42 -> 2.6457733 | H43: =H42-G42 -> 0 | I43: Positive only while e x s is still rising; zero once the shares are flat, because the saving then grows exactly with premium revenue.
B44: Discovery Mode saving as % of total revenue, bp (consolidated-margin equivalent) | C44: =C30/C8*10000 -> 276.16495 | D44: =D30/D8*10000 -> 283.1591 | E44: =E30/E8*10000 -> 288.65535 | F44: =F30/F8*10000 -> 292.58546 | G44: =G30/G8*10000 -> 294.36002 | H44: =H30/H8*10000 -> 293.64142
B46: G. Memo: consolidated gross margin (for the Model / RDCF gross-margin row)
B47: Ad-Supported gross margin (input; FY'25 from 20-F, held flat) | C47: 0.18 | D47: =C47 -> 0.18 | E47: =D47 -> 0.18 | F47: =E47 -> 0.18 | G47: =F47 -> 0.18 | H47: =G47 -> 0.18 | I47: FY'25 20-F: Ad-Supported gross profit €330M on €1,836M = 18%. Marquee and Showcase sit here. Replace with the model's own ad-supported build.
B48: Ad-Supported revenue (RPM row 56) | C48: =RPM!Q56 -> 1836 | D48: =RPM!V56 -> 1908 | E48: =RPM!AA56 -> 2184 | F48: =RPM!AB56 -> 2446 | G48: =RPM!AC56 -> 2686 | H48: =RPM!AD56 -> 2901
B49: Consolidated gross margin = (premium GP + ad-supported revenue x ad GM) / total revenue | C49: =(C36+C48*C47)/C8 -> 0.32290702 | D49: =(D36+D48*D47)/D8 -> 0.32470765 | E49: =(E36+E48*E47)/E8 -> 0.32463245 | F49: =(F36+F48*F47)/F8 -> 0.32471159 | G49: =(G36+G48*G47)/G8 -> 0.32465736 | H49: =(H36+H48*H47)/H8 -> 0.32430422 | I49: FY'25 reproduces ~32.3% vs 32.0% reported; the gap is rounding in the 34% and 18% segment margins.
...

Sheet RPM
B2: STUB: mirrors RPM rows 2/55/56/58 for the FY columns. Delete after pasting the tab into the model. | Q2: FY'25 | V2: FY'26E | AA2: FY'27E | AB2: FY'28E | AC2: FY'29E | AD2: FY'30E
B55: Premium Revenue | Q55: 15350 | V55: 17502 | AA55: 18991 | AB55: 20723 | AC55: 22331 | AD55: 23581
B56: Ad-Supported Revenue (Free Tier) | Q56: 1836 | V56: 1908 | AA56: 2184 | AB56: 2446 | AC56: 2686 | AD56: 2901
B58: Total Revenue | Q58: 17186 | V58: 19410 | AA58: 21175 | AB58: 23169 | AC58: 25017 | AD58: 26482

Sheet Valuation
B2: Case Selector
B3: Toggle | C3: Base | E3: STUB: mirrors Valuation!C3. Delete after pasting.

Sheet DM Inputs
B2: STUB: mirrors DM Inputs D30 and D35. Delete after pasting.
B30: e: share of all streams served from DM-eligible surfaces | D30: 0.512
B35: s: enrolled share of eligible-surface streams | D35: 0.33
