Workbook

Sheet AB_Inputs
A1: Audiobooks: inputs
A2: Blue text = hard-coded input. Orange fill = estimate (the note says how it was derived). Yellow fill with red text = forecast placeholder: replace with a link to the main model before use. No forecasts beyond FY27.
A4: Input | B4: Value | C4: Unit | D4: Period | E4: Type | F4: Source / how obtained
A5: A. Group revenue (denominator for basis points)
A6: Group revenue 2024 | B6: 15673 | C6: €M | D6: FY24 | E6: Actual | F6: Spotify 20-F
A7: Group revenue 2025 | B7: 17186 | C7: €M | D7: FY25 | E7: Actual | F7: Spotify 20-F
A8: Group revenue 2026E | B8: 19500 | C8: €M | D8: FY26E | E8: LINK TO MODEL | F8: Placeholder. Link to model: total revenue FY26E
A9: Group revenue 2027E | B9: 21300 | C9: €M | D9: FY27E | E9: LINK TO MODEL | F9: Placeholder. Link to model: total revenue FY27E
A11: B. Bundle saving: MLC contingency disclosed in Spotify filings (gross mechanical-royalty discount, cumulative from 1 Mar 2024)
A12: MLC contingency, cumulative 1 Mar 2024 to 30 Jun 2024 | B12: 46 | C12: €M | D12: Q2-24 | E12: Actual | F12: 6-K Q2-24: 'approximately €46 million, of which approximately €35 million relates to the three months ended June 30, 2024'
A13: of which the three months April to June 2024 | B13: 35 | C13: €M | D13: Q2-24 | E13: Actual | F13: 6-K Q2-24 (same sentence)
A14: MLC contingency, cumulative to 30 Sep 2024 | B14: 94 | C14: €M | D14: Q3-24 | E14: Actual | F14: 6-K Q3-24
A15: MLC contingency, cumulative to 31 Dec 2024 | B15: 150 | C15: €M | D15: Q4-24 | E15: Actual | F15: 20-F FY24
A16: MLC contingency, cumulative to 31 Mar 2025 | B16: 205 | C16: €M | D16: Q1-25 | E16: Actual | F16: 6-K Q1-25
A17: MLC contingency, cumulative to 30 Jun 2025 | B17: 256 | C17: €M | D17: Q2-25 | E17: Actual | F17: 6-K Q2-25
A18: MLC contingency, cumulative to 30 Sep 2025 | B18: 308 | C18: €M | D18: Q3-25 | E18: Actual | F18: 6-K Q3-25: first filing to add 'Any liability would be partially offset by direct deals with publishers'
A19: MLC contingency, cumulative to 31 Dec 2025 | B19: 358 | C19: €M | D19: Q4-25 | E19: Actual | F19: 20-F FY25
A20: MLC contingency, cumulative to 31 Mar 2026 | B20: 410 | C20: €M | D20: Q1-26 | E20: Actual | F20: 6-K Q1-26 (USD 473M at the time, per NMPA 'nearly $480 million by Spotify's own admission')
A21: MLC contingency, cumulative to 30 Jun 2026 | B21: 437 | C21: €M | D21: Q2-26 | E21: Actual | F21: 6-K Q2-26 as quoted by Music Ally, 7 Sep 2026. A second reading of the same filing gives €473M (which is also the USD value of the Q1-26 figure). Verify against the Q2-26 6-K legal-proceedings note before quoting
A22: Gross bundle saving 2026E | B22: 205 | C22: €M | D22: FY26E | E22: LINK TO MODEL | F22: Placeholder: 4 x the average quarterly contingency increment from Q2-25 to Q1-26 (€51M). Link to model
A23: Gross bundle saving 2027E | B23: 205 | C23: €M | D23: FY27E | E23: LINK TO MODEL | F23: Placeholder: flat on 2026E; the Phonorecords IV settlement that permits the bundle rate runs to end-2027. Link to model
A25: C. Bundle saving: independent cross-check (Billboard analysis of Spotify's MLC reports)
A26: Mechanical royalties paid to the MLC, paid tiers, Q4-23 | B26: 97.3 | C26: $M | D26: Q4-23 | E26: Reported | F26: Billboard analysis of Spotify's MLC reports
A27: Mechanical royalties paid to the MLC, paid tiers, Q4-25 | B27: 53.3 | C27: $M | D27: Q4-25 | E27: Reported | F27: Billboard analysis (-45%)
A28: Blended mechanical per-stream rate, paid tiers, Q4-23 | B28: 0.00068 | C28: $/stream | D28: Q4-23 | E28: Reported | F28: Billboard analysis
A29: Blended mechanical per-stream rate, paid tiers, Q4-25 | B29: 0.00033 | C29: $/stream | D29: Q4-25 | E29: Reported | F29: Billboard analysis (-51%)
A30: EUR/USD, Q4-25 average | B30: 1.16 | C30: x | D30: Q4-25 | E30: Estimate | F30: Approximate
A32: D. Direct publisher deals that hand part of the saving back
A33: UMPG share of US mechanicals | B33: 0.22 | C33: % | E33: Estimate | F33: Estimate from US publishing market shares (range 20-25%)
A34: UMPG direct licence start month (2025) | B34: 2 | C34: month | D34: 2025 | E34: Reported | F34: Announced 26 Jan 2025; reported to 'nullify' the bundle discount going forward
A35: Warner Chappell share of US mechanicals | B35: 0.13 | C35: % | E35: Estimate | F35: Estimate (range 11-15%)
A36: Warner Chappell direct licence start month (2025) | B36: 3 | C36: month | D36: 2025 | E36: Reported | F36: Announced 6 Feb 2025; 'supersedes the bundling payment structure' (MBW)
A37: Kobalt share of US mechanicals | B37: 0.05 | C37: % | E37: Estimate | F37: Estimate; largest independent (range 4-7%)
A38: Kobalt direct licence start month (2025) | B38: 9 | C38: month | D38: 2025 | E38: Reported | F38: Announced 13 Aug 2025; 'bespoke terms rather than the compulsory licence rates'
A39: Sony Music Publishing share of US mechanicals | B39: 0.26 | C39: % | E39: Estimate | F39: Estimate; SMP ranked #1 publisher in every quarter of 2025 (range 23-28%)
A40: Sony Music Publishing direct licence start month (2025) | B40: 10 | C40: month | D40: 2025 | E40: Reported | F40: Announced 18 Sep 2025; direct US licence
A41: BMG share of US mechanicals | B41: 0.03 | C41: % | E41: Estimate | F41: Estimate (range 2-4%)
A42: BMG direct licence start month (2025) | B42: 11 | C42: month | D42: 2025 | E42: Reported | F42: Announced 9 Oct 2025
A43: Share of the bundle discount restored to direct-licensed publishers | B43: 0.75 | C43: % | E43: Estimate | F43: Estimate. Spotify: liability 'partially offset by direct deals'. MBW on the Warner deal: terms 'continue to recognize a difference between bundled and music-only listeners' but payments 'substantially improved'. Range 50-100%
A44: MLC amended complaint succeeds in 2027 (1 = yes): the independents' share of the saving goes to zero | B44: 0 | C44: flag | D44: 2027 | E44: Estimate | F44: Scenario switch. Interlocutory appeal denied 1 Sep 2026; fact discovery cutoff 13 Mar 2027; no trial date set
...

Sheet AB_Bridge
A1: Audiobooks: bridge from inputs to the gross-margin contribution (€M unless stated)
A2: N = B + A - C. B = bundle royalty saving retained; A = paid audiobook revenue; C = audiobook licensing cost paid to book publishers. The June 2024 price increase is excluded (memo on the inputs tab).
A4: 1. Bundle mechanical-royalty saving (B)
A5: 1a. Quarterly increments in the MLC contingency = the gross bundle discount per quarter
A6: Filing (period end) | C6: Cumulative | D6: Increment | E6: Months | F6: €M per month
A7: 6-K Q2-24 (30 Jun 2024) | C7: =AB_Inputs!$B$12 -> 46 | D7: =C7 -> 46 | E7: 4 | F7: =D7/E7 -> 11.5
A8: 6-K Q3-24 (30 Sep 2024) | C8: =AB_Inputs!$B$14 -> 94 | D8: =C8-C7 -> 48 | E8: 3 | F8: =D8/E8 -> 16
A9: 20-F FY24 (31 Dec 2024) | C9: =AB_Inputs!$B$15 -> 150 | D9: =C9-C8 -> 56 | E9: 3 | F9: =D9/E9 -> 18.666667
A10: 6-K Q1-25 (31 Mar 2025) | C10: =AB_Inputs!$B$16 -> 205 | D10: =C10-C9 -> 55 | E10: 3 | F10: =D10/E10 -> 18.333333
A11: 6-K Q2-25 (30 Jun 2025) | C11: =AB_Inputs!$B$17 -> 256 | D11: =C11-C10 -> 51 | E11: 3 | F11: =D11/E11 -> 17
A12: 6-K Q3-25 (30 Sep 2025) | C12: =AB_Inputs!$B$18 -> 308 | D12: =C12-C11 -> 52 | E12: 3 | F12: =D12/E12 -> 17.333333
A13: 20-F FY25 (31 Dec 2025) | C13: =AB_Inputs!$B$19 -> 358 | D13: =C13-C12 -> 50 | E13: 3 | F13: =D13/E13 -> 16.666667
A14: 6-K Q1-26 (31 Mar 2026) | C14: =AB_Inputs!$B$20 -> 410 | D14: =C14-C13 -> 52 | E14: 3 | F14: =D14/E14 -> 17.333333
A15: 6-K Q2-26 (30 Jun 2026): verify, see inputs note | C15: =AB_Inputs!$B$21 -> 437 | D15: =C15-C14 -> 27 | E15: 3 | F15: =D15/E15 -> 9
A16: of which April to June 2024 (so March 2024 alone was about €11M) | C16: =AB_Inputs!$B$13 -> 35 | E16: 3 | F16: =C16/E16 -> 11.666667
A17: Average quarterly increment, Q2-25 to Q1-26 (x4 = basis for the 2026E-27E placeholders) | B17: =AVERAGE(D11:D14) -> 51.25 | C17: =B17*4 -> 205
A18: Reading: €50-56M a quarter from Q4-24 to Q1-26 with no step down after the direct deals, so the figure is gross. Every paid-tier stream is still reported through the MLC at the bundle rate; the direct-licensed publishers receive a top-up outside it.
A20: 1b. Cross-check from Billboard's analysis of the MLC reports (paid tiers)
A21: Mechanical royalties paid to the MLC, $M: Q4-23 (col B), Q4-25 (col C) | B21: =AB_Inputs!$B$26 -> 97.3 | C21: =AB_Inputs!$B$27 -> 53.3
A22: Blended per-stream rate, $: Q4-23 (col B), Q4-25 (col C) | B22: =AB_Inputs!$B$28 -> 0.00068 | C22: =AB_Inputs!$B$29 -> 0.00033
A23: Implied streams, bn: Q4-23 (col B), Q4-25 (col C) | B23: =B21/B22/1000 -> 143.08824 | C23: =C21/C22/1000 -> 161.51515
A24: Implied Q4-25 discount, $M = Q4-25 streams x Q4-23 rate - paid | B24: =C23*B22*1000-C21 -> 56.530303
A25: Implied Q4-25 discount in €M (col B) vs the 20-F FY25 increment (col C) | B25: =B24/AB_Inputs!$B$30 -> 48.73302 | C25: =D13 -> 50
A27: 1c. Gross saving by year, hand-back, and B
C28: 2024A | D28: 2025A | E28: 2026E | F28: 2027E
A29: Gross bundle saving (2024-25 from the filings; 2026E-27E placeholders) | C29: =AB_Inputs!$B$15 -> 150 | D29: =AB_Inputs!$B$19-AB_Inputs!$B$15 -> 208 | E29: =AB_Inputs!$B$22 -> 205 | F29: =AB_Inputs!$B$23 -> 205
A30: Publisher (share of US mechanicals in col B; months on direct licence by year)
A31: UMPG | B31: =AB_Inputs!$B$33 -> 0.22 | C31: 0 | D31: =13-AB_Inputs!$B$34 -> 11 | E31: 12 | F31: 12
A32: Warner Chappell | B32: =AB_Inputs!$B$35 -> 0.13 | C32: 0 | D32: =13-AB_Inputs!$B$36 -> 10 | E32: 12 | F32: 12
A33: Kobalt | B33: =AB_Inputs!$B$37 -> 0.05 | C33: 0 | D33: =13-AB_Inputs!$B$38 -> 4 | E33: 12 | F33: 12
A34: Sony Music Publishing | B34: =AB_Inputs!$B$39 -> 0.26 | C34: 0 | D34: =13-AB_Inputs!$B$40 -> 3 | E34: 12 | F34: 12
A35: BMG | B35: =AB_Inputs!$B$41 -> 0.03 | C35: 0 | D35: =13-AB_Inputs!$B$42 -> 2 | E35: 12 | F35: 12
A36: Sum of shares on direct licences (independents are the remainder, still paid at the bundle rate via the MLC) | B36: =SUM(B31:B35) -> 0.69
A37: Restoration of the discount in the direct deals | B37: =AB_Inputs!$B$43 -> 0.75
A38: Hand-back = gross x sum(share x months / 12) x restoration | C38: =C29*SUMPRODUCT($B$31:$B$35,C31:C35)/12*$B$37 -> 0 | D38: =D29*SUMPRODUCT($B$31:$B$35,D31:D35)/12*$B$37 -> 61.88 | E38: =E29*SUMPRODUCT($B$31:$B$35,E31:E35)/12*$B$37 -> 106.0875 | F38: =F29*SUMPRODUCT($B$31:$B$35,F31:F35)/12*$B$37 -> 106.0875
A39: B Net bundle saving retained (2027: if MLC switch = 1, the independents' share goes to zero) | C39: =C29-C38 -> 150 | D39: =D29-D38 -> 146.12 | E39: =E29-E38 -> 98.9125 | F39: =IF(AB_Inputs!$B$44=1,F29*$B$36*(1-$B$37),F29-F38) -> 98.9125
A41: 2. Audiobook licensing cost paid to book publishers (C)
C42: 2024A | D42: 2025A | E42: 2026E | F42: 2027E
A43: Growth y/y (2025 from reported hours growth; 2026E-27E placeholders, see AB_Sensitivity) | D43: =AB_Inputs!$B$48 -> 0.58 | E43: =AB_Inputs!$B$49 -> 0.43 | F43: =AB_Inputs!$B$50 -> 0.3
A44: C (2024 anchored on 'hundreds of millions of dollars a year', Oct-24) | C44: =AB_Inputs!$B$47 -> 190 | D44: =C44*(1+D43) -> 300.2 | E44: =D44*(1+E43) -> 429.286 | F44: =E44*(1+F43) -> 558.0718
...

Sheet AB_Sensitivity
A1: Audiobooks: sensitivity to the growth assigned to audiobook licensing cost
A2: Only C moves. B, A and group revenue are held at the AB_Bridge values. The row's growth rate is applied to both 2026E and 2027E; 2025 growth stays at the inputs value. Blue cells can be edited.
A4: Licensing-cost growth p.a., 2026E and 2027E | B4: C 2026E, €M | C4: C 2027E, €M | D4: Contribution 2026E, €M | E4: Contribution 2027E, €M | F4: Headwind 2026E, bp | G4: Headwind 2027E, bp
A5: 0.2 | B5: =AB_Bridge!$D$44*(1+$A5) -> 360.24 | C5: =AB_Bridge!$D$44*(1+$A5)^2 -> 432.288 | D5: =AB_Bridge!$E$39+AB_Bridge!$E$48-B5 -> -186.3275 | E5: =AB_Bridge!$F$39+AB_Bridge!$F$48-C5 -> -213.3755 | F5: =(D5-AB_Bridge!$D$55)/AB_Bridge!$E$56*10000 -> -31.921795 | G5: =(E5-D5)/AB_Bridge!$F$56*10000 -> -12.698592
A6: 0.3 | B6: =AB_Bridge!$D$44*(1+$A6) -> 390.26 | C6: =AB_Bridge!$D$44*(1+$A6)^2 -> 507.338 | D6: =AB_Bridge!$E$39+AB_Bridge!$E$48-B6 -> -216.3475 | E6: =AB_Bridge!$F$39+AB_Bridge!$F$48-C6 -> -288.4255 | F6: =(D6-AB_Bridge!$D$55)/AB_Bridge!$E$56*10000 -> -47.316667 | G6: =(E6-D6)/AB_Bridge!$F$56*10000 -> -33.839437
A7: 0.4 | B7: =AB_Bridge!$D$44*(1+$A7) -> 420.28 | C7: =AB_Bridge!$D$44*(1+$A7)^2 -> 588.392 | D7: =AB_Bridge!$E$39+AB_Bridge!$E$48-B7 -> -246.3675 | E7: =AB_Bridge!$F$39+AB_Bridge!$F$48-C7 -> -369.4795 | F7: =(D7-AB_Bridge!$D$55)/AB_Bridge!$E$56*10000 -> -62.711538 | G7: =(E7-D7)/AB_Bridge!$F$56*10000 -> -57.799061
A8: 0.43 | B8: =AB_Bridge!$D$44*(1+$A8) -> 429.286 | C8: =AB_Bridge!$D$44*(1+$A8)^2 -> 613.87898 | D8: =AB_Bridge!$E$39+AB_Bridge!$E$48-B8 -> -255.3735 | E8: =AB_Bridge!$F$39+AB_Bridge!$F$48-C8 -> -394.96648 | F8: =(D8-AB_Bridge!$D$55)/AB_Bridge!$E$56*10000 -> -67.33 | G8: =(E8-D8)/AB_Bridge!$F$56*10000 -> -65.53661 | H8: base 2026E growth
A9: 0.5 | B9: =AB_Bridge!$D$44*(1+$A9) -> 450.3 | C9: =AB_Bridge!$D$44*(1+$A9)^2 -> 675.45 | D9: =AB_Bridge!$E$39+AB_Bridge!$E$48-B9 -> -276.3875 | E9: =AB_Bridge!$F$39+AB_Bridge!$F$48-C9 -> -456.5375 | F9: =(D9-AB_Bridge!$D$55)/AB_Bridge!$E$56*10000 -> -78.10641 | G9: =(E9-D9)/AB_Bridge!$F$56*10000 -> -84.577465
A10: 0.6 | B10: =AB_Bridge!$D$44*(1+$A10) -> 480.32 | C10: =AB_Bridge!$D$44*(1+$A10)^2 -> 768.512 | D10: =AB_Bridge!$E$39+AB_Bridge!$E$48-B10 -> -306.4075 | E10: =AB_Bridge!$F$39+AB_Bridge!$F$48-C10 -> -549.5995 | F10: =(D10-AB_Bridge!$D$55)/AB_Bridge!$E$56*10000 -> -93.501282 | G10: =(E10-D10)/AB_Bridge!$F$56*10000 -> -114.17465
A11: 0.7 | B11: =AB_Bridge!$D$44*(1+$A11) -> 510.34 | C11: =AB_Bridge!$D$44*(1+$A11)^2 -> 867.578 | D11: =AB_Bridge!$E$39+AB_Bridge!$E$48-B11 -> -336.4275 | E11: =AB_Bridge!$F$39+AB_Bridge!$F$48-C11 -> -648.6655 | F11: =(D11-AB_Bridge!$D$55)/AB_Bridge!$E$56*10000 -> -108.89615 | G11: =(E11-D11)/AB_Bridge!$F$56*10000 -> -146.59061
A13: Base case on AB_Bridge (43% in 2026E, 30% in 2027E) | B13: =AB_Bridge!$E$44 -> 429.286 | C13: =AB_Bridge!$F$44 -> 558.0718 | D13: =AB_Bridge!$E$55 -> -255.3735 | E13: =AB_Bridge!$F$55 -> -339.1593 | F13: =AB_Bridge!$E$63 -> -67.33 | G13: =AB_Bridge!$F$63 -> -39.336056
A15: Reading: the headwind is negative in every row. Its size scales with the growth assigned to licensing cost, which rests on listeners +60% (disclosed) and a 0.7x haircut from listeners to cost (estimate).
