Workbook

Sheet Cover
B11: Company Information
B12: Company Name | C12: FTAI Aviation
B13: Ticker | C13: NASDAQ: FTAI
B15: Share price (10.2.26) | C15: =DCF!K18
B16: Diluted shares outstanding (mm) | C16: =DCF!K16
B17: Market Capitalization ($mm) | C17: =C15*C16
B18: (-) Cash & Equivalents ($mm) | C18: =DCF!K14*-1
B19: (+) Total Debt ($mm) | C19: =DCF!K12*-1
B20: (+) Preferred Equity ($mm) | C20: =DCF!K13*-1
B21: Enterprise Value ($mm) | C21: =SUM(C17:C20)
B23: Key
B24: Hardcodes | C24: BLUE
B25: Calculations | C25: BLACK
B26: Linked | C26: GREEN
B27: Key assumption / fill in | C27: YELLOW
B29: 1-Year Valuation (Oct-27)
B30: 1-year target (active case) | C30: ='1Y Valuation'!F24
B31: Return | C31: ='1Y Valuation'!F26
B32: Probability-weighted target | C32: ='1Y Valuation'!J11
B33: Reward / risk | C33: ='1Y Valuation'!J13

Sheet DCF
B2: Case Selector
B3: Toggle | C3: Base | P3: Sensitivity: Implied Share Price
Q4: Terminal Growth Rate
C5: 2026E | D5: 2027E | E5: 2028E | F5: 2029E | G5: 2030E | H5: 2031E | J5: Perpetuity Growth Method | M5: Exit Multiple Method | P5: =K17 | Q5: 0.02 | R5: 0.025 | S5: 0.03 | T5: 0.035 | U5: 0.04
B6: Present Value Bridge | J6: WACC | K6: ='WACC Calculation'!B20 | M6: WACC | N6: =K6 | P6: =ROUND($K$6*200,0)/200+(-0.01) | Q6: =(SUMPRODUCT($C$9:$H$9/(1+$P6)^$C$10:$H$10)+('Operating Model'!$I$29*(1+Q$5)-Q$5*'Operating Model'!$I$58)/($P6-Q$5)/(1+$P6)^$H$10+$K$12+$K$13+$K$14)/$K$16 | R6: =(SUMPRODUCT($C$9:$H$9/(1+$P6)^$C$10:$H$10)+('Operating Model'!$I$29*(1+R$5)-R$5*'Operating Model'!$I$58)/($P6-R$5)/(1+$P6)^$H$10+$K$12+$K$13+$K$14)/$K$16 | S6: =(SUMPRODUCT($C$9:$H$9/(1+$P6)^$C$10:$H$10)+('Operating Model'!$I$29*(1+S$5)-S$5*'Operating Model'!$I$58)/($P6-S$5)/(1+$P6)^$H$10+$K$12+$K$13+$K$14)/$K$16 | T6: =(SUMPRODUCT($C$9:$H$9/(1+$P6)^$C$10:$H$10)+('Operating Model'!$I$29*(1+T$5)-T$5*'Operating Model'!$I$58)/($P6-T$5)/(1+$P6)^$H$10+$K$12+$K$13+$K$14)/$K$16 | U6: =(SUMPRODUCT($C$9:$H$9/(1+$P6)^$C$10:$H$10)+('Operating Model'!$I$29*(1+U$5)-U$5*'Operating Model'!$I$58)/($P6-U$5)/(1+$P6)^$H$10+$K$12+$K$13+$K$14)/$K$16
B7: UFCF | C7: ='Operating Model'!D69 | D7: ='Operating Model'!E69 | E7: ='Operating Model'!F69 | F7: ='Operating Model'!G69 | G7: ='Operating Model'!H69 | H7: ='Operating Model'!I69 | J7: PV of Projected UFCF | K7: =SUM(C12:H12) | M7: PV of Projected UFCF | N7: =K7 | P7: =ROUND($K$6*200,0)/200+(-0.005) | Q7: =(SUMPRODUCT($C$9:$H$9/(1+$P7)^$C$10:$H$10)+('Operating Model'!$I$29*(1+Q$5)-Q$5*'Operating Model'!$I$58)/($P7-Q$5)/(1+$P7)^$H$10+$K$12+$K$13+$K$14)/$K$16 | R7: =(SUMPRODUCT($C$9:$H$9/(1+$P7)^$C$10:$H$10)+('Operating Model'!$I$29*(1+R$5)-R$5*'Operating Model'!$I$58)/($P7-R$5)/(1+$P7)^$H$10+$K$12+$K$13+$K$14)/$K$16 | S7: =(SUMPRODUCT($C$9:$H$9/(1+$P7)^$C$10:$H$10)+('Operating Model'!$I$29*(1+S$5)-S$5*'Operating Model'!$I$58)/($P7-S$5)/(1+$P7)^$H$10+$K$12+$K$13+$K$14)/$K$16 | T7: =(SUMPRODUCT($C$9:$H$9/(1+$P7)^$C$10:$H$10)+('Operating Model'!$I$29*(1+T$5)-T$5*'Operating Model'!$I$58)/($P7-T$5)/(1+$P7)^$H$10+$K$12+$K$13+$K$14)/$K$16 | U7: =(SUMPRODUCT($C$9:$H$9/(1+$P7)^$C$10:$H$10)+('Operating Model'!$I$29*(1+U$5)-U$5*'Operating Model'!$I$58)/($P7-U$5)/(1+$P7)^$H$10+$K$12+$K$13+$K$14)/$K$16
B8: Year Fraction | C8: =$K$21 | D8: 1 | E8: 1 | F8: 1 | G8: 1 | H8: 1 | J8: Terminal Growth Rate | K8: 0.03 | M8: Final Year Adj. EBITDA | N8: =H14 | O8: WACC | P8: =ROUND($K$6*200,0)/200+(0) | Q8: =(SUMPRODUCT($C$9:$H$9/(1+$P8)^$C$10:$H$10)+('Operating Model'!$I$29*(1+Q$5)-Q$5*'Operating Model'!$I$58)/($P8-Q$5)/(1+$P8)^$H$10+$K$12+$K$13+$K$14)/$K$16 | R8: =(SUMPRODUCT($C$9:$H$9/(1+$P8)^$C$10:$H$10)+('Operating Model'!$I$29*(1+R$5)-R$5*'Operating Model'!$I$58)/($P8-R$5)/(1+$P8)^$H$10+$K$12+$K$13+$K$14)/$K$16 | S8: =(SUMPRODUCT($C$9:$H$9/(1+$P8)^$C$10:$H$10)+('Operating Model'!$I$29*(1+S$5)-S$5*'Operating Model'!$I$58)/($P8-S$5)/(1+$P8)^$H$10+$K$12+$K$13+$K$14)/$K$16 | T8: =(SUMPRODUCT($C$9:$H$9/(1+$P8)^$C$10:$H$10)+('Operating Model'!$I$29*(1+T$5)-T$5*'Operating Model'!$I$58)/($P8-T$5)/(1+$P8)^$H$10+$K$12+$K$13+$K$14)/$K$16 | U8: =(SUMPRODUCT($C$9:$H$9/(1+$P8)^$C$10:$H$10)+('Operating Model'!$I$29*(1+U$5)-U$5*'Operating Model'!$I$58)/($P8-U$5)/(1+$P8)^$H$10+$K$12+$K$13+$K$14)/$K$16
B9: UFCF in Period | C9: =C7*C8 | D9: =D7*D8 | E9: =E7*E8 | F9: =F7*F8 | G9: =G7*G8 | H9: =H7*H8 | J9: Terminal Value | K9: =K22/(K6-K8) | M9: Exit Multiple (EV / EBITDA) | N9: 13 | P9: =ROUND($K$6*200,0)/200+(0.005) | Q9: =(SUMPRODUCT($C$9:$H$9/(1+$P9)^$C$10:$H$10)+('Operating Model'!$I$29*(1+Q$5)-Q$5*'Operating Model'!$I$58)/($P9-Q$5)/(1+$P9)^$H$10+$K$12+$K$13+$K$14)/$K$16 | R9: =(SUMPRODUCT($C$9:$H$9/(1+$P9)^$C$10:$H$10)+('Operating Model'!$I$29*(1+R$5)-R$5*'Operating Model'!$I$58)/($P9-R$5)/(1+$P9)^$H$10+$K$12+$K$13+$K$14)/$K$16 | S9: =(SUMPRODUCT($C$9:$H$9/(1+$P9)^$C$10:$H$10)+('Operating Model'!$I$29*(1+S$5)-S$5*'Operating Model'!$I$58)/($P9-S$5)/(1+$P9)^$H$10+$K$12+$K$13+$K$14)/$K$16 | T9: =(SUMPRODUCT($C$9:$H$9/(1+$P9)^$C$10:$H$10)+('Operating Model'!$I$29*(1+T$5)-T$5*'Operating Model'!$I$58)/($P9-T$5)/(1+$P9)^$H$10+$K$12+$K$13+$K$14)/$K$16 | U9: =(SUMPRODUCT($C$9:$H$9/(1+$P9)^$C$10:$H$10)+('Operating Model'!$I$29*(1+U$5)-U$5*'Operating Model'!$I$58)/($P9-U$5)/(1+$P9)^$H$10+$K$12+$K$13+$K$14)/$K$16
B10: Discount Period (mid-year) | C10: =C8/2 | D10: =SUM($C$8:C8)+D8/2 | E10: =SUM($C$8:D8)+E8/2 | F10: =SUM($C$8:E8)+F8/2 | G10: =SUM($C$8:F8)+G8/2 | H10: =SUM($C$8:G8)+H8/2 | J10: PV of TV (mid-year) | K10: =K9/(1+K6)^H10 | M10: Terminal Value | N10: =N8*N9 | P10: =ROUND($K$6*200,0)/200+(0.01) | Q10: =(SUMPRODUCT($C$9:$H$9/(1+$P10)^$C$10:$H$10)+('Operating Model'!$I$29*(1+Q$5)-Q$5*'Operating Model'!$I$58)/($P10-Q$5)/(1+$P10)^$H$10+$K$12+$K$13+$K$14)/$K$16 | R10: =(SUMPRODUCT($C$9:$H$9/(1+$P10)^$C$10:$H$10)+('Operating Model'!$I$29*(1+R$5)-R$5*'Operating Model'!$I$58)/($P10-R$5)/(1+$P10)^$H$10+$K$12+$K$13+$K$14)/$K$16 | S10: =(SUMPRODUCT($C$9:$H$9/(1+$P10)^$C$10:$H$10)+('Operating Model'!$I$29*(1+S$5)-S$5*'Operating Model'!$I$58)/($P10-S$5)/(1+$P10)^$H$10+$K$12+$K$13+$K$14)/$K$16 | T10: =(SUMPRODUCT($C$9:$H$9/(1+$P10)^$C$10:$H$10)+('Operating Model'!$I$29*(1+T$5)-T$5*'Operating Model'!$I$58)/($P10-T$5)/(1+$P10)^$H$10+$K$12+$K$13+$K$14)/$K$16 | U10: =(SUMPRODUCT($C$9:$H$9/(1+$P10)^$C$10:$H$10)+('Operating Model'!$I$29*(1+U$5)-U$5*'Operating Model'!$I$58)/($P10-U$5)/(1+$P10)^$H$10+$K$12+$K$13+$K$14)/$K$16
B11: Discount Factor | C11: =1/(1+$K$6)^C10 | D11: =1/(1+$K$6)^D10 | E11: =1/(1+$K$6)^E10 | F11: =1/(1+$K$6)^F10 | G11: =1/(1+$K$6)^G10 | H11: =1/(1+$K$6)^H10 | J11: Enterprise Value | K11: =K7+K10 | M11: PV of TV | N11: =N10/(1+K6)^(H10+H8/2) | P11: =ROUND($K$6*200,0)/200+(0.015) | Q11: =(SUMPRODUCT($C$9:$H$9/(1+$P11)^$C$10:$H$10)+('Operating Model'!$I$29*(1+Q$5)-Q$5*'Operating Model'!$I$58)/($P11-Q$5)/(1+$P11)^$H$10+$K$12+$K$13+$K$14)/$K$16 | R11: =(SUMPRODUCT($C$9:$H$9/(1+$P11)^$C$10:$H$10)+('Operating Model'!$I$29*(1+R$5)-R$5*'Operating Model'!$I$58)/($P11-R$5)/(1+$P11)^$H$10+$K$12+$K$13+$K$14)/$K$16 | S11: =(SUMPRODUCT($C$9:$H$9/(1+$P11)^$C$10:$H$10)+('Operating Model'!$I$29*(1+S$5)-S$5*'Operating Model'!$I$58)/($P11-S$5)/(1+$P11)^$H$10+$K$12+$K$13+$K$14)/$K$16 | T11: =(SUMPRODUCT($C$9:$H$9/(1+$P11)^$C$10:$H$10)+('Operating Model'!$I$29*(1+T$5)-T$5*'Operating Model'!$I$58)/($P11-T$5)/(1+$P11)^$H$10+$K$12+$K$13+$K$14)/$K$16 | U11: =(SUMPRODUCT($C$9:$H$9/(1+$P11)^$C$10:$H$10)+('Operating Model'!$I$29*(1+U$5)-U$5*'Operating Model'!$I$58)/($P11-U$5)/(1+$P11)^$H$10+$K$12+$K$13+$K$14)/$K$16
B12: PV of UFCF | C12: =C9*C11 | D12: =D9*D11 | E12: =E9*E11 | F12: =F9*F11 | G12: =G9*G11 | H12: =H9*H11 | J12: (-) Debt | K12: -3453.32 | M12: Enterprise Value | N12: =N7+N11
J13: (-) Preferred Equity | K13: -65 | M13: (-) Debt | N13: =K12 | Q13: Exit Multiple (EV / EBITDA)
B14: Adj. EBITDA | C14: ='Operating Model'!D18 | D14: ='Operating Model'!E18 | E14: ='Operating Model'!F18 | F14: ='Operating Model'!G18 | G14: ='Operating Model'!H18 | H14: ='Operating Model'!I18 | J14: (+) Cash | K14: 337.195 | M14: (-) Preferred Equity | N14: =K13 | P14: =N18 | Q14: 11 | R14: 12 | S14: 13 | T14: 14 | U14: 15
J15: Equity Value | K15: =K11+K12+K13+K14 | M15: (+) Cash | N15: =K14 | P15: =P6 | Q15: =(SUMPRODUCT($C$9:$H$9/(1+$P15)^$C$10:$H$10)+$H$14*Q$14/(1+$P15)^($H$10+$H$8/2)+$K$12+$K$13+$K$14)/$K$16 | R15: =(SUMPRODUCT($C$9:$H$9/(1+$P15)^$C$10:$H$10)+$H$14*R$14/(1+$P15)^($H$10+$H$8/2)+$K$12+$K$13+$K$14)/$K$16 | S15: =(SUMPRODUCT($C$9:$H$9/(1+$P15)^$C$10:$H$10)+$H$14*S$14/(1+$P15)^($H$10+$H$8/2)+$K$12+$K$13+$K$14)/$K$16 | T15: =(SUMPRODUCT($C$9:$H$9/(1+$P15)^$C$10:$H$10)+$H$14*T$14/(1+$P15)^($H$10+$H$8/2)+$K$12+$K$13+$K$14)/$K$16 | U15: =(SUMPRODUCT($C$9:$H$9/(1+$P15)^$C$10:$H$10)+$H$14*U$14/(1+$P15)^($H$10+$H$8/2)+$K$12+$K$13+$K$14)/$K$16
J16: Diluted Shares (mm) | K16: 104.044 | M16: Equity Value | N16: =N12+N13+N14+N15 | P16: =P7 | Q16: =(SUMPRODUCT($C$9:$H$9/(1+$P16)^$C$10:$H$10)+$H$14*Q$14/(1+$P16)^($H$10+$H$8/2)+$K$12+$K$13+$K$14)/$K$16 | R16: =(SUMPRODUCT($C$9:$H$9/(1+$P16)^$C$10:$H$10)+$H$14*R$14/(1+$P16)^($H$10+$H$8/2)+$K$12+$K$13+$K$14)/$K$16 | S16: =(SUMPRODUCT($C$9:$H$9/(1+$P16)^$C$10:$H$10)+$H$14*S$14/(1+$P16)^($H$10+$H$8/2)+$K$12+$K$13+$K$14)/$K$16 | T16: =(SUMPRODUCT($C$9:$H$9/(1+$P16)^$C$10:$H$10)+$H$14*T$14/(1+$P16)^($H$10+$H$8/2)+$K$12+$K$13+$K$14)/$K$16 | U16: =(SUMPRODUCT($C$9:$H$9/(1+$P16)^$C$10:$H$10)+$H$14*U$14/(1+$P16)^($H$10+$H$8/2)+$K$12+$K$13+$K$14)/$K$16
B17: Sum of the Parts (FY27E) | C17: FY27E EBITDA | D17: EV / EBITDA | E17: EV ($mm) | F17: $ / Share | J17: Implied Share Price | K17: =K15/K16 | M17: Diluted Shares (mm) | N17: =K16 | O17: WACC | P17: =P8 | Q17: =(SUMPRODUCT($C$9:$H$9/(1+$P17)^$C$10:$H$10)+$H$14*Q$14/(1+$P17)^($H$10+$H$8/2)+$K$12+$K$13+$K$14)/$K$16 | R17: =(SUMPRODUCT($C$9:$H$9/(1+$P17)^$C$10:$H$10)+$H$14*R$14/(1+$P17)^($H$10+$H$8/2)+$K$12+$K$13+$K$14)/$K$16 | S17: =(SUMPRODUCT($C$9:$H$9/(1+$P17)^$C$10:$H$10)+$H$14*S$14/(1+$P17)^($H$10+$H$8/2)+$K$12+$K$13+$K$14)/$K$16 | T17: =(SUMPRODUCT($C$9:$H$9/(1+$P17)^$C$10:$H$10)+$H$14*T$14/(1+$P17)^($H$10+$H$8/2)+$K$12+$K$13+$K$14)/$K$16 | U17: =(SUMPRODUCT($C$9:$H$9/(1+$P17)^$C$10:$H$10)+$H$14*U$14/(1+$P17)^($H$10+$H$8/2)+$K$12+$K$13+$K$14)/$K$16
B18: Aerospace Products | C18: ='Operating Model'!E14 | D18: 16 | E18: =C18*D18 | F18: =E18/$K$16 | J18: Current Price | K18: 167.03 | M18: Implied Share Price | N18: =N16/N17 | P18: =P9 | Q18: =(SUMPRODUCT($C$9:$H$9/(1+$P18)^$C$10:$H$10)+$H$14*Q$14/(1+$P18)^($H$10+$H$8/2)+$K$12+$K$13+$K$14)/$K$16 | R18: =(SUMPRODUCT($C$9:$H$9/(1+$P18)^$C$10:$H$10)+$H$14*R$14/(1+$P18)^($H$10+$H$8/2)+$K$12+$K$13+$K$14)/$K$16 | S18: =(SUMPRODUCT($C$9:$H$9/(1+$P18)^$C$10:$H$10)+$H$14*S$14/(1+$P18)^($H$10+$H$8/2)+$K$12+$K$13+$K$14)/$K$16 | T18: =(SUMPRODUCT($C$9:$H$9/(1+$P18)^$C$10:$H$10)+$H$14*T$14/(1+$P18)^($H$10+$H$8/2)+$K$12+$K$13+$K$14)/$K$16 | U18: =(SUMPRODUCT($C$9:$H$9/(1+$P18)^$C$10:$H$10)+$H$14*U$14/(1+$P18)^($H$10+$H$8/2)+$K$12+$K$13+$K$14)/$K$16
B19: FTAI Power | C19: ='Operating Model'!E15 | D19: 12 | E19: =C19*D19 | F19: =E19/$K$16 | J19: % Upside | K19: =(K17-K18)/K18 | M19: Current Price | N19: =K18 | P19: =P10 | Q19: =(SUMPRODUCT($C$9:$H$9/(1+$P19)^$C$10:$H$10)+$H$14*Q$14/(1+$P19)^($H$10+$H$8/2)+$K$12+$K$13+$K$14)/$K$16 | R19: =(SUMPRODUCT($C$9:$H$9/(1+$P19)^$C$10:$H$10)+$H$14*R$14/(1+$P19)^($H$10+$H$8/2)+$K$12+$K$13+$K$14)/$K$16 | S19: =(SUMPRODUCT($C$9:$H$9/(1+$P19)^$C$10:$H$10)+$H$14*S$14/(1+$P19)^($H$10+$H$8/2)+$K$12+$K$13+$K$14)/$K$16 | T19: =(SUMPRODUCT($C$9:$H$9/(1+$P19)^$C$10:$H$10)+$H$14*T$14/(1+$P19)^($H$10+$H$8/2)+$K$12+$K$13+$K$14)/$K$16 | U19: =(SUMPRODUCT($C$9:$H$9/(1+$P19)^$C$10:$H$10)+$H$14*U$14/(1+$P19)^($H$10+$H$8/2)+$K$12+$K$13+$K$14)/$K$16
B20: Aviation Leasing + SCI | C20: ='Operating Model'!E16 | D20: 9 | E20: =C20*D20 | F20: =E20/$K$16 | M20: % Upside | N20: =(N18-N19)/N19 | P20: =P11 | Q20: =(SUMPRODUCT($C$9:$H$9/(1+$P20)^$C$10:$H$10)+$H$14*Q$14/(1+$P20)^($H$10+$H$8/2)+$K$12+$K$13+$K$14)/$K$16 | R20: =(SUMPRODUCT($C$9:$H$9/(1+$P20)^$C$10:$H$10)+$H$14*R$14/(1+$P20)^($H$10+$H$8/2)+$K$12+$K$13+$K$14)/$K$16 | S20: =(SUMPRODUCT($C$9:$H$9/(1+$P20)^$C$10:$H$10)+$H$14*S$14/(1+$P20)^($H$10+$H$8/2)+$K$12+$K$13+$K$14)/$K$16 | T20: =(SUMPRODUCT($C$9:$H$9/(1+$P20)^$C$10:$H$10)+$H$14*T$14/(1+$P20)^($H$10+$H$8/2)+$K$12+$K$13+$K$14)/$K$16 | U20: =(SUMPRODUCT($C$9:$H$9/(1+$P20)^$C$10:$H$10)+$H$14*U$14/(1+$P20)^($H$10+$H$8/2)+$K$12+$K$13+$K$14)/$K$16
B21: Corporate & Eliminations | C21: ='Operating Model'!E17 | D21: =SUMPRODUCT(C18:C20,D18:D20)/SUM(C18:C20) | E21: =C21*D21 | F21: =E21/$K$16 | J21: Stub Year Fraction (FY26) | K21: 0.5
B22: Enterprise Value | C22: =SUM(C18:C21) | D22: =E22/C22 | E22: =SUM(E18:E21) | F22: =E22/$K$16 | J22: Normalized Terminal UFCF | K22: ='Operating Model'!I29*(1+K8)-K8*'Operating Model'!I58 | M22: Implied Terminal Growth | N22: =(N10/(1+K6)^0.5*K6-'Operating Model'!I29)/(N10/(1+K6)^0.5+'Operating Model'!I29-'Operating Model'!I58)
B23: (-) Net Debt (YE27E) | E23: =-'Operating Model'!E79 | F23: =E23/$K$16 | M23: Implied Exit Multiple (Perpetuity) | N23: =K9*(1+K6)^0.5/H14
B24: (-) Preferred Equity | E24: =K13 | F24: =E24/$K$16
B25: Equity Value | E25: =E22+E23+E24 | F25: =E25/$K$16 | J25: R/R | M25: Blended Valuation
B26: Current Price | F26: =K18 | J26: Reward (Bull blended % upside) | K26: 1.319 | M26: Perpetuity Growth Method | N26: =K17
B27: SOTP % Upside | F27: =F25/F26-1 | J27: Risk (Bear blended % downside) | K27: -0.386 | M27: Exit Multiple Method | N27: =N18
J28: R/R Skew | K28: =IFERROR(K26/(-1*K27),0) | M28: Weight on Perpetuity Method | N28: 0.5
B29: SOTP Price ex-Power | F29: =(E25-E19)/$K$16 | M29: Blended Share Price | N29: =N26*N28+N27*(1-N28)
B30: SOTP % Upside ex-Power | F30: =F29/F26-1 | M30: Current Price | N30: =K18
M31: Blended % Upside | N31: =N29/N30-1

Sheet 1Y Valuation
B1: FTAI Aviation
B2: 1-Year Valuation (target date Oct-27) – matches the pitch deck
B3: Case follows DCF!C3. NTM = Q4'27–Q3'28 ≈ ¼ FY27E + ¾ FY28E; net debt interpolated YE26E → YE27E. $ in millions except per share.
B5: Case-specific multiples (EV / NTM EBITDA) | H5: Case outputs (pasted values from the case toggle)
B6: Segment | C6: Bear | D6: Base | E6: Bull | F6: Active | I6: Bear | J6: Base | K6: Bull
B7: Aerospace Products | C7: 10 | D7: 14 | E7: 16 | F7: =CHOOSE(MATCH(DCF!$C$3,{"Bear","Base","Bull"},0),C7,D7,E7) | H7: NTM adj. EBITDA ($M) | I7: 1562.1 | J7: 2843.4 | K7: 3402
B8: FTAI Power | C8: 8 | D8: 10 | E8: 12 | F8: =CHOOSE(MATCH(DCF!$C$3,{"Bear","Base","Bull"},0),C8,D8,E8) | H8: 1-year target ($ / share) | I8: 113.52 | J8: 309.32 | K8: 429.94
B9: Aviation Leasing + SCI | C9: 8 | D9: 9 | E9: 9 | F9: =CHOOSE(MATCH(DCF!$C$3,{"Bear","Base","Bull"},0),C9,D9,E9) | H9: Return vs. $167.03 | I9: -0.32 | J9: 0.852 | K9: 1.574
H10: Probability | I10: 0.2 | J10: 0.6 | K10: 0.2
B11: NTM weights | H11: Probability-weighted target | J11: =SUMPRODUCT(I8:K8,I10:K10)
B12: Weight on FY27E | C12: 0.25 | H12: Probability-weighted return | J12: =J11/F25-1
B13: Weight on FY28E | C13: =1-C12 | H13: Reward / risk (bull up / bear down) | J13: =K9/-I9
B15: Sum of the parts at Oct-27 (active case) | H15: Value bridge by thesis (base multiples)
B16: Segment | C16: NTM EBITDA | D16: EV / EBITDA | E16: EV | F16: $ / share | H16: Step | I16: $ / share | J16: Cumulative
B17: Aerospace Products | C17: =$C$12*'Operating Model'!E14+$C$13*'Operating Model'!F14 | D17: =F7 | E17: =C17*D17 | F17: =E17/DCF!$K$16 | H17: Bear-case outcomes (≈ today's $167) | I17: 161.2 | J17: =SUM($I$17:I17)
B18: FTAI Power | C18: =$C$12*'Operating Model'!E15+$C$13*'Operating Model'!F15 | D18: =F8 | E18: =C18*D18 | F18: =E18/DCF!$K$16 | H18: + Thesis I: margins (margin, PMA, pass-through, escalator, inventory) | I18: 22.3 | J18: =SUM($I$17:I18)
B19: Aviation Leasing + SCI | C19: =$C$12*'Operating Model'!E16+$C$13*'Operating Model'!F16 | D19: =F9 | E19: =C19*D19 | F19: =E19/DCF!$K$16 | H19: + Thesis II: share (retirements, SV rates, share, SCI fleet, leasing) | I19: 62.4 | J19: =SUM($I$17:I19)
B20: Corporate & eliminations (at blended multiple) | C20: =$C$12*'Operating Model'!E17+$C$13*'Operating Model'!F17 | D20: =SUM(E17:E19)/SUM(C17:C19) | E20: =C20*D20 | F20: =E20/DCF!$K$16 | H20: + Thesis III: Power (units, JV share, margin) | I20: 63.4 | J20: =SUM($I$17:I20)
B21: Enterprise value | C21: =SUM(C17:C20) | D21: =E21/C21 | E21: =SUM(E17:E20) | F21: =E21/DCF!$K$16 | H21: Base-case 1-year target | J21: =J20
B22: (–) Net debt (Sep-27E) | E22: =-($C$12*'Operating Model'!D79+$C$13*'Operating Model'!E79) | F22: =E22/DCF!$K$16 | H22: Method: starting from the Bear case, each thesis's Assumptions bear rows were set to base values in order (I → II → III) and the SOTP re-run at base multiples. Order-dependent; values pasted.
B23: (–) Preferred equity | E23: =DCF!K13 | F23: =E23/DCF!$K$16
B24: 1-year target (equity value / share) | E24: =SUM(E21:E23) | F24: =E24/DCF!$K$16
B25: Current price | F25: =DCF!K18
B26: Return | F26: =F24/F25-1
B28: Cross-checks (active case)
B29: EV / NTM EBITDA today (NTM ≈ ¼ FY26E + ¾ FY27E) | F29: =Cover!C21/($C$12*'Operating Model'!D18+$C$13*'Operating Model'!E18)
B30: EV / NTM EBITDA at target | F30: =D21
B31: Target ex-Power (Power multiple = 0) | F31: =((E17+E19)*(1+C20/SUM(C17:C19))+E22+E23)/DCF!$K$16
B32: Aerospace multiple implied by today's price | F32: =((F25*DCF!$K$16-E22-E23)/(1+C20/SUM(C17:C19))-E18-E19)/C17
B33: $ / share per 1x of Aerospace multiple | F33: =C17*(1+C20/SUM(C17:C19))/DCF!$K$16
B34: Blended DCF rolled forward 1 year (– dividends) | F34: =DCF!N29*(1+'WACC Calculation'!B19)-C35
B35: Dividends next 12 months ($ / share) | C35: 2
B37: Sensitivity: 1-year target, Aerospace × Power multiple (active case)
B38: Aero \ Power | C38: 6 | D38: 8 | E38: 10 | F38: 12
B39: 10 | C39: =(($B39*$C$17+C$38*$C$18+$D$19*$C$19)*(1+$C$20/SUM($C$17:$C$19))+$E$22+$E$23)/DCF!$K$16 | D39: =(($B39*$C$17+D$38*$C$18+$D$19*$C$19)*(1+$C$20/SUM($C$17:$C$19))+$E$22+$E$23)/DCF!$K$16 | E39: =(($B39*$C$17+E$38*$C$18+$D$19*$C$19)*(1+$C$20/SUM($C$17:$C$19))+$E$22+$E$23)/DCF!$K$16 | F39: =(($B39*$C$17+F$38*$C$18+$D$19*$C$19)*(1+$C$20/SUM($C$17:$C$19))+$E$22+$E$23)/DCF!$K$16
B40: 12 | C40: =(($B40*$C$17+C$38*$C$18+$D$19*$C$19)*(1+$C$20/SUM($C$17:$C$19))+$E$22+$E$23)/DCF!$K$16 | D40: =(($B40*$C$17+D$38*$C$18+$D$19*$C$19)*(1+$C$20/SUM($C$17:$C$19))+$E$22+$E$23)/DCF!$K$16 | E40: =(($B40*$C$17+E$38*$C$18+$D$19*$C$19)*(1+$C$20/SUM($C$17:$C$19))+$E$22+$E$23)/DCF!$K$16 | F40: =(($B40*$C$17+F$38*$C$18+$D$19*$C$19)*(1+$C$20/SUM($C$17:$C$19))+$E$22+$E$23)/DCF!$K$16
B41: 14 | C41: =(($B41*$C$17+C$38*$C$18+$D$19*$C$19)*(1+$C$20/SUM($C$17:$C$19))+$E$22+$E$23)/DCF!$K$16 | D41: =(($B41*$C$17+D$38*$C$18+$D$19*$C$19)*(1+$C$20/SUM($C$17:$C$19))+$E$22+$E$23)/DCF!$K$16 | E41: =(($B41*$C$17+E$38*$C$18+$D$19*$C$19)*(1+$C$20/SUM($C$17:$C$19))+$E$22+$E$23)/DCF!$K$16 | F41: =(($B41*$C$17+F$38*$C$18+$D$19*$C$19)*(1+$C$20/SUM($C$17:$C$19))+$E$22+$E$23)/DCF!$K$16
B42: 16 | C42: =(($B42*$C$17+C$38*$C$18+$D$19*$C$19)*(1+$C$20/SUM($C$17:$C$19))+$E$22+$E$23)/DCF!$K$16 | D42: =(($B42*$C$17+D$38*$C$18+$D$19*$C$19)*(1+$C$20/SUM($C$17:$C$19))+$E$22+$E$23)/DCF!$K$16 | E42: =(($B42*$C$17+E$38*$C$18+$D$19*$C$19)*(1+$C$20/SUM($C$17:$C$19))+$E$22+$E$23)/DCF!$K$16 | F42: =(($B42*$C$17+F$38*$C$18+$D$19*$C$19)*(1+$C$20/SUM($C$17:$C$19))+$E$22+$E$23)/DCF!$K$16

Sheet Diligence
B1: FTAI Aviation
B2: Diligence summary behind the Thesis II assumptions (search-based, Oct-26; counts are a floor)
B4: 1. CFM56 Outsourcing Flip Tracker – 14 tier-1 engine shops
B5: Shop type | C5: Reviewed | D5: Add LEAP | E5: Pull back CFM56 | F5: Win outside CFM56
B6: Airline-owned | C6: 8 | D6: 8 | E6: 1 | F6: 3
B7: OEM network | C7: 2 | D7: 2 | E7: 1 | F7: 2
B8: Independent | C8: 4 | D8: 4 | E8: 0 | F8: 4
B9: Total | C9: =SUM(C6:C8) | D9: =SUM(D6:D8) | E9: =SUM(E6:E8) | F9: =SUM(F6:F8)
B10: • OEMs: all new sites LEAP-only; CFM gives up Ryanair CFM56 labor from 2029 (keeps parts).
B11: • First airline flip: Lufthansa Group sends own CFM56 to FL Technics (Oct-26). EVA Air → MTU (May-26); United → FTAI CFM56-7B MRE (Oct-26).
B12: • Counter: Korean Air keeps CFM56, outsources LEAP; independents also add CFM56 (overflow is real but contested).
B14: 2. Test Cell Tracker – 18 engine test cells
B15: Category | C15: Cells
B16: Existing cells adapted to test LEAP (incl. 1 likely) | C16: 9
B17: …still testing CFM56, where disclosed | C17: 4 of 4
B18: …dropped CFM56 | C18: 0
B19: New cells built for LEAP | C19: 7
B20: New cell built first for CFM56 (Willis Lease + GEM) | C20: 1
B21: Unknown (LHT Hamburg, StandardAero) | C21: 2
B22: • 'Ongoing shortage of testing capacity' – Willis Lease; 'Europe-wide testing capacity constraints' – SR Technics. LEAP shares cells; no cell dropped CFM56.
B24: 3. Retirements, fuel and OEM capacity – evidence vs. model inputs
B25: Evidence | C25: Value | E25: Model input | F25: Model value | G25: Read-across
B26: GE 2026 CFM56 retirements (actual, Sep-26) | C26: 1.5–2.0% | E26: FY26 retirement -7B / -5B | F26: =TEXT(Assumptions!F10,"0.0%")&" / "&TEXT(Assumptions!F15,"0.0%") | G26: Consistent – base retained
B27: GE view of 2027 retirements | C27: ~3% | E27: FY27 retirement -7B / -5B | F27: =TEXT(Assumptions!K10,"0.0%")&" / "&TEXT(Assumptions!K15,"0.0%") | G27: Base ~2.2% blended is below GE's ~3%; GE has cut its view four times. Bear (2.5% / 4.0%) covers GE's number
B28: GE CFM56 shop visits 2026 / 2027 | C28: ~2,400 / ~2,400 | E28: Total shop visits FY26 / FY27 | F28: =TEXT(RPM!L26,"#,##0")&" / "&TEXT(RPM!Q26,"#,##0") | G28: Consistent – base retained
B29: Jet fuel peak (IATA, 3-Apr-26) / 15-Sep-26 | C29: $209 / $198 bbl | E29: Retirement rates | F29: No change | G29: Parked CFM56s down since March; 2022 analog shows no retirement spike
B30: FTAI 2026 module guide | C30: 1,200 | E30: FTAI modules FY26E | F30: =TEXT(RPM!L42,"#,##0") | G30: Consistent – base retained
B31: Mgmt share of CFM56 market (Q2'26) | C31: 14% | E31: 3rd-party share FY27E (base) | F31: =TEXT(Assumptions!K46,"0.0%") | G31: Tracker shows OEM / airline work moving to independents; base ramp retained, bull 25%
B32: GE LEAP internal shop visits (Q2'26) | C32: +50% y/y | E32: — | F32: — | G32: OEM growth capacity going to LEAP
B33: OEM share of LEAP vs. CFM56 shop visits | C33: ~85% vs. ~1/3 | E33: — | F33: — | G33: Two-thirds of CFM56 work already with independents
B35: Conclusion: the new diligence confirms the base-case Thesis II inputs; no driver changes were needed. Valuation updated to the 1-year framework on '1Y Valuation'.
B36: Sources: Flip Tracker and Test Cell Tracker workbooks (Oct-26); GE Aerospace (Q2'26, MS Laguna Sep-26, Reuters Jul-26); IATA / Platts; Safran H1'26; CFM; FTAI Q2'26.

Sheet Operating Model
B1: FTAI Aviation
B2: Operating Model & Cash Flow Build
B3: Amounts in $ millions, except share data
B4: Fiscal year ends December 31st
C6: FY25A | D6: FY26E | E6: FY27E | F6: FY28E | G6: FY29E | H6: FY30E | I6: FY31E
A7: x | B7: Operating Build
B8: Aerospace Products Revenue | C8: =RPM!G82 | D8: =RPM!L82 | E8: =RPM!Q82 | F8: =RPM!R82 | G8: =RPM!S82 | H8: =RPM!T82 | I8: =RPM!U82
B9: FTAI Power Revenue | C9: =RPM!G83 | D9: =RPM!L83 | E9: =RPM!Q83 | F9: =RPM!R83 | G9: =RPM!S83 | H9: =RPM!T83 | I9: =RPM!U83
B10: Aviation Leasing + SCI Revenue | C10: =RPM!G84 | D10: =RPM!L84 | E10: =RPM!Q84 | F10: =RPM!R84 | G10: =RPM!S84 | H10: =RPM!T84 | I10: =RPM!U84
B11: Total Revenue | C11: =SUM(C8:C10) | D11: =SUM(D8:D10) | E11: =SUM(E8:E10) | F11: =SUM(F8:F10) | G11: =SUM(G8:G10) | H11: =SUM(H8:H10) | I11: =SUM(I8:I10)
B12: YoY Growth | D12: =D11/C11-1 | E12: =E11/D11-1 | F12: =F11/E11-1 | G12: =G11/F11-1 | H12: =H11/G11-1 | I12: =I11/H11-1
B14: Aerospace Products Adj. EBITDA | C14: =RPM!G89 | D14: =RPM!L89 | E14: =RPM!Q89 | F14: =RPM!R89 | G14: =RPM!S89 | H14: =RPM!T89 | I14: =RPM!U89
B15: FTAI Power Adj. EBITDA | C15: =RPM!G90 | D15: =RPM!L90 | E15: =RPM!Q90 | F15: =RPM!R90 | G15: =RPM!S90 | H15: =RPM!T90 | I15: =RPM!U90
B16: Aviation Leasing + SCI Adj. EBITDA | C16: =RPM!G91 | D16: =RPM!L91 | E16: =RPM!Q91 | F16: =RPM!R91 | G16: =RPM!S91 | H16: =RPM!T91 | I16: =RPM!U91
B17: Corporate & Eliminations | C17: =RPM!G92 | D17: =RPM!L92 | E17: =RPM!Q92 | F17: =RPM!R92 | G17: =RPM!S92 | H17: =RPM!T92 | I17: =RPM!U92
B18: Total Adj. EBITDA | C18: =SUM(C14:C17) | D18: =SUM(D14:D17) | E18: =SUM(E14:E17) | F18: =SUM(F14:F17) | G18: =SUM(G14:G17) | H18: =SUM(H14:H17) | I18: =SUM(I14:I17)
B19: Adj. EBITDA Margin | C19: =IFERROR(C18/C11,0) | D19: =IFERROR(D18/D11,0) | E19: =IFERROR(E18/E11,0) | F19: =IFERROR(F18/F11,0) | G19: =IFERROR(G18/G11,0) | H19: =IFERROR(H18/H11,0) | I19: =IFERROR(I18/I11,0)
B20: (-) Non-cash Adj. EBITDA Items (SCI share, elims, other) | C20: -230.7 | D20: =-D18*Assumptions!F140 | E20: =-E18*Assumptions!K140 | F20: =-F18*Assumptions!L140 | G20: =-G18*Assumptions!M140 | H20: =-H18*Assumptions!N140 | I20: =-I18*Assumptions!O140
B21: (-) D&A | C21: =-C40 | D21: =-D40 | E21: =-E40 | F21: =-F40 | G21: =-G40 | H21: =-H40 | I21: =-I40
B22: (-) SBC | C22: =-C45 | D22: =-D45 | E22: =-E45 | F22: =-F45 | G22: =-G45 | H22: =-H45 | I22: =-I45
B23: EBIT | C23: =C18+C20+C21+C22 | D23: =D18+D20+D21+D22 | E23: =E18+E20+E21+E22 | F23: =F18+F20+F21+F22 | G23: =G18+G20+G21+G22 | H23: =H18+H20+H21+H22 | I23: =I18+I20+I21+I22
B24: EBIT Margin | C24: =IFERROR(C23/C11,0) | D24: =IFERROR(D23/D11,0) | E24: =IFERROR(E23/E11,0) | F24: =IFERROR(F23/F11,0) | G24: =IFERROR(G23/G11,0) | H24: =IFERROR(H23/H11,0) | I24: =IFERROR(I23/I11,0)
B26: Taxes | D26: =MAX(0,D23)*D27 | E26: =MAX(0,E23)*E27 | F26: =MAX(0,F23)*F27 | G26: =MAX(0,G23)*G27 | H26: =MAX(0,H23)*H27 | I26: =MAX(0,I23)*I27
B27: Tax Rate | D27: =Assumptions!F119 | E27: =Assumptions!K119 | F27: =Assumptions!L119 | G27: =Assumptions!M119 | H27: =Assumptions!N119 | I27: =Assumptions!O119
B29: NOPAT | D29: =D23-D26 | E29: =E23-E26 | F29: =F23-F26 | G29: =G23-G26 | H29: =H23-H26 | I29: =I23-I26
B31: Cash Flow Reconciliation
A32: x | B32: Leasing Equipment & PP&E Schedule
B33: Beginning Leasing Equipment & PP&E | D33: =C39 | E33: =D39 | F33: =E39 | G33: =F39 | H33: =G39 | I33: =H39
B34: (+) Acquisition of Leasing Equipment | C34: 658.8 | D34: =Assumptions!F111 | E34: =Assumptions!K111 | F34: =Assumptions!L111 | G34: =Assumptions!M111 | H34: =Assumptions!N111 | I34: =Assumptions!O111
B35: (+) PP&E CapEx | C35: 27.712 | D35: =D36*D11+D9*Assumptions!F115 | E35: =E36*E11+E9*Assumptions!K115 | F35: =F36*F11+F9*Assumptions!L115 | G35: =G36*G11+G9*Assumptions!M115 | H35: =H36*H11+H9*Assumptions!N115 | I35: =I36*I11+I9*Assumptions!O115
B36: % of Sales | C36: =C35/C11 | D36: =Assumptions!F109 | E36: =Assumptions!K109 | F36: =Assumptions!L109 | G36: =Assumptions!M109 | H36: =Assumptions!N109 | I36: =Assumptions!O109
B37: (-) Sale of Leasing Equipment (at book) | C37: -1712.5 | D37: =-Assumptions!F113 | E37: =-Assumptions!K113 | F37: =-Assumptions!L113 | G37: =-Assumptions!M113 | H37: =-Assumptions!N113 | I37: =-Assumptions!O113
B38: (-) Depreciation & Amortization | C38: -225.797 | D38: =-Assumptions!F107 | E38: =-Assumptions!K107 | F38: =-Assumptions!L107 | G38: =-Assumptions!M107 | H38: =-Assumptions!N107 | I38: =-Assumptions!O107
B39: Ending Leasing Equipment & PP&E | C39: 1665.872 | D39: =D33+D34+D35+D37+D38 | E39: =E33+E34+E35+E37+E38 | F39: =F33+F34+F35+F37+F38 | G39: =G33+G34+G35+G37+G38 | H39: =H33+H34+H35+H37+H38 | I39: =I33+I34+I35+I37+I38
B40: Total D&A | C40: =-C38 | D40: =-D38 | E40: =-E38 | F40: =-F38 | G40: =-G38 | H40: =-H38 | I40: =-I38
B41: Total CapEx | C41: =C34+C35 | D41: =D34+D35 | E41: =E34+E35 | F41: =F34+F35 | G41: =G34+G35 | H41: =H34+H35 | I41: =I34+I35
B43: Non-Cash Adjustments
B44: (+) D&A | C44: =C40 | D44: =D40 | E44: =E40 | F44: =F40 | G44: =G40 | H44: =H40 | I44: =I40
B45: (+) SBC | C45: 21.733 | D45: =D46*D11 | E45: =E46*E11 | F45: =F46*F11 | G45: =G46*G11 | H45: =H46*H11 | I45: =I46*I11
B46: % of Sales | C46: =C45/C11 | D46: =Assumptions!F117 | E46: =Assumptions!K117 | F46: =Assumptions!L117 | G46: =Assumptions!M117 | H46: =Assumptions!N117 | I46: =Assumptions!O117
...

Sheet WACC Calculation
A1: WACC Calculation
A3: Total Market Capitalization ($mm) | B3: =DCF!K18*DCF!K16
A4: Total Debt ($mm) | B4: =-DCF!K12
A6: Weight of Equity | B6: =B3/(B3+B4)
A7: Weight of Debt | B7: =B4/(B3+B4)
A8: Total Weight | B8: =B6+B7
A10: Pretax Cost of Debt | B10: 0.072
A11: Tax Rate | B11: =Assumptions!F119
A12: After-tax Cost of Debt | B12: =B10*(1-B11)
A14: Risk Free Rate | B14: 0.042
A15: Market Risk Premium | B15: 0.045
A16: Return on Market | B16: =B14+B15
A17: Raw Beta (5Y monthly) | B17: 1.51
A18: Adjusted Beta (Bloomberg: 0.67 x raw + 0.33) | B18: =0.67*B17+0.33
A19: Cost of Equity | B19: =B14+B18*B15
A20: WACC | B20: =B19*B6+B12*B7 | D20: CAPM with Bloomberg-adjusted beta; blue inputs - refresh from Bloomberg

Sheet RPM
B1: FTAI Aviation
B2: Revenue Build
B3: (in million $)
C5: Q1-25 | D5: Q2-25 | E5: Q3-25 | F5: Q4-25 | G5: FY25 | H5: Q1-26 | I5: Q2-26 | J5: Q3-26 | K5: Q4-26 | L5: FY26 | M5: Q1-27 | N5: Q2-27 | O5: Q3-27 | P5: Q4-27 | Q5: FY27 | R5: FY28 | S5: FY29 | T5: FY30 | U5: FY31
B6: Aerospace Products
A8: x | B8: CFM56 Fleet & Shop Demand
B9: CFM56-7B (737MG)
B10: BoP Engine Fleet | C10: 13984 | D10: 13940 | E10: 13896 | F10: 13853 | G10: 13984 | H10: 13809 | I10: 13810 | J10: =I13 | K10: =J13 | L10: =H10 | M10: =K13 | N10: =M13 | O10: =N13 | P10: =O13 | Q10: =M10 | R10: =P13 | S10: =R13 | T10: =S13 | U10: =T13
B11: Retirement Rate | C11: 0.0031 | D11: 0.0031 | E11: 0.0031 | F11: 0.0031 | G11: 0.0125 | H11: 0.0038 | I11: 0.0038 | J11: =Assumptions!D8 | K11: =Assumptions!E8 | L11: =IFERROR(L12/L10,0) | M11: =Assumptions!G8 | N11: =Assumptions!H8 | O11: =Assumptions!I8 | P11: =Assumptions!J8 | Q11: =IFERROR(Q12/Q10,0) | R11: =Assumptions!L8 | S11: =Assumptions!M8 | T11: =Assumptions!N8 | U11: =Assumptions!O8
B12: Retired Engines | C12: 44 | D12: 44 | E12: 44 | F12: 43 | G12: 175 | H12: 52 | I12: 52 | J12: =J10*J11 | K12: =K10*K11 | L12: =SUM(H12:K12) | M12: =M10*M11 | N12: =N10*N11 | O12: =O10*O11 | P12: =P10*P11 | Q12: =SUM(M12:P12) | R12: =R10*R11 | S12: =S10*S11 | T12: =T10*T11 | U12: =U10*U11
B13: EoP Engine Fleet | C13: 13940 | D13: 13896 | E13: 13853 | F13: 13809 | G13: 13809 | H13: 13757 | I13: 13758 | J13: =J10-J12 | K13: =K10-K12 | L13: =K13 | M13: =M10-M12 | N13: =N10-N12 | O13: =O10-O12 | P13: =P10-P12 | Q13: =P13 | R13: =R10-R12 | S13: =S10-S12 | T13: =T10-T12 | U13: =U10-U12
B14: Shop Visit Rate | C14: 0.0261 | D14: 0.0262 | E14: 0.0263 | F14: 0.0264 | G14: 0.1055 | H14: 0.027 | I14: 0.027 | J14: =Assumptions!D18 | K14: =Assumptions!E18 | L14: =SUM(H14:K14) | M14: =Assumptions!G18 | N14: =Assumptions!H18 | O14: =Assumptions!I18 | P14: =Assumptions!J18 | Q14: =SUM(M14:P14) | R14: =Assumptions!L18 | S14: =Assumptions!M18 | T14: =Assumptions!N18 | U14: =Assumptions!O18
B15: Shop Visits | C15: 364 | D15: 364 | E15: 364 | F15: 364 | G15: 1457 | H15: 372 | I15: 372 | J15: =J14*J13 | K15: =K14*K13 | L15: =SUM(H15:K15) | M15: =M14*M13 | N15: =N14*N13 | O15: =O14*O13 | P15: =P14*P13 | Q15: =SUM(M15:P15) | R15: =R14*R13 | S15: =S14*S13 | T15: =T14*T13 | U15: =U14*U13
B17: CFM56-5B (A320ceo)
B18: BoP Engine Fleet | C18: 9016 | D18: 8988 | E18: 8959 | F18: 8931 | G18: 9016 | H18: 8903 | I18: 8893 | J18: =I21 | K18: =J21 | L18: =H18 | M18: =K21 | N18: =M21 | O18: =N21 | P18: =O21 | Q18: =M18 | R18: =P21 | S18: =R21 | T18: =S21 | U18: =T21
B19: Retirement Rate | C19: 0.0031 | D19: 0.0031 | E19: 0.0031 | F19: 0.0031 | G19: 0.0125 | H19: 0.005 | I19: 0.005 | J19: =Assumptions!D13 | K19: =Assumptions!E13 | L19: =IFERROR(L20/L18,0) | M19: =Assumptions!G13 | N19: =Assumptions!H13 | O19: =Assumptions!I13 | P19: =Assumptions!J13 | Q19: =IFERROR(Q20/Q18,0) | R19: =Assumptions!L13 | S19: =Assumptions!M13 | T19: =Assumptions!N13 | U19: =Assumptions!O13
B20: Retired Engines | C20: 28 | D20: 28 | E20: 28 | F20: 28 | G20: 113 | H20: 45 | I20: 45 | J20: =J19*J18 | K20: =K19*K18 | L20: =SUM(H20:K20) | M20: =M19*M18 | N20: =N19*N18 | O20: =O19*O18 | P20: =P19*P18 | Q20: =SUM(M20:P20) | R20: =R19*R18 | S20: =S19*S18 | T20: =T19*T18 | U20: =U19*U18
B21: EoP Engine Fleet | C21: 8988 | D21: 8959 | E21: 8931 | F21: 8903 | G21: 8903 | H21: 8858 | I21: 8848 | J21: =J18-J20 | K21: =K18-K20 | L21: =K21 | M21: =M18-M20 | N21: =N18-N20 | O21: =O18-O20 | P21: =P18-P20 | Q21: =P21 | R21: =R18-R20 | S21: =S18-S20 | T21: =T18-T20 | U21: =U18-U20
B22: Shop Visit Rate | C22: 0.0248 | D22: 0.0249 | E22: 0.025 | F22: 0.0251 | G22: 0.1003 | H22: 0.0257 | I22: 0.0258 | J22: =Assumptions!D23 | K22: =Assumptions!E23 | L22: =SUM(H22:K22) | M22: =Assumptions!G23 | N22: =Assumptions!H23 | O22: =Assumptions!I23 | P22: =Assumptions!J23 | Q22: =SUM(M22:P22) | R22: =Assumptions!L23 | S22: =Assumptions!M23 | T22: =Assumptions!N23 | U22: =Assumptions!O23
B23: Shop Visits | C23: 223 | D23: 223 | E23: 223 | F23: 223 | G23: 893 | H23: 228 | I23: 228 | J23: =J21*J22 | K23: =K21*K22 | L23: =SUM(H23:K23) | M23: =M21*M22 | N23: =N21*N22 | O23: =O21*O22 | P23: =P21*P22 | Q23: =SUM(M23:P23) | R23: =R21*R22 | S23: =S21*S22 | T23: =T21*T22 | U23: =U21*U22
B25: Total EoP CFM56 Fleet | C25: 22928 | D25: 22856 | E25: 22784 | F25: 22713 | G25: 22713 | H25: 22616 | I25: 22606 | J25: =J13+J21 | K25: =K13+K21 | L25: =L13+L21 | M25: =M13+M21 | N25: =N13+N21 | O25: =O13+O21 | P25: =P13+P21 | Q25: =Q13+Q21 | ... U25: =U13+U21
B26: Total Shop Visits | C26: 588 | D26: 588 | E26: 588 | F26: 588 | G26: 2350 | H26: 600 | I26: 600 | J26: =J23+J15 | K26: =K23+K15 | L26: =SUM(H26:K26) | M26: =M23+M15 | N26: =N23+N15 | O26: =O23+O15 | P26: =P23+P15 | Q26: =SUM(M26:P26) | R26: =R23+R15 | S26: =S23+S15 | T26: =T23+T15 | U26: =U23+U15
B27: Modules per Shop Visit | C27: 3 | D27: 3 | E27: 3 | F27: 3 | G27: 3 | H27: 3 | I27: 3 | J27: =Assumptions!D28 | K27: =Assumptions!E28 | L27: =IFERROR(L28/L26,0) | M27: =Assumptions!G28 | N27: =Assumptions!H28 | O27: =Assumptions!I28 | P27: =Assumptions!J28 | Q27: =IFERROR(Q28/Q26,0) | R27: =Assumptions!L28 | S27: =Assumptions!M28 | T27: =Assumptions!N28 | U27: =Assumptions!O28
B28: Total Module Demand | C28: 1763 | D28: 1763 | E28: 1763 | F28: 1763 | G28: 7050 | H28: 1800 | I28: 1800 | J28: =J26*J27 | K28: =K26*K27 | L28: =SUM(H28:K28) | M28: =M26*M27 | N28: =N26*N27 | O28: =O26*O27 | P28: =P26*P27 | Q28: =SUM(M28:P28) | R28: =R26*R27 | S28: =S26*S27 | T28: =T26*T27 | U28: =U26*U27
A30: x | B30: SCI MRE Share
B31: SCI Owned Aircraft (EoP) | C31: 4 | D31: 37 | E31: 101 | F31: 130 | G31: 130 | H31: 200 | I31: 276 | J31: =Assumptions!D32 | K31: =Assumptions!E32 | L31: =K31 | M31: =Assumptions!G32 | N31: =Assumptions!H32 | O31: =Assumptions!I32 | P31: =Assumptions!J32 | Q31: =P31 | R31: =Assumptions!L32 | S31: =Assumptions!M32 | T31: =Assumptions!N32 | U31: =Assumptions!O32
B32: Engines per Aircraft | C32: 2 | D32: 2 | E32: 2 | F32: 2 | G32: 2 | H32: 2 | I32: 2 | J32: =Assumptions!D37 | K32: =Assumptions!E37 | L32: =Assumptions!F37 | M32: =Assumptions!G37 | N32: =Assumptions!H37 | O32: =Assumptions!I37 | P32: =Assumptions!J37 | Q32: =Assumptions!K37 | ... U32: =Assumptions!O37
B33: SCI Shop Visit Rate | C33: 0.05 | D33: 0.05 | E33: 0.05 | F33: 0.05 | G33: 0.2 | H33: 0.05 | I33: 0.05 | J33: =Assumptions!D39 | K33: =Assumptions!E39 | L33: =Assumptions!F39 | M33: =Assumptions!G39 | N33: =Assumptions!H39 | O33: =Assumptions!I39 | P33: =Assumptions!J39 | Q33: =Assumptions!K39 | ... U33: =Assumptions!O39
B34: SCI Shop Visits | C34: 0 | D34: 4 | E34: 10 | F34: 13 | G34: 27 | H34: 20 | I34: 28 | J34: =J31*J32*J33 | K34: =K31*K32*K33 | L34: =SUM(H34:K34) | M34: =M31*M32*M33 | N34: =N31*N32*N33 | O34: =O31*O32*O33 | P34: =P31*P32*P33 | Q34: =SUM(M34:P34) | R34: =R31*R32*R33 | S34: =S31*S32*S33 | T34: =T31*T32*T33 | U34: =U31*U32*U33
B35: SCI Module Demand | C35: 1 | D35: 11 | E35: 30 | F35: 39 | G35: 82 | H35: 60 | I35: 83 | J35: =J34*J27 | K35: =K34*K27 | L35: =SUM(H35:K35) | M35: =M34*M27 | N35: =N34*N27 | O35: =O34*O27 | P35: =P34*P27 | Q35: =SUM(M35:P35) | R35: =R34*R27 | S35: =S34*S27 | T35: =T34*T27 | U35: =U34*U27
A37: x | B37: MRO Demand
B38: Module Demand | J38: =J28 | K38: =K28 | L38: =L28 | M38: =M28 | N38: =N28 | O38: =O28 | P38: =P28 | Q38: =Q28 | ... U38: =U28
B39: FTAI Share of Module Demand | J39: =Assumptions!D44 | K39: =Assumptions!E44 | L39: =Assumptions!F44 | M39: =Assumptions!G44 | N39: =Assumptions!H44 | O39: =Assumptions!I44 | P39: =Assumptions!J44 | Q39: =Assumptions!K44 | ... U39: =Assumptions!O44
B40: MRO Modules | J40: =J38*J39 | K40: =K38*K39 | L40: =L38*L39 | M40: =M38*M39 | N40: =N38*N39 | O40: =O38*O39 | P40: =P38*P39 | Q40: =Q38*Q39 | ... U40: =U38*U39
B42: FTAI Modules Produced | C42: 138 | D42: 184 | E42: 207 | F42: 228 | G42: =SUM(C42:F42) | H42: 270 | I42: 296 | J42: =J40+J35 | K42: =K40+K35 | L42: =SUM(H42:K42) | M42: =M40+M35 | N42: =N40+N35 | O42: =O40+O35 | P42: =P40+P35 | Q42: =SUM(M42:P42) | R42: =R40+R35 | S42: =S40+S35 | T42: =T40+T35 | U42: =U40+U35
B43: y/y growth | H43: =H42/C42-1 | I43: =I42/D42-1 | J43: =J42/E42-1 | K43: =K42/F42-1 | L43: =L42/G42-1 | M43: =M42/H42-1 | N43: =N42/I42-1 | O43: =O42/J42-1 | ... Q43: =Q42/L42-1 | R43: =R42/Q42-1 | S43: =S42/R42-1 | T43: =T42/S42-1 | U43: =U42/T42-1
A45: x | B45: Aerospace Products Revenue
B46: CFM Annual Escalator | J46: =Assumptions!D49 | K46: =Assumptions!E49 | L46: =Assumptions!F49 | M46: =Assumptions!G49 | N46: =Assumptions!H49 | O46: =Assumptions!I49 | P46: =Assumptions!J49 | Q46: =Assumptions!K49 | ... U46: =Assumptions!O49
B47: FTAI Pass-Through (% of OEM escalator) | J47: =Assumptions!D54 | K47: =Assumptions!E54 | M47: =Assumptions!G54 | N47: =Assumptions!H54 | O47: =Assumptions!I54 | P47: =Assumptions!J54 | R47: =Assumptions!L54 | S47: =Assumptions!M54 | T47: =Assumptions!N54 | U47: =Assumptions!O54
B48: Revenue per Module Growth | J48: =J46*J47 | K48: =K46*K47 | M48: =M46*M47 | N48: =N46*N47 | O48: =O46*O47 | P48: =P46*P47 | R48: =R46*R47 | S48: =S46*S47 | T48: =T46*T47 | U48: =U46*U47
...

Sheet Assumptions
B1: FTAI Aviation
B2: Assumptions
D4: Q3-26 | E4: Q4-26 | F4: FY26 | G4: Q1-27 | H4: Q2-27 | I4: Q3-27 | J4: Q4-27 | K4: FY27 | L4: FY28 | M4: FY29 | N4: FY30 | O4: FY31
B6: Revenue Assumptions - CFM56 Fleet & Shop Visit Demand
B8: CFM56-7B Retirement Rate (% of BoP fleet) | D8: =CHOOSE(MATCH(DCF!$C$3, {"Bear","Base","Bull"}, 0),D9, D10,D11) | E8: =CHOOSE(MATCH(DCF!$C$3, {"Bear","Base","Bull"}, 0),E9, E10,E11) | F8: =CHOOSE(MATCH(DCF!$C$3, {"Bear","Base","Bull"}, 0),F9, F10,F11) | G8: =CHOOSE(MATCH(DCF!$C$3, {"Bear","Base","Bull"}, 0),G9, G10,G11) | H8: =CHOOSE(MATCH(DCF!$C$3, {"Bear","Base","Bull"}, 0),H9, H10,H11) | I8: =CHOOSE(MATCH(DCF!$C$3, {"Bear","Base","Bull"}, 0),I9, I10,I11) | J8: =CHOOSE(MATCH(DCF!$C$3, {"Bear","Base","Bull"}, 0),J9, J10,J11) | K8: =CHOOSE(MATCH(DCF!$C$3, {"Bear","Base","Bull"}, 0),K9, K10,K11) | ... O8: =CHOOSE(MATCH(DCF!$C$3, {"Bear","Base","Bull"}, 0),O9, O10,O11)
B9: Bear | D9: =1-(1-F9)^(1/4) | E9: =1-(1-F9)^(1/4) | F9: 0.015 | G9: =1-(1-K9)^(1/4) | H9: =1-(1-K9)^(1/4) | I9: =1-(1-K9)^(1/4) | J9: =1-(1-K9)^(1/4) | K9: 0.025 | L9: 0.025 | M9: 0.03 | N9: 0.03 | O9: 0.035
B10: Base | D10: =1-(1-F10)^(1/4) | E10: =1-(1-F10)^(1/4) | F10: 0.015 | G10: =1-(1-K10)^(1/4) | H10: =1-(1-K10)^(1/4) | I10: =1-(1-K10)^(1/4) | J10: =1-(1-K10)^(1/4) | K10: 0.02 | L10: 0.02 | M10: 0.025 | N10: 0.025 | O10: 0.03
B11: Bull | D11: =1-(1-F11)^(1/4) | E11: =1-(1-F11)^(1/4) | F11: =F10 | G11: =1-(1-K11)^(1/4) | H11: =1-(1-K11)^(1/4) | I11: =1-(1-K11)^(1/4) | J11: =1-(1-K11)^(1/4) | K11: =K10 | L11: =L10 | M11: =M10 | N11: =N10 | O11: =O10
B13: CFM56-5B Retirement Rate (% of BoP fleet) | D13: =CHOOSE(MATCH(DCF!$C$3, {"Bear","Base","Bull"}, 0),D14, D15,D16) | E13: =CHOOSE(MATCH(DCF!$C$3, {"Bear","Base","Bull"}, 0),E14, E15,E16) | F13: =CHOOSE(MATCH(DCF!$C$3, {"Bear","Base","Bull"}, 0),F14, F15,F16) | G13: =CHOOSE(MATCH(DCF!$C$3, {"Bear","Base","Bull"}, 0),G14, G15,G16) | H13: =CHOOSE(MATCH(DCF!$C$3, {"Bear","Base","Bull"}, 0),H14, H15,H16) | I13: =CHOOSE(MATCH(DCF!$C$3, {"Bear","Base","Bull"}, 0),I14, I15,I16) | J13: =CHOOSE(MATCH(DCF!$C$3, {"Bear","Base","Bull"}, 0),J14, J15,J16) | K13: =CHOOSE(MATCH(DCF!$C$3, {"Bear","Base","Bull"}, 0),K14, K15,K16) | ... O13: =CHOOSE(MATCH(DCF!$C$3, {"Bear","Base","Bull"}, 0),O14, O15,O16)
B14: Bear | D14: =1-(1-F14)^(1/4) | E14: =1-(1-F14)^(1/4) | F14: 0.02 | G14: =1-(1-K14)^(1/4) | H14: =1-(1-K14)^(1/4) | I14: =1-(1-K14)^(1/4) | J14: =1-(1-K14)^(1/4) | K14: 0.04 | L14: 0.04 | M14: 0.045 | N14: 0.045 | O14: 0.05
B15: Base | D15: =1-(1-F15)^(1/4) | E15: =1-(1-F15)^(1/4) | F15: 0.02 | G15: =1-(1-K15)^(1/4) | H15: =1-(1-K15)^(1/4) | I15: =1-(1-K15)^(1/4) | J15: =1-(1-K15)^(1/4) | K15: 0.025 | L15: 0.03 | M15: 0.035 | N15: 0.035 | O15: 0.04
B16: Bull | D16: =1-(1-F16)^(1/4) | E16: =1-(1-F16)^(1/4) | F16: =F15 | G16: =1-(1-K16)^(1/4) | H16: =1-(1-K16)^(1/4) | I16: =1-(1-K16)^(1/4) | J16: =1-(1-K16)^(1/4) | K16: =K15 | L16: =L15 | M16: =M15 | N16: =N15 | O16: =O15
B18: CFM56-7B Shop Visit Rate | D18: =CHOOSE(MATCH(DCF!$C$3, {"Bear","Base","Bull"}, 0),D19, D20,D21) | E18: =CHOOSE(MATCH(DCF!$C$3, {"Bear","Base","Bull"}, 0),E19, E20,E21) | F18: =CHOOSE(MATCH(DCF!$C$3, {"Bear","Base","Bull"}, 0),F19, F20,F21) | G18: =CHOOSE(MATCH(DCF!$C$3, {"Bear","Base","Bull"}, 0),G19, G20,G21) | H18: =CHOOSE(MATCH(DCF!$C$3, {"Bear","Base","Bull"}, 0),H19, H20,H21) | I18: =CHOOSE(MATCH(DCF!$C$3, {"Bear","Base","Bull"}, 0),I19, I20,I21) | J18: =CHOOSE(MATCH(DCF!$C$3, {"Bear","Base","Bull"}, 0),J19, J20,J21) | K18: =CHOOSE(MATCH(DCF!$C$3, {"Bear","Base","Bull"}, 0),K19, K20,K21) | ... O18: =CHOOSE(MATCH(DCF!$C$3, {"Bear","Base","Bull"}, 0),O19, O20,O21)
B19: Bear | D19: =F19/4 | E19: =F19/4 | F19: ='SV Analysis'!E33 | G19: =K19/4 | H19: =K19/4 | I19: =K19/4 | J19: =K19/4 | K19: ='SV Analysis'!F33 | L19: ='SV Analysis'!G33 | M19: ='SV Analysis'!H33 | N19: ='SV Analysis'!I33 | O19: ='SV Analysis'!J33
B20: Base | D20: =F20/4 | E20: =F20/4 | F20: ='SV Analysis'!E34 | G20: =K20/4 | H20: =K20/4 | I20: =K20/4 | J20: =K20/4 | K20: ='SV Analysis'!F34 | L20: ='SV Analysis'!G34 | M20: ='SV Analysis'!H34 | N20: ='SV Analysis'!I34 | O20: ='SV Analysis'!J34
B21: Bull | D21: =F21/4 | E21: =F21/4 | F21: =F20 | G21: =K21/4 | H21: =K21/4 | I21: =K21/4 | J21: =K21/4 | K21: =K20 | L21: =L20 | M21: =M20 | N21: =N20 | O21: =O20
B23: CFM56-5B Shop Visit Rate | D23: =CHOOSE(MATCH(DCF!$C$3, {"Bear","Base","Bull"}, 0),D24, D25,D26) | E23: =CHOOSE(MATCH(DCF!$C$3, {"Bear","Base","Bull"}, 0),E24, E25,E26) | F23: =CHOOSE(MATCH(DCF!$C$3, {"Bear","Base","Bull"}, 0),F24, F25,F26) | G23: =CHOOSE(MATCH(DCF!$C$3, {"Bear","Base","Bull"}, 0),G24, G25,G26) | H23: =CHOOSE(MATCH(DCF!$C$3, {"Bear","Base","Bull"}, 0),H24, H25,H26) | I23: =CHOOSE(MATCH(DCF!$C$3, {"Bear","Base","Bull"}, 0),I24, I25,I26) | J23: =CHOOSE(MATCH(DCF!$C$3, {"Bear","Base","Bull"}, 0),J24, J25,J26) | K23: =CHOOSE(MATCH(DCF!$C$3, {"Bear","Base","Bull"}, 0),K24, K25,K26) | ... O23: =CHOOSE(MATCH(DCF!$C$3, {"Bear","Base","Bull"}, 0),O24, O25,O26)
B24: Bear | D24: =F24/4 | E24: =F24/4 | F24: =F19-0.005 | G24: =K24/4 | H24: =K24/4 | I24: =K24/4 | J24: =K24/4 | K24: =K19-0.005 | L24: =L19-0.005 | M24: =M19-0.005 | N24: =N19-0.005 | O24: =O19-0.005
B25: Base | D25: =F25/4 | E25: =F25/4 | F25: =F20-0.005 | G25: =K25/4 | H25: =K25/4 | I25: =K25/4 | J25: =K25/4 | K25: =K20-0.005 | L25: =L20-0.005 | M25: =M20-0.005 | N25: =N20-0.005 | O25: =O20-0.005
B26: Bull | D26: =F26/4 | E26: =F26/4 | F26: =F21-0.005 | G26: =K26/4 | H26: =K26/4 | I26: =K26/4 | J26: =K26/4 | K26: =K21-0.005 | L26: =L21-0.005 | M26: =M21-0.005 | N26: =N21-0.005 | O26: =O21-0.005
B28: Modules per Shop Visit | D28: 3 | E28: 3 | F28: 3 | G28: 3 | H28: 3 | I28: 3 | J28: 3 | K28: 3 | L28: 3 | M28: 3 | N28: 3 | O28: 3
B30: Revenue Assumptions - SCI Captive Demand
B32: SCI Owned Aircraft | D32: =CHOOSE(MATCH(DCF!$C$3, {"Bear","Base","Bull"}, 0),D33, D34,D35) | E32: =CHOOSE(MATCH(DCF!$C$3, {"Bear","Base","Bull"}, 0),E33, E34,E35) | F32: =CHOOSE(MATCH(DCF!$C$3, {"Bear","Base","Bull"}, 0),F33, F34,F35) | G32: =CHOOSE(MATCH(DCF!$C$3, {"Bear","Base","Bull"}, 0),G33, G34,G35) | H32: =CHOOSE(MATCH(DCF!$C$3, {"Bear","Base","Bull"}, 0),H33, H34,H35) | I32: =CHOOSE(MATCH(DCF!$C$3, {"Bear","Base","Bull"}, 0),I33, I34,I35) | J32: =CHOOSE(MATCH(DCF!$C$3, {"Bear","Base","Bull"}, 0),J33, J34,J35) | K32: =CHOOSE(MATCH(DCF!$C$3, {"Bear","Base","Bull"}, 0),K33, K34,K35) | ... O32: =CHOOSE(MATCH(DCF!$C$3, {"Bear","Base","Bull"}, 0),O33, O34,O35)
B33: Bear | D33: =D34 | E33: =E34 | F33: =F34 | G33: 325 | H33: 335 | I33: 345 | J33: 350 | K33: =J33 | L33: 375 | M33: 400 | N33: 400 | O33: 400
B34: Base | D34: 300 | E34: 316 | F34: =E34 | G34: 350 | H34: 385 | I34: 420 | J34: 450 | K34: =J34 | L34: 550 | M34: 650 | N34: 700 | O34: 750
B35: Bull | D35: =D34 | E35: =E34 | F35: =F34 | G35: =G34 | H35: =H34 | I35: =I34 | J35: =J34 | K35: =J35 | L35: =L34 | M35: =M34 | N35: =N34 | O35: =O34
B37: Engines per Aircraft | D37: 2 | E37: 2 | F37: 2 | G37: 2 | H37: 2 | I37: 2 | J37: 2 | K37: 2 | L37: 2 | M37: 2 | N37: 2 | O37: 2
B39: SCI Shop Visit Rate | D39: =CHOOSE(MATCH(DCF!$C$3, {"Bear","Base","Bull"}, 0),D40, D41,D42) | E39: =CHOOSE(MATCH(DCF!$C$3, {"Bear","Base","Bull"}, 0),E40, E41,E42) | F39: =CHOOSE(MATCH(DCF!$C$3, {"Bear","Base","Bull"}, 0),F40, F41,F42) | G39: =CHOOSE(MATCH(DCF!$C$3, {"Bear","Base","Bull"}, 0),G40, G41,G42) | H39: =CHOOSE(MATCH(DCF!$C$3, {"Bear","Base","Bull"}, 0),H40, H41,H42) | I39: =CHOOSE(MATCH(DCF!$C$3, {"Bear","Base","Bull"}, 0),I40, I41,I42) | J39: =CHOOSE(MATCH(DCF!$C$3, {"Bear","Base","Bull"}, 0),J40, J41,J42) | K39: =CHOOSE(MATCH(DCF!$C$3, {"Bear","Base","Bull"}, 0),K40, K41,K42) | ... O39: =CHOOSE(MATCH(DCF!$C$3, {"Bear","Base","Bull"}, 0),O40, O41,O42)
B40: Bear | D40: =D41 | E40: =E41 | F40: =F41 | G40: =G41 | H40: =H41 | I40: =I41 | J40: =J41 | K40: =K41 | ... O40: =O41
B41: Base | D41: 0.05 | E41: 0.05 | F41: 0.2 | G41: 0.05 | H41: 0.05 | I41: 0.05 | J41: 0.05 | K41: 0.2 | L41: 0.2 | M41: 0.2 | N41: 0.2 | O41: 0.2
B42: Bull | D42: =D41 | E42: =E41 | F42: =F41 | G42: =G41 | H42: =H41 | I42: =I41 | J42: =J41 | K42: =K41 | ... O42: =O41
B44: FTAI Share of MRO (%) | D44: =CHOOSE(MATCH(DCF!$C$3, {"Bear","Base","Bull"}, 0),D45, D46,D47) | E44: =CHOOSE(MATCH(DCF!$C$3, {"Bear","Base","Bull"}, 0),E45, E46,E47) | F44: =CHOOSE(MATCH(DCF!$C$3, {"Bear","Base","Bull"}, 0),F45, F46,F47) | G44: =CHOOSE(MATCH(DCF!$C$3, {"Bear","Base","Bull"}, 0),G45, G46,G47) | H44: =CHOOSE(MATCH(DCF!$C$3, {"Bear","Base","Bull"}, 0),H45, H46,H47) | I44: =CHOOSE(MATCH(DCF!$C$3, {"Bear","Base","Bull"}, 0),I45, I46,I47) | J44: =CHOOSE(MATCH(DCF!$C$3, {"Bear","Base","Bull"}, 0),J45, J46,J47) | K44: =CHOOSE(MATCH(DCF!$C$3, {"Bear","Base","Bull"}, 0),K45, K46,K47) | ... O44: =CHOOSE(MATCH(DCF!$C$3, {"Bear","Base","Bull"}, 0),O45, O46,O47)
B45: Bear | D45: =D46 | E45: =E46 | F45: =AVERAGE(D45:E45) | G45: 0.135 | H45: 0.14 | I45: 0.145 | J45: 0.15 | K45: =AVERAGE(G45:J45) | L45: 0.15 | M45: 0.15 | N45: 0.15 | O45: 0.15
B46: Base | D46: 0.119 | E46: 0.13 | F46: =AVERAGE(D46:E46) | G46: 0.15 | H46: 0.163 | I46: 0.175 | J46: 0.186 | K46: =AVERAGE(G46:J46) | L46: 0.19 | M46: 0.195 | N46: 0.2 | O46: 0.2
B47: Bull | D47: =D46 | E47: =E46 | F47: =AVERAGE(D47:E47) | G47: 0.155 | H47: 0.17 | I47: 0.185 | J47: 0.2 | K47: =AVERAGE(G47:J47) | L47: 0.21 | M47: 0.23 | N47: 0.24 | O47: 0.25
B49: OEM Price Escalator | D49: =CHOOSE(MATCH(DCF!$C$3, {"Bear","Base","Bull"}, 0),D50, D51,D52) | E49: =CHOOSE(MATCH(DCF!$C$3, {"Bear","Base","Bull"}, 0),E50, E51,E52) | F49: =CHOOSE(MATCH(DCF!$C$3, {"Bear","Base","Bull"}, 0),F50, F51,F52) | G49: =CHOOSE(MATCH(DCF!$C$3, {"Bear","Base","Bull"}, 0),G50, G51,G52) | H49: =CHOOSE(MATCH(DCF!$C$3, {"Bear","Base","Bull"}, 0),H50, H51,H52) | I49: =CHOOSE(MATCH(DCF!$C$3, {"Bear","Base","Bull"}, 0),I50, I51,I52) | J49: =CHOOSE(MATCH(DCF!$C$3, {"Bear","Base","Bull"}, 0),J50, J51,J52) | K49: =CHOOSE(MATCH(DCF!$C$3, {"Bear","Base","Bull"}, 0),K50, K51,K52) | ... O49: =CHOOSE(MATCH(DCF!$C$3, {"Bear","Base","Bull"}, 0),O50, O51,O52)
B50: Bear | D50: 0.07 | E50: 0 | F50: 0.07 | G50: 0 | H50: 0 | I50: 0.07 | J50: 0 | K50: 0.07 | L50: =L51-0.02 | M50: =M51-0.02 | N50: =N51-0.02 | O50: =O51-0.02
B51: Base | D51: 0.07 | E51: 0 | F51: 0.07 | G51: 0.065 | H51: 0 | I51: 0.07 | J51: 0 | K51: 0.07 | L51: 0.07 | M51: 0.07 | N51: 0.07 | O51: 0.07
B52: Bull | D52: =D51 | E52: =E51 | F52: =F51 | G52: =G51 | H52: =H51 | I52: =I51 | J52: =J51 | K52: =K51 | ... O52: =O51
B54: FTAI Pass-Through | D54: =CHOOSE(MATCH(DCF!$C$3, {"Bear","Base","Bull"}, 0),D55, D56,D57) | E54: =CHOOSE(MATCH(DCF!$C$3, {"Bear","Base","Bull"}, 0),E55, E56,E57) | F54: =CHOOSE(MATCH(DCF!$C$3, {"Bear","Base","Bull"}, 0),F55, F56,F57) | G54: =CHOOSE(MATCH(DCF!$C$3, {"Bear","Base","Bull"}, 0),G55, G56,G57) | H54: =CHOOSE(MATCH(DCF!$C$3, {"Bear","Base","Bull"}, 0),H55, H56,H57) | I54: =CHOOSE(MATCH(DCF!$C$3, {"Bear","Base","Bull"}, 0),I55, I56,I57) | J54: =CHOOSE(MATCH(DCF!$C$3, {"Bear","Base","Bull"}, 0),J55, J56,J57) | K54: =CHOOSE(MATCH(DCF!$C$3, {"Bear","Base","Bull"}, 0),K55, K56,K57) | ... O54: =CHOOSE(MATCH(DCF!$C$3, {"Bear","Base","Bull"}, 0),O55, O56,O57)
...

Sheet Data

Sheet CFM56 Data
B1: FTAI Aviation
B2: CFM56 Data
B4: OEM CFM56 shop visits (-5B/-7B)
D5: 2025 | E5: 2026 | F5: 2027 | G5: 2028 | H5: 2029 | I5: 2030 | J5: 2031 | K5: Source
B6: Central | D6: 2350 | E6: 2400 | F6: 2400 | G6: 2350 | H6: 2250 | I6: 2150 | J6: 2085 | K6: C01, C02
B7: Low | D7: 2300 | E7: 2400 | F7: 2400 | G7: 2300 | K7: C02
B8: High | D8: 2400 | E8: 2400 | F8: 2400 | G8: 2400 | K8: C01, C02
B10: Fleet counts
C11: Scope | D11: Engines | E11: Year | K11: Source
B12: Safran | C12: -5B/-7B, incl. stored | D12: 23000 | E12: 2024 | K12: C03
B13: Safran | C13: -5B/-7B | D13: 22800 | E13: 2025 | K13: K15
B14: MTU | C14: -7B | D14: 13000 | E14: 2024 | K14: P02
B15: MTU | C15: -5B | D15: 7000 | E15: 2024 | K15: P02
B16: GE | C16: Installed | D16: 19000 | E16: 2026 | K16: P01
B18: Fleet by completed shop visits
D19: 0 | E19: 1 | F19: 2+ | K19: Source
B20: 2024 actual | D20: 0.4 | E20: 0.29 | F20: 0.31 | K20: C03
B21: 2028 OEM projection | D21: 0.26 | E21: 0.31 | F21: 0.43 | K21: C03
B23: Cohort roll-forward (central)
D24: 2025 | E24: 2026 | F24: 2027 | G24: 2028 | H24: 2029 | I24: 2030 | K24: Source
B25: First visits | D25: 975.8292 | E25: 912.14652 | F25: 844.50639 | G25: 763.04959 | H25: 676.20212 | I25: 598.30441 | K25: Cohort Forecast
B26: Second visits | D26: 842.38455 | E26: 890.6853 | F26: 914.28543 | G26: 908.12258 | H26: 874.08453 | I26: 832.09451 | K26: Cohort Forecast
B27: Third+ visits | D27: 531.78625 | E27: 597.16818 | F27: 641.20819 | G27: 678.82784 | H27: 699.71335 | I27: 719.60109 | K27: Cohort Forecast
B28: Repeat-visit share | D28: 0.58475353 | E28: 0.61993895 | F28: 0.64812234 | G28: 0.67529805 | H28: 0.69946573 | I28: 0.72171888 | K28: Cohort Forecast
B29: Broader-work share | D29: 0.48203453 | E29: 0.49209662 | F29: 0.50012581 | G29: 0.50746803 | H29: 0.51371463 | I29: 0.51913179 | K29: Cohort Forecast
B30: Stock: 2+ prior visits | D30: 0.33895981 | E30: 0.36987276 | F30: 0.39502433 | G30: 0.42233464 | H30: 0.44844219 | I30: 0.47526972 | K30: Cohort Forecast
B31: Stock: 0 prior visits | D31: 0.36301791 | E31: 0.32850426 | F31: 0.30110204 | G31: 0.27520982 | H31: 0.25269449 | I31: 0.23190294 | K31: Cohort Forecast
B33: Engine shop-visit history: completed intervals (scraped)
B34: ESN | C34: Model | D34: From | E34: To | F34: Scope (to) | G34: Years | H34: Cycles | I34: Major | K34: Source
B35: 877356 | C35: CFM56-7B27 | D35: 39305 | E35: 41817 | F35: Not stated | G35: =(E35-D35)/365.25 | I35: 1 | K35: D042/D043
B36: 877356 | C36: CFM56-7B27 | D36: 41817 | E36: 43917 | F36: Not stated | G36: =(E36-D36)/365.25 | I36: 1 | K36: D043/D044
B37: 888804 | C37: CFM56-7B27 | D37: 42486 | E37: 44617 | F37: Not stated | G37: =(E37-D37)/365.25 | I37: 1 | K37: D040/D041
B38: 891647 | C38: CFM56-7B24 | D38: 40287 | E38: 40617 | F38: Oil leak repair | G38: =(E38-D38)/365.25 | I38: 0 | K38: D045/D046
B39: 891647 | C39: CFM56-7B24 | D39: 40617 | E39: 42331 | F39: Perf. restoration | G39: =(E39-D39)/365.25 | I39: 1 | K39: D046/D047
B40: 890669 | C40: CFM56-7B24 | D40: 40236 | E40: 41856 | F40: Perf. restoration | G40: =(E40-D40)/365.25 | I40: 1 | K40: D048/D049
B41: 890669 | C41: CFM56-7B24 | D41: 41856 | E41: 42912 | F41: Perf. restoration | G41: =(E41-D41)/365.25 | I41: 1 | K41: D049/D050
B42: 889728 | C42: CFM56-7B22 | D42: 39630 | E42: 41456 | F42: Not stated | G42: =(E42-D42)/365.25 | I42: 1 | K42: D024/D025
B43: 894206 | C43: CFM56-7B24 | D43: 41239 | E43: 42114 | F43: Repair | G43: =(E43-D43)/365.25 | H43: 4649 | I43: 0 | K43: E02
B44: 894206 | C44: CFM56-7B24 | D44: 42114 | E44: 42555 | F44: Repair | G44: =(E44-D44)/365.25 | H44: 2821 | I44: 0 | K44: E02
B45: 894206 | C45: CFM56-7B24 | D45: 42555 | E45: 44033 | F45: Overhaul | G45: =(E45-D45)/365.25 | H45: 5018 | I45: 1 | K45: E02
...

Sheet SV Analysis
B1: FTAI Aviation
B2: Shop Visit Analysis
B4: Engine-level evidence (scraped records)
D5: All visits | E5: Major visits | F5: Time on wing | G5: Utilization -7B | H5: Utilization -5B
B6: Observations | D6: =COUNT('CFM56 Data'!G35:G48) | E6: =COUNT('CFM56 Data'!G52:G60) | F6: =COUNT('CFM56 Data'!G64:G67) | G6: =COUNTIF('CFM56 Data'!C71:C221,"CFM56-7B") | H6: =COUNTIF('CFM56 Data'!C71:C221,"CFM56-5B")
B7: Median years between visits / on wing | D7: =MEDIAN('CFM56 Data'!G35:G48) | E7: =MEDIAN('CFM56 Data'!G52:G60) | F7: =MEDIAN('CFM56 Data'!G64:G67)
B8: Average years | D8: =AVERAGE('CFM56 Data'!G35:G48) | E8: =AVERAGE('CFM56 Data'!G52:G60) | F8: =AVERAGE('CFM56 Data'!G64:G67)
B9: Median cycles between visits / on wing | D9: =MEDIAN('CFM56 Data'!H35:H48) | E9: =MEDIAN('CFM56 Data'!H52:H60) | F9: =MEDIAN('CFM56 Data'!H64:H67)
B10: Median cycles / year | F10: =MEDIAN('CFM56 Data'!H64:H67)/MEDIAN('CFM56 Data'!G64:G67) | G10: {=MEDIAN(IF('CFM56 Data'!C71:C221="CFM56-7B",'CFM56 Data'!J71:J221))} | H10: {=MEDIAN(IF('CFM56 Data'!C71:C221="CFM56-5B",'CFM56 Data'!J71:J221))}
B11: Implied annual shop-visit probability (1 / median years) | D11: =1/D7 | E11: =1/E7 | F11: =1/F7
B13: Shop visits by case
D14: FY25A | E14: FY26E | F14: FY27E | G14: FY28E | H14: FY29E | I14: FY30E | J14: FY31E
B15: Base | D15: ='CFM56 Data'!D6 | E15: ='CFM56 Data'!E6 | F15: ='CFM56 Data'!F6 | G15: ='CFM56 Data'!G6 | H15: ='CFM56 Data'!H6 | I15: ='CFM56 Data'!I6 | J15: ='CFM56 Data'!J6
B16: Bull | D16: =D15 | E16: =E15 | F16: 2550 | G16: 2500 | H16: 2400 | I16: 2300 | J16: 2200
B17: Bear | D17: =D15 | E17: =E15 | F17: 2300 | G17: 2300 | H17: =G17*0.94 | I17: =H17*0.94 | J17: =I17*0.94
B19: Year-end fleet by case (RPM basis)
D20: FY25A | E20: FY26E | F20: FY27E | G20: FY28E | H20: FY29E | I20: FY30E | J20: FY31E
B21: Bear -7B | D21: =RPM!$G$13 | E21: =D21*(1-Assumptions!F9) | F21: =E21*(1-Assumptions!K9) | G21: =F21*(1-Assumptions!L9) | H21: =G21*(1-Assumptions!M9) | I21: =H21*(1-Assumptions!N9) | J21: =I21*(1-Assumptions!O9)
B22: Bear -5B | D22: =RPM!$G$21 | E22: =D22*(1-Assumptions!F14) | F22: =E22*(1-Assumptions!K14) | G22: =F22*(1-Assumptions!L14) | H22: =G22*(1-Assumptions!M14) | I22: =H22*(1-Assumptions!N14) | J22: =I22*(1-Assumptions!O14)
B23: Bear total | D23: =D21+D22 | E23: =E21+E22 | F23: =F21+F22 | G23: =G21+G22 | H23: =H21+H22 | I23: =I21+I22 | J23: =J21+J22
B24: Base -7B | D24: =RPM!$G$13 | E24: =D24*(1-Assumptions!F10) | F24: =E24*(1-Assumptions!K10) | G24: =F24*(1-Assumptions!L10) | H24: =G24*(1-Assumptions!M10) | I24: =H24*(1-Assumptions!N10) | J24: =I24*(1-Assumptions!O10)
B25: Base -5B | D25: =RPM!$G$21 | E25: =D25*(1-Assumptions!F15) | F25: =E25*(1-Assumptions!K15) | G25: =F25*(1-Assumptions!L15) | H25: =G25*(1-Assumptions!M15) | I25: =H25*(1-Assumptions!N15) | J25: =I25*(1-Assumptions!O15)
B26: Base total | D26: =D24+D25 | E26: =E24+E25 | F26: =F24+F25 | G26: =G24+G25 | H26: =H24+H25 | I26: =I24+I25 | J26: =J24+J25
B27: Bull -7B | D27: =RPM!$G$13 | E27: =D27*(1-Assumptions!F11) | F27: =E27*(1-Assumptions!K11) | G27: =F27*(1-Assumptions!L11) | H27: =G27*(1-Assumptions!M11) | I27: =H27*(1-Assumptions!N11) | J27: =I27*(1-Assumptions!O11)
B28: Bull -5B | D28: =RPM!$G$21 | E28: =D28*(1-Assumptions!F16) | F28: =E28*(1-Assumptions!K16) | G28: =F28*(1-Assumptions!L16) | H28: =G28*(1-Assumptions!M16) | I28: =H28*(1-Assumptions!N16) | J28: =I28*(1-Assumptions!O16)
B29: Bull total | D29: =D27+D28 | E29: =E27+E28 | F29: =F27+F28 | G29: =G27+G28 | H29: =H27+H28 | I29: =I27+I28 | J29: =J27+J28
B31: Shop-visit rate
D32: FY25A | E32: FY26E | F32: FY27E | G32: FY28E | H32: FY29E | I32: FY30E | J32: FY31E
B33: Bear (visits / RPM fleet) | D33: =D17/D23 | E33: =E17/E23 | F33: =F17/F23 | G33: =G17/G23 | H33: =H17/H23 | I33: =I17/I23 | J33: =J17/J23
B34: Base (visits / RPM fleet) | D34: =D15/D26 | E34: =E15/E26 | F34: =F15/F26 | G34: =G15/G26 | H34: =H15/H26 | I34: =I15/I26 | J34: =J15/J26
B35: Bull (visits / RPM fleet) | D35: =D16/D29 | E35: =E16/E29 | F35: =F16/F29 | G35: =G16/G29 | H35: =H16/H29 | I35: =I16/I29 | J35: =J16/J29
B36: Base on GE installed fleet (19,000) | D36: =D15/'CFM56 Data'!D16 | E36: =E15/'CFM56 Data'!D16 | F36: =F15/'CFM56 Data'!D16 | G36: =G15/'CFM56 Data'!D16 | H36: =H15/'CFM56 Data'!D16 | I36: =I15/'CFM56 Data'!D16 | J36: =J15/'CFM56 Data'!D16
B37: Engine records: major visits | D37: =$E$11 | E37: =$E$11 | F37: =$E$11 | G37: =$E$11 | H37: =$E$11 | I37: =$E$11 | J37: =$E$11
B38: Engine records: all visits | D38: =$D$11 | E38: =$D$11 | F38: =$D$11 | G38: =$D$11 | H38: =$D$11 | I38: =$D$11 | J38: =$D$11
B40: Fleet visit history (cohort)
D41: FY25A | E41: FY26E | F41: FY27E | G41: FY28E | H41: FY29E | I41: FY30E
B42: Repeat-visit share | D42: ='CFM56 Data'!D28 | E42: ='CFM56 Data'!E28 | F42: ='CFM56 Data'!F28 | G42: ='CFM56 Data'!G28 | H42: ='CFM56 Data'!H28 | I42: ='CFM56 Data'!I28
B43: Broader-work share | D43: ='CFM56 Data'!D29 | E43: ='CFM56 Data'!E29 | F43: ='CFM56 Data'!F29 | G43: ='CFM56 Data'!G29 | H43: ='CFM56 Data'!H29 | I43: ='CFM56 Data'!I29
B44: Stock: 2+ prior visits | D44: ='CFM56 Data'!D30 | E44: ='CFM56 Data'!E30 | F44: ='CFM56 Data'!F30 | G44: ='CFM56 Data'!G30 | H44: ='CFM56 Data'!H30 | I44: ='CFM56 Data'!I30
B45: Stock: 0 prior visits | D45: ='CFM56 Data'!D31 | E45: ='CFM56 Data'!E31 | F45: ='CFM56 Data'!F31 | G45: ='CFM56 Data'!G31 | H45: ='CFM56 Data'!H31 | I45: ='CFM56 Data'!I31

Sheet Pricing Data
B1: FTAI Aviation
B2: CFM56 Repair Pricing
B4: Summary
B5: Family | C5: Period | D5: Matched | E5: Median change | F5: Average change | G5: Higher | H5: Lower | I5: Unchanged
B6: CFM56-5B | C6: 2024-2025 | D6: =COUNTIFS($B$31:$B$3434,"CFM56-5B",$C$31:$C$3434,"2024-2025") | E6: {=MEDIAN(IF(($B$31:$B$3434="CFM56-5B")*($C$31:$C$3434="2024-2025"),$J$31:$J$3434))} | F6: =AVERAGEIFS($J$31:$J$3434,$B$31:$B$3434,"CFM56-5B",$C$31:$C$3434,"2024-2025") | G6: =COUNTIFS($B$31:$B$3434,"CFM56-5B",$C$31:$C$3434,"2024-2025",$J$31:$J$3434,">0") | H6: =COUNTIFS($B$31:$B$3434,"CFM56-5B",$C$31:$C$3434,"2024-2025",$J$31:$J$3434,"<0") | I6: =COUNTIFS($B$31:$B$3434,"CFM56-5B",$C$31:$C$3434,"2024-2025",$J$31:$J$3434,0)
B7: CFM56-5B | C7: 2025-2026 | D7: =COUNTIFS($B$31:$B$3434,"CFM56-5B",$C$31:$C$3434,"2025-2026") | E7: {=MEDIAN(IF(($B$31:$B$3434="CFM56-5B")*($C$31:$C$3434="2025-2026"),$J$31:$J$3434))} | F7: =AVERAGEIFS($J$31:$J$3434,$B$31:$B$3434,"CFM56-5B",$C$31:$C$3434,"2025-2026") | G7: =COUNTIFS($B$31:$B$3434,"CFM56-5B",$C$31:$C$3434,"2025-2026",$J$31:$J$3434,">0") | H7: =COUNTIFS($B$31:$B$3434,"CFM56-5B",$C$31:$C$3434,"2025-2026",$J$31:$J$3434,"<0") | I7: =COUNTIFS($B$31:$B$3434,"CFM56-5B",$C$31:$C$3434,"2025-2026",$J$31:$J$3434,0)
B8: CFM56-7B | C8: 2025-2026 | D8: =COUNTIFS($B$31:$B$3434,"CFM56-7B",$C$31:$C$3434,"2025-2026") | E8: {=MEDIAN(IF(($B$31:$B$3434="CFM56-7B")*($C$31:$C$3434="2025-2026"),$J$31:$J$3434))} | F8: =AVERAGEIFS($J$31:$J$3434,$B$31:$B$3434,"CFM56-7B",$C$31:$C$3434,"2025-2026") | G8: =COUNTIFS($B$31:$B$3434,"CFM56-7B",$C$31:$C$3434,"2025-2026",$J$31:$J$3434,">0") | H8: =COUNTIFS($B$31:$B$3434,"CFM56-7B",$C$31:$C$3434,"2025-2026",$J$31:$J$3434,"<0") | I8: =COUNTIFS($B$31:$B$3434,"CFM56-7B",$C$31:$C$3434,"2025-2026",$J$31:$J$3434,0)
B10: Median change by part category
B11: Part category | D11: CFM56-5B | E11: CFM56-7B | F11: Packages
