Workbook

Sheet DM Summary
B2: Discovery Mode Efficacy Summary | C2: Value | D2: n | H2: Notes
B4: Evidence from 70 first-hand artist reports on r/musicmarketing (Oct 2020 - Oct 2026) and 35 Spotify for Artists screenshots. Green = link to a data tab; the tabs that follow hold the inputs and formulas.
B6: 1. Key Numbers
B7: Median Spotify-reported lift, campaigns Aug 2023 - Nov 2024 | C7: ='DM Campaign Lifts'!$H$15 -> 4.0591695 | D7: ='DM Campaign Lifts'!$I$15 -> 4 | H7: Radio, Autoplay and Mixes streams during the campaign vs the 28 days before, as reported in the Spotify for Artists campaign screenshot.
B8: Median Spotify-reported lift, campaigns Jan 2025 - Jul 2026 | C8: ='DM Campaign Lifts'!$H$16 -> 0.77991651 | D8: ='DM Campaign Lifts'!$I$16 -> 3 | H8: Same measure, later campaigns: a fraction of the 2023-24 lifts even on Spotify's own flattering metric.
B9: Median saves + adds per Discovery Mode listener | C9: ='DM Engagement'!$F$20 -> 0.012422383 | D9: =COUNT('DM Engagement'!$F$7:$F$14) -> 8 | H9: (Saves + playlist adds) / campaign listeners, from the campaign reports.
B10: Median saves per listener, artists' overall audience | C10: ='DM Engagement'!$F$21 -> 0.19854954 | D10: =COUNT('DM Engagement'!$F$15:$F$18) -> 4 | H10: Saves / listeners from four artists' 12-month dashboards. Different artists and definitions, so read as orders of magnitude.
B11: Share of first-hand reports that went up, artists under 10k listeners | C11: ='DM Artist Pairs'!$G$35 -> 1 | D11: ='DM Artist Pairs'!$F$35 -> 8 | H11: Hand-coded set of 70 first-hand reports; 26 stated an audience size.
B12: Share of first-hand reports that went up, artists with 10k+ listeners | C12: ='DM Artist Pairs'!$G$38 -> 0.38888889 | D12: ='DM Artist Pairs'!$F$38 -> 18 | H12: Above 10k listeners the reports are a coin flip.
B13: First-hand reports saying Discover Weekly / algorithmic streams fell | C13: ='DM Corpus'!$C$16 -> 12 | D13: ='DM Corpus'!$C$11 -> 70 | H13: n = all first-hand reports coded.
B14: Median Discovery Mode share of monthly streams, established artists | C14: ='DM Corpus'!$C$59 -> 0.075 | D14: ='DM Corpus'!$D$59 -> 8 | H14: Established artists (500k+ monthly streams) report 3-5%; catalog-heavy artists up to a third.
B16: 2. The Argument
B17: Mechanism first: a relative boost inside a fixed pool | H17: Discovery Mode is a relative boost inside a fixed pool of Radio and Autoplay slots. Every new enrollee dilutes the others, so the per-track payoff must fall as enrollment grows. Symptoms: in one Dec 2023 campaign 4 of 6 enrolled songs got zero Discovery Mode streams; in 2025 one artist found 7 of 12 enrolled songs at 0-100 radio streams while still enrolled.
B18: Spotify's own lift metric is shrinking | H18: Even on the flattering Radio/Autoplay-only measure, the 2025-26 campaign reports show a fraction of the 2023-24 lifts (chart 1 below; DM Campaign Lifts tab).
B19: The lift is hollow | H19: The one artist who checked total streams found Spotify claiming +55% while the song's total fell. Discovery Mode listeners keep the song about 1% of the time versus roughly 20% for an artist's normal audience, and the latest campaign in the set has the lowest engagement of all (chart 2 below; DM Engagement tab).
B20: Enrollment has become defensive | H20: Artists who stay say they re-enrolled out of fear or 'would not take it out again'; opting out halved one song's daily streams. For a new artist the pitch is now 'give up 30% to avoid losing ground', not 'give up 30% to grow' (DM On-Off Cases tab).
B21: It still works only where the royalties barely matter | H21: Every report from artists under 10k listeners went up; above 10k it is a coin flip (chart 3 below; DM Artist Pairs tab). The addressable pool for the margin lever is the long tail.
B23: 3. Where It Breaks
B24: Time trend in the artist-reported pairs | H24: The 18 artist-reported before/after pairs trend toward 'Up' over time (2023: 1 up / 5 down; 2025-26: 3 up / 0 down). The defensible reading is mix shift: the 2023 losers were 30k-80k-listener artists in the early rollout, the later winners are mostly small. State that; do not rely on the pairs for the time claim.
B25: Sample size and selection | H25: Sample sizes are tiny (7 campaign lifts, 18 pairs) and self-selected from one subreddit. The 2026 platform-wide drops some artists report could be an algorithm change unrelated to the program.
B27: 4. Charts
B84: Colour key: blue = hard-coded input read from the post or screenshot (notes give the post id); black = formula; green = link to another tab.

Sheet DM Campaign Lifts
B2: Discovery Mode Campaign Reports | C2: Month | D2: Source (post id) | E2: Songs enrolled | F2: DM-context streams, campaign | G2: DM-context streams, prior 28 days | H2: Reported lift | I2: Era | J2: Lift, 2023-24 | K2: Lift, 2025-26 | L2: Campaign listeners | M2: New listeners | N2: Saves + adds per listener | O2: Songs that gained | P2: Songs reported | Q2: Notes
B4: Streams in Radio, Autoplay and Mixes during the campaign vs the 28 days before, as shown in artists' Spotify for Artists screenshots.
B6: 1. Campaign Reports With a Prior-28-Day Figure
B7: Aug 2023 | C7: 45139 | D7: 15woi7w | F7: 445475 | G7: 91662 | H7: =IF(G7="","",F7/G7-1) -> 3.8599747 | I7: =IF(YEAR(C7)<=2024,"2023-24","2025-26") -> 2023-24 | J7: =IF(I7="2023-24",H7,"") -> 3.8599747 | K7: =IF(I7="2025-26",H7,"") | L7: 192090 | M7: 105307 | N7: 0.010573169 | Q7: Aug 1-20 only; 'results insane'.
B8: Oct 2024 (a) | C8: 45566 | D8: 1g1fk0o | E8: 8 | F8: 5658 | G8: 1076 | H8: =IF(G8="","",F8/G8-1) -> 4.2583643 | I8: =IF(YEAR(C8)<=2024,"2023-24","2025-26") -> 2023-24 | J8: =IF(I8="2023-24",H8,"") -> 4.2583643 | K8: =IF(I8="2025-26",H8,"") | L8: 4755 | N8: 0.011987382 | O8: 8 | P8: 8
B9: Oct 2024 (b) | C9: 45566 | D9: 1geig0k | E9: 4 | F9: 3011 | G9: 359 | H9: =IF(G9="","",F9/G9-1) -> 7.3871866 | I9: =IF(YEAR(C9)<=2024,"2023-24","2025-26") -> 2023-24 | J9: =IF(I9="2023-24",H9,"") -> 7.3871866 | K9: =IF(I9="2025-26",H9,"") | L9: 1723 | M9: 932 | N9: 0.048171793 | O9: 3 | P9: 4
B10: Nov 2024 | C10: 45597 | D10: 1h46nzy | E10: 4 | F10: 46995 | G10: 16336 | H10: =IF(G10="","",F10/G10-1) -> 1.8767752 | I10: =IF(YEAR(C10)<=2024,"2023-24","2025-26") -> 2023-24 | J10: =IF(I10="2023-24",H10,"") -> 1.8767752 | K10: =IF(I10="2025-26",H10,"") | L10: 25167 | M10: 21328 | N10: 0.010728335 | Q10: ~25k monthly listeners.
B11: Jan 2025 | C11: 45658 | D11: 1ig7963 (text) | E11: 1 | F11: 7404 | G11: 4777 | H11: =IF(G11="","",F11/G11-1) -> 0.54992673 | I11: =IF(YEAR(C11)<=2024,"2023-24","2025-26") -> 2025-26 | J11: =IF(I11="2023-24",H11,"") | K11: =IF(I11="2025-26",H11,"") -> 0.54992673 | Q11: Spotify reported +55% lift, but the same song's TOTAL streams fell from ~46k/month (Oct-Dec) to 43k in Jan.
B12: Oct 2025 | C12: 45931 | D12: 1omcbrg | E12: 7 | F12: 39156 | G12: 10195 | H12: =IF(G12="","",F12/G12-1) -> 2.8407062 | I12: =IF(YEAR(C12)<=2024,"2023-24","2025-26") -> 2025-26 | J12: =IF(I12="2023-24",H12,"") | K12: =IF(I12="2025-26",H12,"") -> 2.8407062 | L12: 27807 | N12: 0.017333765 | O12: 7 | P12: 7
B13: Jul 2026 | C13: 46204 | D13: 1uy70w1 (text) | E13: 3 | F13: 7675 | G13: 4312 | H13: =IF(G13="","",F13/G13-1) -> 0.77991651 | I13: =IF(YEAR(C13)<=2024,"2023-24","2025-26") -> 2025-26 | J13: =IF(I13="2023-24",H13,"") | K13: =IF(I13="2025-26",H13,"") -> 0.77991651 | L13: 5911 | M13: 5243 | N13: 0.012857385 | O13: 3 | P13: 3
B15: Median reported lift, 2023-24 campaigns | H15: =MEDIAN(H7:H10) -> 4.0591695 | I15: =COUNT(H7:H10) -> 4 | Q15: n in column I. Rows are sorted by campaign date, so the era split is the row break between Nov 2024 and Jan 2025.
B16: Median reported lift, 2025-26 campaigns | H16: =MEDIAN(H11:H13) -> 0.77991651 | I16: =COUNT(H11:H13) -> 3
B17: Median reported lift, all campaigns with a before figure | H17: =MEDIAN(H7:H13) -> 2.8407062 | I17: =COUNT(H7:H13) -> 7
B18: Latest campaign lift as a share of the earliest | H18: =H13/H7 -> 0.20205223
B20: 2. Campaign Reports Without a Prior-28-Day Figure (engagement only)
B21: Dec 2023 | C21: 45261 | D21: 18lveoc | E21: 6 | F21: 1816 | H21: =IF(G21="","",F21/G21-1) | I21: =IF(YEAR(C21)<=2024,"2023-24","2025-26") -> 2023-24 | J21: =IF(I21="2023-24",H21,"") | K21: =IF(I21="2025-26",H21,"") | L21: 1306 | N21: 0.018376723 | O21: 2 | P21: 6 | Q21: 4 of 6 songs got 0 DM streams (incl. top songs).
B22: Sep 2026 | C22: 46266 | D22: 1wu7cam | E22: 7 | F22: 27994 | H22: =IF(G22="","",F22/G22-1) | I22: =IF(YEAR(C22)<=2024,"2023-24","2025-26") -> 2025-26 | J22: =IF(I22="2023-24",H22,"") | K22: =IF(I22="2025-26",H22,"") | L22: 22689 | N22: 0.0068315043 | Q22: Intent 0.19-1.10% per song.
B24: 3. Definitions and Sources
B25: Reported lift = campaign streams / prior-28-day streams - 1. Where the screenshot showed only the lift, the prior-28-day figure is streams / (1 + lift).
B26: These counts cover only Radio, Autoplay and Mixes. They do not show whether the song's total streams rose; the Jan 2025 case is the one artist who checked, and total streams fell.
B27: Saves + adds per listener = (saves + playlist adds) / campaign listeners, from the same screenshot.
B28: Source: screenshots posted to r/musicmarketing, identified by post id. Collected via the Arctic Shift archive, read by hand.
B30: Colour key: blue = hard-coded input read from the post or screenshot (notes give the post id); black = formula; green = link to another tab.

Sheet DM Artist Pairs
B2: Discovery Mode Artist Before/After Pairs | C2: Date posted | D2: Year | E2: Monthly listeners at start | F2: Size band | G2: Before | H2: After | I2: Change | J2: Direction | K2: Source (post id) | L2: Notes
B4: Every first-hand report that gave both a before and an after figure. 'Flat' = change within +/-5%.
B6: 1. Before/After Pairs Reported by Artists
B7: Monthly listeners | C7: 45212 | D7: =YEAR(C7) -> 2023 | E7: 37500 | F7: =IF(E7="","not stated",IF(E7<10000,"Under 10k",IF(E7<50000,"10k-50k","50k+"))) -> 10k-50k | G7: 37500 | H7: 19000 | I7: =H7/G7-1 -> -0.49333333 | J7: =IF(ABS(I7)<0.05,"Flat",IF(I7>0,"Up","Down")) -> Down | K7: 176v311/k2zctt7/k3tx6dh | L7: Organic 35-40k listeners; after 3 months of DM down to 19k, no follows/saves from DM, Fans Also Like 'destroyed'.
B8: Monthly listeners | C8: 45213 | D8: =YEAR(C8) -> 2023 | E8: 80000 | F8: =IF(E8="","not stated",IF(E8<10000,"Under 10k",IF(E8<50000,"10k-50k","50k+"))) -> 50k+ | G8: 80000 | H8: 52000 | I8: =H8/G8-1 -> -0.35 | J8: =IF(ABS(I8)<0.05,"Flat",IF(I8>0,"Up","Down")) -> Down | K8: k4ox17o | L8: Discover Weekly streams fell, radio rose; saves/adds from DM 'terrible'.
B9: Monthly listeners | C9: 45213 | D9: =YEAR(C9) -> 2023 | E9: 80000 | F9: =IF(E9="","not stated",IF(E9<10000,"Under 10k",IF(E9<50000,"10k-50k","50k+"))) -> 50k+ | G9: 80000 | H9: 40000 | I9: =H9/G9-1 -> -0.5 | J9: =IF(ABS(I9)<0.05,"Flat",IF(I9>0,"Up","Down")) -> Down | K9: k4pk3ug | L9: Blames Spotify pushing Discover Weekly less after DM.
B10: Radio streams / month | C10: 45226 | D10: =YEAR(C10) -> 2023 | F10: =IF(E10="","not stated",IF(E10<10000,"Under 10k",IF(E10<50000,"10k-50k","50k+"))) -> not stated | G10: 1800 | H10: 20000 | I10: =H10/G10-1 -> 10.111111 | J10: =IF(ABS(I10)<0.05,"Flat",IF(I10>0,"Up","Down")) -> Up | K10: k6lhdlu | L10: Radio ~1,800/month before DM -> ~20,000/month after several months (releases weekly).
B11: Monthly listeners | C11: 45240 | D11: =YEAR(C11) -> 2023 | E11: 30000 | F11: =IF(E11="","not stated",IF(E11<10000,"Under 10k",IF(E11<50000,"10k-50k","50k+"))) -> 10k-50k | G11: 30000 | H11: 8700 | I11: =H11/G11-1 -> -0.71 | J11: =IF(ABS(I11)<0.05,"Flat",IF(I11>0,"Up","Down")) -> Down | K11: k79yvek | L11: One song on DM in Sept (0.90% intent); skipped Oct and Discover Weekly 'suppressed'; re-enrolled out of fear.
B12: Monthly listeners | C12: 45261 | D12: =YEAR(C12) -> 2023 | E12: 30000 | F12: =IF(E12="","not stated",IF(E12<10000,"Under 10k",IF(E12<50000,"10k-50k","50k+"))) -> 10k-50k | G12: 30000 | H12: 5000 | I12: =H12/G12-1 -> -0.83333333 | J12: =IF(ABS(I12)<0.05,"Flat",IF(I12>0,"Up","Down")) -> Down | K12: kbb4arn | L12: Beta: first campaign gave a bump; second campaign listeners fell 30k -> 5k (normal range 10-20k).
B13: Streams / month | C13: 45349 | D13: =YEAR(C13) -> 2024 | F13: =IF(E13="","not stated",IF(E13<10000,"Under 10k",IF(E13<50000,"10k-50k","50k+"))) -> not stated | G13: 10000 | H13: 50000 | I13: =H13/G13-1 -> 4 | J13: =IF(ABS(I13)<0.05,"Flat",IF(I13>0,"Up","Down")) -> Up | K13: kspq2mj | L13: 'Totally down to discovery mode'; not every song works.
B14: Streams / day | C14: 45352 | D14: =YEAR(C14) -> 2024 | F14: =IF(E14="","not stated",IF(E14<10000,"Under 10k",IF(E14<50000,"10k-50k","50k+"))) -> not stated | G14: 40000 | H14: 15000 | I14: =H14/G14-1 -> -0.625 | J14: =IF(ABS(I14)<0.05,"Flat",IF(I14>0,"Up","Down")) -> Down | K14: 1b43vbm | L14: Song at ~40k/day; fell the month it was enrolled and never recovered; also pulled from Discover Weekly.
B15: Radio streams / month | C15: 45352 | D15: =YEAR(C15) -> 2024 | F15: =IF(E15="","not stated",IF(E15<10000,"Under 10k",IF(E15<50000,"10k-50k","50k+"))) -> not stated | G15: 4000 | H15: 150 | I15: =H15/G15-1 -> -0.9625 | J15: =IF(ABS(I15)<0.05,"Flat",IF(I15>0,"Up","Down")) -> Down | K15: ksx3w9s | L15: Last DM month: 150 streams; month without DM: 4k on radio alone.
B16: Monthly listeners | C16: 45352 | D16: =YEAR(C16) -> 2024 | E16: 2000 | F16: =IF(E16="","not stated",IF(E16<10000,"Under 10k",IF(E16<50000,"10k-50k","50k+"))) -> Under 10k | G16: 2000 | H16: 7500 | I16: =H16/G16-1 -> 2.75 | J16: =IF(ABS(I16)<0.05,"Flat",IF(I16>0,"Up","Down")) -> Up | K16: kszo2zz
B17: Streams / month | C17: 45364 | D17: =YEAR(C17) -> 2024 | F17: =IF(E17="","not stated",IF(E17<10000,"Under 10k",IF(E17<50000,"10k-50k","50k+"))) -> not stated | G17: 1000000 | H17: 300000 | I17: =H17/G17-1 -> -0.7 | J17: =IF(ABS(I17)<0.05,"Flat",IF(I17>0,"Up","Down")) -> Down | K17: ktmj79o | L17: ~1M streams/month -> 300k 'literally overnight'; never came back after stopping.
B18: Discover Weekly streams / week | C18: 45518 | D18: =YEAR(C18) -> 2024 | F18: =IF(E18="","not stated",IF(E18<10000,"Under 10k",IF(E18<50000,"10k-50k","50k+"))) -> not stated | G18: 5000 | H18: 190 | I18: =H18/G18-1 -> -0.962 | J18: =IF(ABS(I18)<0.05,"Flat",IF(I18>0,"Up","Down")) -> Down | K18: li52lv4/lve66bg | L18: Best track ~5k DW streams/week; 3 weeks on DM = 567 DW streams total; took 4 months to recover.
B19: Monthly listeners | C19: 45649 | D19: =YEAR(C19) -> 2024 | E19: 25000 | F19: =IF(E19="","not stated",IF(E19<10000,"Under 10k",IF(E19<50000,"10k-50k","50k+"))) -> 10k-50k | G19: 25000 | H19: 60000 | I19: =H19/G19-1 -> 1.4 | J19: =IF(ABS(I19)<0.05,"Flat",IF(I19>0,"Up","Down")) -> Up | K19: m3i1jez | L19: ~30k DM streams month 1, 40k month 2.
B20: Monthly listeners | C20: 45653 | D20: =YEAR(C20) -> 2024 | E20: 5000 | F20: =IF(E20="","not stated",IF(E20<10000,"Under 10k",IF(E20<50000,"10k-50k","50k+"))) -> Under 10k | G20: 5000 | H20: 44000 | I20: =H20/G20-1 -> 7.8 | J20: =IF(ABS(I20)<0.05,"Flat",IF(I20>0,"Up","Down")) -> Up | K20: m3ys1wz | L20: Meta ads + DM; much of growth via radio.
B21: Streams / month | C21: 45690 | D21: =YEAR(C21) -> 2025 | E21: 60000 | F21: =IF(E21="","not stated",IF(E21<10000,"Under 10k",IF(E21<50000,"10k-50k","50k+"))) -> 50k+ | G21: 36655 | H21: 36549 | I21: =H21/G21-1 -> -0.0028918292 | J21: =IF(ABS(I21)<0.05,"Flat",IF(I21>0,"Up","Down")) -> Flat | K21: 1ig7963 | L21: Song A: Dec 36,655 streams -> Jan 36,549 while Spotify reported +69% lift. Song B: ~46k/month -> 43k while Spotify credited 7,404 DM streams (+55%).
B22: Monthly listeners | C22: 45909 | D22: =YEAR(C22) -> 2025 | E22: 10000 | F22: =IF(E22="","not stated",IF(E22<10000,"Under 10k",IF(E22<50000,"10k-50k","50k+"))) -> 10k-50k | G22: 10000 | H22: 20000 | I22: =H22/G22-1 -> 1 | J22: =IF(ABS(I22)<0.05,"Flat",IF(I22>0,"Up","Down")) -> Up | K22: nd42847
B23: Monthly listeners | C23: 45909 | D23: =YEAR(C23) -> 2025 | E23: 100 | F23: =IF(E23="","not stated",IF(E23<10000,"Under 10k",IF(E23<50000,"10k-50k","50k+"))) -> Under 10k | G23: 100 | H23: 700 | I23: =H23/G23-1 -> 6 | J23: =IF(ABS(I23)<0.05,"Flat",IF(I23>0,"Up","Down")) -> Up | K23: nd5w63f | L23: One track on DM ~800 streams/month; fans at shows cite it.
B24: Streams / day | C24: 46067 | D24: =YEAR(C24) -> 2026 | E24: 100000 | F24: =IF(E24="","not stated",IF(E24<10000,"Under 10k",IF(E24<50000,"10k-50k","50k+"))) -> 50k+ | G24: 500 | H24: 1000 | I24: =H24/G24-1 -> 1 | J24: =IF(ABS(I24)<0.05,"Flat",IF(I24>0,"Up","Down")) -> Up | K24: 1r4op37 | L24: Taking the song OUT of DM cut it from ~1,000 to ~500 streams/day; 'would not take it out again'.
B26: 2. Direction by Year Posted (these 18 numeric pairs) | L26: Caveat: by year, these pairs trend toward 'Up', not away from it. The 2023 losers were all 30k-80k-listener artists in the early rollout; most later winners are small artists. Read it as a change in who posts, not proof the program improved.
B27: Year | C27: Up | D27: Down | E27: Flat | F27: Total | G27: Avg listeners at start, Down cases
B28: 2023 | C28: =COUNTIFS($D$7:$D$24,B28,$J$7:$J$24,"Up") -> 1 | D28: =COUNTIFS($D$7:$D$24,B28,$J$7:$J$24,"Down") -> 5 | E28: =COUNTIFS($D$7:$D$24,B28,$J$7:$J$24,"Flat") -> 0 | F28: =SUM(C28:E28) -> 6 | G28: =IFERROR(AVERAGEIFS($E$7:$E$24,$D$7:$D$24,B28,$J$7:$J$24,"Down"),"size not stated") -> 51500
B29: 2024 | C29: =COUNTIFS($D$7:$D$24,B29,$J$7:$J$24,"Up") -> 4 | D29: =COUNTIFS($D$7:$D$24,B29,$J$7:$J$24,"Down") -> 4 | E29: =COUNTIFS($D$7:$D$24,B29,$J$7:$J$24,"Flat") -> 0 | F29: =SUM(C29:E29) -> 8 | G29: =IFERROR(AVERAGEIFS($E$7:$E$24,$D$7:$D$24,B29,$J$7:$J$24,"Down"),"size not stated") -> size not stated
B30: 2025 | C30: =COUNTIFS($D$7:$D$24,B30,$J$7:$J$24,"Up") -> 2 | D30: =COUNTIFS($D$7:$D$24,B30,$J$7:$J$24,"Down") -> 0 | E30: =COUNTIFS($D$7:$D$24,B30,$J$7:$J$24,"Flat") -> 1 | F30: =SUM(C30:E30) -> 3 | G30: =IFERROR(AVERAGEIFS($E$7:$E$24,$D$7:$D$24,B30,$J$7:$J$24,"Down"),"size not stated") -> size not stated
B31: 2026 | C31: =COUNTIFS($D$7:$D$24,B31,$J$7:$J$24,"Up") -> 1 | D31: =COUNTIFS($D$7:$D$24,B31,$J$7:$J$24,"Down") -> 0 | E31: =COUNTIFS($D$7:$D$24,B31,$J$7:$J$24,"Flat") -> 0 | F31: =SUM(C31:E31) -> 1 | G31: =IFERROR(AVERAGEIFS($E$7:$E$24,$D$7:$D$24,B31,$J$7:$J$24,"Down"),"size not stated") -> size not stated
B33: 3. Direction by Audience Size at the Start (all first-hand reports that stated a size, n = 26) | L33: Counts come from the hand-coded set of 70 first-hand reports (not only the 18 with numbers); 26 of them stated an audience size. 'Mixed / flat' pools the report's 'mixed' and 'flat' codes.
B34: Size band | C34: Up | D34: Mixed / flat | E34: Down | F34: Total | G34: Share up
B35: Under 10k | C35: 8 | D35: 0 | E35: 0 | F35: =SUM(C35:E35) -> 8 | G35: =C35/F35 -> 1
B36: 10k-50k | C36: 4 | D36: 1 | E36: 4 | F36: =SUM(C36:E36) -> 9 | G36: =C36/F36 -> 0.44444444
B37: 50k+ | C37: 3 | D37: 3 | E37: 3 | F37: =SUM(C37:E37) -> 9 | G37: =C37/F37 -> 0.33333333
B38: 10k and above | C38: =SUM(C36:C37) -> 7 | D38: =SUM(D36:D37) -> 4 | E38: =SUM(E36:E37) -> 7 | F38: =SUM(C38:E38) -> 18 | G38: =C38/F38 -> 0.38888889
B40: Colour key: blue = hard-coded input read from the post or screenshot (notes give the post id); black = formula; green = link to another tab.

Sheet DM Engagement
B2: Discovery Mode Listener Engagement | C2: Group | D2: Source (post id) | E2: Listeners | F2: Saves + adds per listener | G2: Discovery Mode listeners | H2: Overall audience | I2: Notes
B4: Discovery Mode campaign listeners (Spotify campaign report) vs artists' overall audience (Spotify for Artists dashboard). Columns G and H split the series for the chart.
B6: 1. Saves + Playlist Adds per Listener
B7: Aug 2023 campaign | C7: Discovery Mode listeners | D7: ='DM Campaign Lifts'!$D$7 -> 15woi7w | E7: ='DM Campaign Lifts'!$L$7 -> 192090 | F7: ='DM Campaign Lifts'!$N$7 -> 0.010573169 | G7: =F7 -> 0.010573169 | I7: Discovery Mode rows link to the campaign-report tab: listeners and (saves + playlist adds) / campaign listeners from the campaign screenshot.
B8: Dec 2023 campaign | C8: Discovery Mode listeners | D8: ='DM Campaign Lifts'!$D$21 -> 18lveoc | E8: ='DM Campaign Lifts'!$L$21 -> 1306 | F8: ='DM Campaign Lifts'!$N$21 -> 0.018376723 | G8: =F8 -> 0.018376723
B9: Oct 2024 campaign (a) | C9: Discovery Mode listeners | D9: ='DM Campaign Lifts'!$D$8 -> 1g1fk0o | E9: ='DM Campaign Lifts'!$L$8 -> 4755 | F9: ='DM Campaign Lifts'!$N$8 -> 0.011987382 | G9: =F9 -> 0.011987382
B10: Oct 2024 campaign (b) | C10: Discovery Mode listeners | D10: ='DM Campaign Lifts'!$D$9 -> 1geig0k | E10: ='DM Campaign Lifts'!$L$9 -> 1723 | F10: ='DM Campaign Lifts'!$N$9 -> 0.048171793 | G10: =F10 -> 0.048171793
B11: Nov 2024 campaign | C11: Discovery Mode listeners | D11: ='DM Campaign Lifts'!$D$10 -> 1h46nzy | E11: ='DM Campaign Lifts'!$L$10 -> 25167 | F11: ='DM Campaign Lifts'!$N$10 -> 0.010728335 | G11: =F11 -> 0.010728335
B12: Oct 2025 campaign | C12: Discovery Mode listeners | D12: ='DM Campaign Lifts'!$D$12 -> 1omcbrg | E12: ='DM Campaign Lifts'!$L$12 -> 27807 | F12: ='DM Campaign Lifts'!$N$12 -> 0.017333765 | G12: =F12 -> 0.017333765
B13: Jul 2026 campaign | C13: Discovery Mode listeners | D13: ='DM Campaign Lifts'!$D$13 -> 1uy70w1 (text) | E13: ='DM Campaign Lifts'!$L$13 -> 5911 | F13: ='DM Campaign Lifts'!$N$13 -> 0.012857385 | G13: =F13 -> 0.012857385
B14: Sep 2026 campaign | C14: Discovery Mode listeners | D14: ='DM Campaign Lifts'!$D$22 -> 1wu7cam | E14: ='DM Campaign Lifts'!$L$22 -> 22689 | F14: ='DM Campaign Lifts'!$N$22 -> 0.0068315043 | G14: =F14 -> 0.0068315043
B15: Artist 17gqiej, 12 months | C15: Overall audience | D15: 17gqiej | F15: 0.24525392 | H15: =F15 -> 0.24525392 | I15: Overall rate = saves / listeners from the artist's 12-month dashboard. Different artists and definitions, so read as orders of magnitude.
B16: Artist 1q4bb7s, all time | C16: Overall audience | D16: 1q4bb7s | F16: 0.18248588 | H16: =F16 -> 0.18248588
B17: Artist 1rvflj9, 12 months | C17: Overall audience | D17: 1rvflj9 | F17: 0.21461319 | H17: =F17 -> 0.21461319
B18: Kublaii (1hn3dhf), 12 months | C18: Overall audience | D18: 1hn3dhf | F18: 0.080622942 | H18: =F18 -> 0.080622942
B20: Median, Discovery Mode listeners | F20: =MEDIAN(F7:F14) -> 0.012422383
B21: Median, overall audience | F21: =MEDIAN(F15:F18) -> 0.19854954
B22: Overall audience keeps the song this many times more often | F22: =F21/F20 -> 15.983208 | I22: Order-of-magnitude gap: Discovery Mode listeners keep the song about 1% of the time; an artist's normal audience roughly 20%.
B24: Colour key: blue = hard-coded input read from the post or screenshot (notes give the post id); black = formula; green = link to another tab.

Sheet DM On-Off Cases
B2: Discovery Mode On/Off Cases | C2: Source (post id) | D2: Switch | E2: Before | F2: After | G2: Change | H2: Notes
B4: Cases where an artist's own graphs show the switch.
B6: 1. What Happened When Discovery Mode Was Switched On or Off
B7: Radio & autoplay listeners / day | C7: 1and042 | D7: DM on (Apr 2023) | E7: 70 | F7: 900 | G7: =IF(OR(E7="",F7=""),"",F7/E7-1) -> 11.857143 | H7: ~70/day before -> ~400 right after -> ~900-1,200 a year later; weekly releases throughout.
B8: Artist streams / month | C8: 1q4bb7s | D8: DM on (Dec 1, 2025) | E8: 195000 | F8: 280000 | G8: =IF(OR(E8="",F8=""),"",F8/E8-1) -> 0.43589744 | H8: Nov ~195k -> Dec ~280k (back to Oct level). Song-level daily streams: 2,646 -> ~4,500; 270 -> ~900; 553 -> ~1,300. Popularity of 4 promoted songs +4-6 points, top song -2. Followers/day unchanged.
B9: Radio & autoplay streams / day | C9: 1rvflj9 | D9: DM off (Oct 2025) then on | E9: 7000 | F9: 2000 | G9: =IF(OR(E9="",F9=""),"",F9/E9-1) -> -0.71428571 | H9: ~6-9k/day Jul-Sep with DM -> ~2k/day in October with DM off -> 6-11k/day after re-enrolling. Then an ~80% collapse in Mar 2026 with DM on.
B10: Song streams / day | C10: 1r4op37 (text) | D10: DM off | E10: 1000 | F10: 500 | G10: =IF(OR(E10="",F10=""),"",F10/E10-1) -> -0.5 | H10: Spotify flagged the song 'not recommended'; removing it halved daily streams.
B11: Radio streams / month | C11: ksx3w9s (text) | D11: DM off | E11: 150 | F11: 4000 | G11: =IF(OR(E11="",F11=""),"",F11/E11-1) -> 25.666667 | H11: Opposite case: 150 DM streams in last DM month; 4k radio the month after leaving.
B12: Song radio streams (28 days) | C12: 1t81jjd | D12: DM off + Meta ads | F12: 74 | G12: =IF(OR(E12="",F12=""),"",F12/E12-1) | H12: 7 of 12 songs had fallen to 0-100 radio streams in DM; after opting out, radio stayed at 74 even with ads (saves +270%).
B14: Why it matters for the framing | H14: Artists who stay enrolled describe it as defensive (re-enrolled out of fear; 'would not take it out again'). Switching off cut radio streams by 50-70% in two charted cases. For an artist deciding whether to enroll for the first time, the pitch has become 'pay 30% to avoid losing ground'.
B16: Colour key: blue = hard-coded input read from the post or screenshot (notes give the post id); black = formula; green = link to another tab.

Sheet DM Corpus
B2: Discovery Mode Corpus and Method | C2: Value | H2: Notes
B4: Source corpus, the extra series quoted in posts, and how the reports were coded.
B6: 1. Corpus
B7: r/musicmarketing posts since Oct 2020 (Arctic Shift archive) | C7: 27088
B8: Posts mentioning Discovery Mode | C8: 130
B9: Comments in those threads | C9: 1953
B10: Artist experiences coded | C10: 73
B11: of which first-hand | C11: 70
B12: first-hand: streams went up | C12: 39
B13: first-hand: streams went down | C13: 21
B14: first-hand: mixed | C14: 7
B15: first-hand: flat | C15: 3
B16: First-hand reports saying Discover Weekly / algorithmic streams fell after opting in | C16: 12
B17: Spotify for Artists screenshots read (7 more had been deleted) | C17: 35
B18: Share of first-hand reports that went up | C18: =C12/C11 -> 0.55714286
B20: 2. Spotify-Reported 'Stream Lift' Figures Quoted in Posts and Screenshots | H20: Order as extracted; dates not attached, so this list cannot be used for a time trend.
B21: Lift 1 | C21: 2.77
B22: Lift 2 | C22: 9.15
B23: Lift 3 | C23: 11.92
B24: Lift 4 | C24: 1.5
B25: Lift 5 | C25: 20
B26: Lift 6 | C26: 30
B27: Lift 7 | C27: 60
B28: Lift 8 | C28: 1.53
B29: Lift 9 | C29: 0.69
B30: Lift 10 | C30: 0.55
B31: Lift 11 | C31: 0.78
B32: Lift 12 | C32: 2.14
B33: Lift 13 | C33: 1.69
B34: Median | C34: =MEDIAN(C21:C33) -> 2.14
B36: 3. Intent Rate per Song Quoted by Artists (saves + adds / listeners) | H36: Spotify's own engagement measure for a Discovery Mode song. Order as extracted.
B37: Intent 1 | C37: 0.015
B38: Intent 2 | C38: 0.009
B39: Intent 3 | C39: 0.02
B40: Intent 4 | C40: 0.0266
B41: Intent 5 | C41: 0.01
B42: Intent 6 | C42: 0.0079
B43: Intent 7 | C43: 0.01
B44: Intent 8 | C44: 0.0121
B45: Intent 9 | C45: 0.004
...
