Workbook

Sheet Summary
A1: Spotify Discovery Mode: from autoplay share of streams to gross margin
A2: Chain: share of music streams in DM contexts (Radio, Autoplay, Mixes) x share of those that are DM-enrolled x 30% commission x recording royalties as % of music revenue x music share of revenue = DM saving as % of revenue. The model is anchored to your view that Discovery Mode is at least 80% of Marketplace gross profit (Inputs section F); the public-bounds estimate is shown beside it for reference.
A4: Selected scenario | B4: =CHOOSE(Inputs!$B$4,"Bear","Base","Bull") -> Base | C4: (Inputs!B4) | E4: Calibration mode | F4: =CHOOSE(Inputs!$B$50+1,"0: as entered","1: hold s_dm, re-level s_ctx","2: hold s_ctx, re-level s_dm","3: re-level both") -> 1: hold s_dm, re-level s_ctx | I4: (Inputs!B50)
A6: The chain, FY2025 (Base) | B6: Model (anchored) | C6: Public bounds only
A7: Share of music streams in Discovery Mode contexts (s_ctx) | B7: ='DM build'!G20 -> 0.60572901 | C7: =Inputs!G13 -> 0.14
A8: Share of those streams that are DM-enrolled (s_dm) | B8: ='DM build'!G21 -> 0.33 | C8: =Inputs!G20 -> 0.33
A9: -> Discovery Mode streams as % of all music streams | B9: ='DM build'!G22 -> 0.19989057 | C9: =C7*C8 -> 0.0462
A10: x Commission on recording royalties (d) | B10: ='DM build'!G23 -> 0.3 | C10: =Inputs!G27 -> 0.3
A11: x Recording royalties % of music revenue x music share of revenue | B11: =Inputs!$C$8*Inputs!$C$9 -> 0.4968 | C11: =Inputs!$C$8*Inputs!$C$9 -> 0.4968
A12: -> Discovery Mode saving as % of total revenue | B12: ='DM build'!G25 -> 0.029791691 | C12: =C9*C10*C11 -> 0.006885648
A13: -> Gross margin contribution (bp) | B13: ='DM build'!G28 -> 297.91691 | C13: =C12*10000 -> 68.85648
A14: -> Discovery Mode gross profit (EUR m) | B14: ='DM build'!G27 -> 512 | C14: =C12*'Revenue & GM'!G13 -> 118.33675
A16: Marketplace anchor (Inputs section F)
A17: Marketplace gross profit FY2025, implied (EUR m) | B17: =Inputs!G53 -> 640
A18: Discovery Mode share of Marketplace gross profit (your view) | B18: =Inputs!G54 -> 0.8
A19: Anchor: Discovery Mode gross profit FY2025 (EUR m) / bp of gross margin | B19: =Inputs!G55 -> 512 | C19: =Inputs!G56*10000 -> 297.91691
A20: DM streams as % of music streams: required by anchor / as entered (public bounds) | B20: =Inputs!G57 -> 0.19989057 | C20: =Inputs!G13*Inputs!G20 -> 0.0462
A21: Re-level factor on the product (required / as entered) | B21: =Inputs!G57/(Inputs!G13*Inputs!G20) -> 4.3266358
A22: Calibrated FY2025 (Base): s_ctx / s_dm | B22: =Inputs!G67 -> 0.60572901 | C22: =Inputs!G73 -> 0.33
A23: Plausibility | B23: =IF(Inputs!G67>0.25,"s_ctx ABOVE the ~25% public bound","s_ctx within public bound") -> s_ctx ABOVE the ~25% public bound | C23: =IF(Inputs!G73>0.57,"s_dm ABOVE the ~57% no-majors ceiling","s_dm within ceiling") -> s_dm within ceiling
A25: Scenario outputs (anchored)
A26: Scenario | B26: FY2025A bp | C26: FY2030E bp | D26: Change bp | E26: FY2030E EUR m | F26: s_ctx FY2030 | G26: s_dm FY2030 | H26: d FY2030
A27: Bear | B27: ='DM build'!G15 -> 297.91691 | C27: ='DM build'!L15 -> 235.22309 | D27: =C27-B27 -> -62.693818 | E27: ='DM build'!L14 -> 692.54561 | F27: ='DM build'!L7 -> 0.74270813 | G27: ='DM build'!L8 -> 0.255 | H27: ='DM build'!L10 -> 0.25
A28: Base | B28: ='DM build'!G28 -> 297.91691 | C28: ='DM build'!L28 -> 322.50851 | D28: =C28-B28 -> 24.5916 | E28: ='DM build'!L27 -> 949.532 | F28: ='DM build'!L20 -> 0.56944887 | G28: ='DM build'!L21 -> 0.38 | H28: ='DM build'!L23 -> 0.3
A29: Bull | B29: ='DM build'!G41 -> 297.91691 | C29: ='DM build'!L41 -> 393.00443 | D29: =C29-B29 -> 95.08752 | E29: ='DM build'!L40 -> 1157.0866 | F29: ='DM build'!L33 -> 0.52738114 | G29: ='DM build'!L34 -> 0.5 | H29: ='DM build'!L36 -> 0.3
A31: FY2030E reported gross margin, selected scenario on your ex-DM path | B31: ='Revenue & GM'!L24 -> 0.34725434 | D31: Investor Day target 35-40%
A32: Share of FY2021-25 reported margin expansion explained by Discovery Mode | B32: ='Revenue & GM'!C34 -> 0.47930459
A33: ... as a share of the 'about a third from music' management cited (above 100% = DM alone exceeds the music third) | B33: ='Revenue & GM'!C36 -> 1.4379138
A35: What the evidence supports
A36: 1. Spotify keeps the commission. The 20-F says cost of revenue 'reflects discounts provided by certain rights holders in return for promotional activities in connection with marketplace programs', and every 2025-26 letter attributes Premium margin gains to 'music costs net of marketplace programs'. The 30% is a gross-margin item, not a redistribution to other labels.
A37: 2. Public bounds alone (DM contexts at 9-20% of music streams, 14% base; 33% of those enrolled) give about 70bp and EUR 120m for FY2025. Your anchor (Discovery Mode at least 80% of roughly EUR 640m Marketplace gross profit) gives about 300bp and EUR 510m, 4.3x larger. The model now runs on the anchor; column C of the chain keeps the public-bounds figure visible.
A38: 3. To hit the anchor, DM streams must be about a fifth of all music streams. Holding your 33% enrollment, DM contexts must carry ~60% of streams, above Spotify's own 'majority of streams are active'. Re-levelling both unknowns gives roughly 30% x 70%, which needs either an Autoplay share far larger than the 25bn-stream sample captured or enrollment beyond the no-majors ceiling. The calibration mode (Inputs!B50) picks which variable absorbs it; the plausibility row flags the result.
A39: 4. On the anchor, Discovery Mode explains about half of the FY2021-25 margin expansion, more than management's 'about a third from music' leaves for all of music. Either the '4x' recap overstates Marketplace gross profit, or the music third was framed over a different period. This is the first thing to test against the Tegus calls (Topic 2 of the triangulation matrix).
A40: 5. Forecast on the anchor: roughly 235bp Bear, 325bp Base, 395bp Bull by FY2030, i.e. the scenario deltas from the public-bounds build carried onto the anchored FY2025 level. Lean-back growth still does not reach DM automatically: AI DJ, Smart Shuffle and Discover Weekly are not DM contexts, so the Bull needs a context expansion or a major label.
A42: Sensitivity: FY2030 gross margin contribution (bp) to the two unknowns, at Base commission and royalty assumptions
A43: s_ctx (context share of music streams) ↓ | s_dm (DM share of context streams) → | B43: 0.2 | C43: 0.33 | D43: 0.4 | E43: 0.5 | F43: 0.6 | G43: 0.8 | H43: 1
A44: 0.1 | B44: =$A44*B$43*Inputs!$L$27*Inputs!$C$8*Inputs!$C$9*10000 -> 29.808 | C44: =$A44*C$43*Inputs!$L$27*Inputs!$C$8*Inputs!$C$9*10000 -> 49.1832 | D44: =$A44*D$43*Inputs!$L$27*Inputs!$C$8*Inputs!$C$9*10000 -> 59.616 | E44: =$A44*E$43*Inputs!$L$27*Inputs!$C$8*Inputs!$C$9*10000 -> 74.52 | F44: =$A44*F$43*Inputs!$L$27*Inputs!$C$8*Inputs!$C$9*10000 -> 89.424 | G44: =$A44*G$43*Inputs!$L$27*Inputs!$C$8*Inputs!$C$9*10000 -> 119.232 | H44: =$A44*H$43*Inputs!$L$27*Inputs!$C$8*Inputs!$C$9*10000 -> 149.04
A45: 0.14 | B45: =$A45*B$43*Inputs!$L$27*Inputs!$C$8*Inputs!$C$9*10000 -> 41.7312 | C45: =$A45*C$43*Inputs!$L$27*Inputs!$C$8*Inputs!$C$9*10000 -> 68.85648 | D45: =$A45*D$43*Inputs!$L$27*Inputs!$C$8*Inputs!$C$9*10000 -> 83.4624 | E45: =$A45*E$43*Inputs!$L$27*Inputs!$C$8*Inputs!$C$9*10000 -> 104.328 | F45: =$A45*F$43*Inputs!$L$27*Inputs!$C$8*Inputs!$C$9*10000 -> 125.1936 | G45: =$A45*G$43*Inputs!$L$27*Inputs!$C$8*Inputs!$C$9*10000 -> 166.9248 | H45: =$A45*H$43*Inputs!$L$27*Inputs!$C$8*Inputs!$C$9*10000 -> 208.656
A46: 0.2 | B46: =$A46*B$43*Inputs!$L$27*Inputs!$C$8*Inputs!$C$9*10000 -> 59.616 | C46: =$A46*C$43*Inputs!$L$27*Inputs!$C$8*Inputs!$C$9*10000 -> 98.3664 | D46: =$A46*D$43*Inputs!$L$27*Inputs!$C$8*Inputs!$C$9*10000 -> 119.232 | E46: =$A46*E$43*Inputs!$L$27*Inputs!$C$8*Inputs!$C$9*10000 -> 149.04 | F46: =$A46*F$43*Inputs!$L$27*Inputs!$C$8*Inputs!$C$9*10000 -> 178.848 | G46: =$A46*G$43*Inputs!$L$27*Inputs!$C$8*Inputs!$C$9*10000 -> 238.464 | H46: =$A46*H$43*Inputs!$L$27*Inputs!$C$8*Inputs!$C$9*10000 -> 298.08
A47: 0.3 | B47: =$A47*B$43*Inputs!$L$27*Inputs!$C$8*Inputs!$C$9*10000 -> 89.424 | C47: =$A47*C$43*Inputs!$L$27*Inputs!$C$8*Inputs!$C$9*10000 -> 147.5496 | D47: =$A47*D$43*Inputs!$L$27*Inputs!$C$8*Inputs!$C$9*10000 -> 178.848 | E47: =$A47*E$43*Inputs!$L$27*Inputs!$C$8*Inputs!$C$9*10000 -> 223.56 | F47: =$A47*F$43*Inputs!$L$27*Inputs!$C$8*Inputs!$C$9*10000 -> 268.272 | G47: =$A47*G$43*Inputs!$L$27*Inputs!$C$8*Inputs!$C$9*10000 -> 357.696 | H47: =$A47*H$43*Inputs!$L$27*Inputs!$C$8*Inputs!$C$9*10000 -> 447.12
...

Sheet Inputs
A1: Inputs and scenarios (blue = hardcoded input; black = formula)
A2: Change the scenario selector or any blue cell. History (FY2021-25) uses the same estimate in every scenario; scenarios diverge from FY2026.
A4: Scenario selector (1 = Bear, 2 = Base, 3 = Bull) | B4: 2 | C4: =CHOOSE($B$4,"Bear","Base","Bull") -> Base
A6: Assumption | B6: Unit | C6: FY2021A | D6: FY2022A | E6: FY2023A | F6: FY2024A | G6: FY2025A | H6: FY2026E | I6: FY2027E | J6: FY2028E | K6: FY2029E | L6: FY2030E
A7: Constants
A8: Recording royalties as % of music revenue (r_rec) | B8: % of music rev | C8: 0.54 | D8: Spotify does not disclose. MIDiA per-stream split 30% DSP / 56% recording / 14% publishing; FY2025 Premium cost of revenue 66% of Premium revenue incl. publishing, delivery, audiobooks. Range 50-58%.
A9: Music share of total revenue (m) | B9: % of total rev | C9: 0.92 | D9: Podcast advertising, audiobook a-la-carte and other non-music revenue carry no Discovery Mode commission. Assumption.
A11: A. DM-eligible context share of music streams (Spotify Radio + Autoplay + Spotify Mixes) - s_ctx
A12: Bear | B12: % of music streams | C12: 0.09 | D12: 0.09 | E12: 0.095 | F12: 0.13 | G12: 0.14 | H12: 0.14 | I12: 0.14 | J12: 0.14 | K12: 0.14 | L12: 0.14
A13: Base | B13: % of music streams | C13: 0.09 | D13: 0.09 | E13: 0.095 | F13: 0.13 | G13: 0.14 | H13: 0.145 | I13: 0.15 | J13: 0.155 | K13: 0.16 | L13: 0.165
A14: Bull | B14: % of music streams | C14: 0.09 | D14: 0.09 | E14: 0.095 | F14: 0.13 | G14: 0.14 | H14: 0.15 | I14: 0.19 | J14: 0.2 | K14: 0.21 | L14: 0.22
A15: Selected scenario | B15: % of music streams | C15: =CHOOSE($B$4,C12,C13,C14) -> 0.09 | D15: =CHOOSE($B$4,D12,D13,D14) -> 0.09 | E15: =CHOOSE($B$4,E12,E13,E14) -> 0.095 | F15: =CHOOSE($B$4,F12,F13,F14) -> 0.13 | G15: =CHOOSE($B$4,G12,G13,G14) -> 0.14 | H15: =CHOOSE($B$4,H12,H13,H14) -> 0.145 | I15: =CHOOSE($B$4,I12,I13,I14) -> 0.15 | J15: =CHOOSE($B$4,J12,J13,J14) -> 0.155 | ... L15: =CHOOSE($B$4,L12,L13,L14) -> 0.165
A16: History: Radio + Autoplay only until Daily Mix joined Discovery Mode on 3 Jan 2024 and Artist/Genre/Decade/Mood Mixes through 2024 (+3.5pp step). FY2025 base 14% sits inside the 9-20% triangulated range (see Triangulation sheet). Bear: flat. Base: +0.5pp a year as lean-back listening grows. Bull: +1pp a year plus a +3pp step in FY2027 if Spotify extends Discovery Mode to Smart Shuffle or other personalised surfaces (not a DM context today).
A18: B. Discovery Mode-enrolled share of DM-context streams - s_dm
A19: Bear | B19: % of context streams | C19: 0.05 | D19: 0.1 | E19: 0.2 | F19: 0.28 | G19: 0.33 | H19: 0.315 | I19: 0.3 | J19: 0.285 | K19: 0.27 | L19: 0.255
A20: Base | B20: % of context streams | C20: 0.05 | D20: 0.1 | E20: 0.2 | F20: 0.28 | G20: 0.33 | H20: 0.34 | I20: 0.35 | J20: 0.36 | K20: 0.37 | L20: 0.38
A21: Bull | B21: % of context streams | C21: 0.05 | D21: 0.1 | E21: 0.2 | F21: 0.28 | G21: 0.33 | H21: 0.35 | I21: 0.43 | J21: 0.455 | K21: 0.48 | L21: 0.5
A22: Selected scenario | B22: % of context streams | C22: =CHOOSE($B$4,C19,C20,C21) -> 0.05 | D22: =CHOOSE($B$4,D19,D20,D21) -> 0.1 | E22: =CHOOSE($B$4,E19,E20,E21) -> 0.2 | F22: =CHOOSE($B$4,F19,F20,F21) -> 0.28 | G22: =CHOOSE($B$4,G19,G20,G21) -> 0.33 | H22: =CHOOSE($B$4,H19,H20,H21) -> 0.34 | I22: =CHOOSE($B$4,I19,I20,I21) -> 0.35 | J22: =CHOOSE($B$4,J19,J20,J21) -> 0.36 | ... L22: =CHOOSE($B$4,L19,L20,L21) -> 0.38
A23: FY2025 = your 33% assumption; the Triangulation sheet shows it is consistent with ~28% of streams outside the majors and Merlin, about half of that catalog enrolled, and a ~3x in-context boost. History ramps from the Nov 2020 US beta (Radio/Autoplay, few licensors) through self-serve access for all distributors (Mar 2023). Bear: -1.5pp a year as the per-track boost fades and enrollment churns (the r/musicmarketing evidence). Base: +1pp a year toward a ~40% no-majors ceiling. Bull: a major label opts in during FY2027 (+8pp step), then +2.5pp a year toward 50%.
A25: C. Discovery Mode commission on recording royalties in DM contexts - d
A26: Bear | B26: % of royalty | C26: 0.3 | D26: 0.3 | E26: 0.3 | F26: 0.3 | G26: 0.3 | H26: 0.3 | I26: 0.3 | J26: 0.25 | K26: 0.25 | L26: 0.25
A27: Base | B27: % of royalty | C27: 0.3 | D27: 0.3 | E27: 0.3 | F27: 0.3 | G27: 0.3 | H27: 0.3 | I27: 0.3 | J27: 0.3 | K27: 0.3 | L27: 0.3
A28: Bull | B28: % of royalty | C28: 0.3 | D28: 0.3 | E28: 0.3 | F28: 0.3 | G28: 0.3 | H28: 0.3 | I28: 0.3 | J28: 0.3 | K28: 0.3 | L28: 0.3
A29: Selected scenario | B29: % of royalty | C29: =CHOOSE($B$4,C26,C27,C28) -> 0.3 | D29: =CHOOSE($B$4,D26,D27,D28) -> 0.3 | E29: =CHOOSE($B$4,E26,E27,E28) -> 0.3 | F29: =CHOOSE($B$4,F26,F27,F28) -> 0.3 | G29: =CHOOSE($B$4,G26,G27,G28) -> 0.3 | H29: =CHOOSE($B$4,H26,H27,H28) -> 0.3 | I29: =CHOOSE($B$4,I26,I27,I28) -> 0.3 | J29: =CHOOSE($B$4,J26,J27,J28) -> 0.3 | ... L29: =CHOOSE($B$4,L26,L27,L28) -> 0.3
A30: Spotify for Artists: 'A 30% commission is applied to recording royalties generated from all streams of selected songs ... in Discovery Mode contexts.' Unchanged under the Sept 2025 terms. Bear cuts it to 25% from FY2028 for regulatory or litigation pressure (House Judiciary letters 2021-22; Capolongo class action Nov 2025).
A32: D. Revenue build inputs (placeholder; paste your own revenue in row 40 to override)
A33: Premium subscribers, year end | B33: m | C33: 180 | D33: 205 | E33: 236 | F33: 263 | G33: 290 | H33: =G33+H34 -> 318 | I33: =H33+I34 -> 344 | J33: =I33+J34 -> 368 | K33: =J33+K34 -> 390 | L33: =K33+L34 -> 410
A34: Net subscriber additions | B34: m | H34: 28 | I34: 26 | J34: 24 | K34: 22 | L34: 20
A35: Premium ARPU (monthly) | B35: EUR | C35: 4.29 | D35: 4.52 | E35: 4.39 | F35: 4.69 | G35: 4.63 | H35: =G35*(1+H36) -> 4.88465 | I35: =H35*(1+I36) -> 5.080036 | J35: =I35*(1+J36) -> 5.2832374 | K35: =J35*(1+K36) -> 5.4681508 | L35: =K35*(1+L36) -> 5.659536
A36: ARPU growth | B36: % | H36: 0.055 | I36: 0.04 | J36: 0.04 | K36: 0.035 | L36: 0.035
A37: Premium revenue, reported | B37: EUR m | C37: 8460 | D37: 10251 | E37: 11566 | F37: 13819 | G37: 15350
A38: Ad-Supported revenue, reported / growth | B38: EUR m | C38: 1208 | D38: 1476 | E38: 1681 | F38: 1854 | G38: 1836
A39: Ad-Supported revenue growth | B39: % | H39: 0.02 | I39: 0.05 | J39: 0.05 | K39: 0.05 | L39: 0.05
A40: Total revenue OVERRIDE (paste your revenue build here; blank = use placeholder) | B40: EUR m
A41: Cost of revenue, reported | B41: EUR m | C41: 7077 | D41: 8801 | E41: 9849 | F41: 10955 | G41: 11690
A42: History from 20-F filings (FY2021-FY2025); see Financials sheet. FY2026 run-rate check: H1 2026 revenue EUR 9.31bn, Q3 2026 guide ~EUR 5.0bn. The placeholder build is deliberately simple; the model only needs a revenue line to turn the DM % into EUR.
A44: E. Gross margin EXCLUDING Discovery Mode, forecast
A45: Ex-DM gross margin change y/y (applied to the derived FY2025 ex-DM base) | B45: bp | H45: 50 | I45: 50 | J45: 50 | K45: 50 | L45: 50
A46: Ex-DM gross margin OVERRIDE (paste your model's ex-DM margin level; blank = FY2025 base + steps) | B46: % of revenue
A47: History ex-DM is derived on the Revenue & GM sheet (reported margin less the DM contribution), so it re-bases automatically when the DM level changes. Everything above DM in the margin stack (podcast turnaround, bundle mechanicals, price floors, Marquee, delivery costs) belongs here.
...

Sheet Revenue & GM
A1: Revenue build and gross margin bridge (selected scenario)
A2: Green = link to another sheet; black = formula. Reported gross margin = margin ex-DM + Discovery Mode contribution.
A4: EUR m unless stated | B4: Unit | C4: FY2021A | D4: FY2022A | E4: FY2023A | F4: FY2024A | G4: FY2025A | H4: FY2026E | I4: FY2027E | J4: FY2028E | K4: FY2029E | L4: FY2030E
A5: Revenue
A6: Premium subscribers, year end | B6: m | C6: =Inputs!C33 -> 180 | D6: =Inputs!D33 -> 205 | E6: =Inputs!E33 -> 236 | F6: =Inputs!F33 -> 263 | G6: =Inputs!G33 -> 290 | H6: =Inputs!H33 -> 318 | I6: =Inputs!I33 -> 344 | J6: =Inputs!J33 -> 368 | ... L6: =Inputs!L33 -> 410
A7: Average subscribers | B7: m | D7: =(C6+D6)/2 -> 192.5 | E7: =(D6+E6)/2 -> 220.5 | F7: =(E6+F6)/2 -> 249.5 | G7: =(F6+G6)/2 -> 276.5 | H7: =(G6+H6)/2 -> 304 | I7: =(H6+I6)/2 -> 331 | J7: =(I6+J6)/2 -> 356 | K7: =(J6+K6)/2 -> 379 | L7: =(K6+L6)/2 -> 400
A8: Premium ARPU (monthly) | B8: EUR | C8: =Inputs!C35 -> 4.29 | D8: =Inputs!D35 -> 4.52 | E8: =Inputs!E35 -> 4.39 | F8: =Inputs!F35 -> 4.69 | G8: =Inputs!G35 -> 4.63 | H8: =Inputs!H35 -> 4.88465 | I8: =Inputs!I35 -> 5.080036 | J8: =Inputs!J35 -> 5.2832374 | ... L8: =Inputs!L35 -> 5.659536
A9: Premium revenue | B9: EUR m | C9: =Inputs!C37 -> 8460 | D9: =Inputs!D37 -> 10251 | E9: =Inputs!E37 -> 11566 | F9: =Inputs!F37 -> 13819 | G9: =Inputs!G37 -> 15350 | H9: =H7*H8*12 -> 17819.203 | I9: =I7*I8*12 -> 20177.903 | J9: =J7*J8*12 -> 22569.99 | K9: =K7*K8*12 -> 24869.15 | L9: =L7*L8*12 -> 27165.773
A10: Ad-Supported revenue | B10: EUR m | C10: =Inputs!C38 -> 1208 | D10: =Inputs!D38 -> 1476 | E10: =Inputs!E38 -> 1681 | F10: =Inputs!F38 -> 1854 | G10: =Inputs!G38 -> 1836 | H10: =G10*(1+Inputs!H39) -> 1872.72 | I10: =H10*(1+Inputs!I39) -> 1966.356 | J10: =I10*(1+Inputs!J39) -> 2064.6738 | K10: =J10*(1+Inputs!K39) -> 2167.9075 | L10: =K10*(1+Inputs!L39) -> 2276.3029
A11: Total revenue, placeholder build | B11: EUR m | C11: =C9+C10 -> 9668 | D11: =D9+D10 -> 11727 | E11: =E9+E10 -> 13247 | F11: =F9+F10 -> 15673 | G11: =G9+G10 -> 17186 | H11: =H9+H10 -> 19691.923 | I11: =I9+I10 -> 22144.259 | J11: =J9+J10 -> 24634.664 | ... L11: =L9+L10 -> 29442.076
A12: Total revenue override (from Inputs row 40) | B12: EUR m | H12: =IF(Inputs!H40="","",Inputs!H40) | I12: =IF(Inputs!I40="","",Inputs!I40) | J12: =IF(Inputs!J40="","",Inputs!J40) | K12: =IF(Inputs!K40="","",Inputs!K40) | L12: =IF(Inputs!L40="","",Inputs!L40)
A13: Total revenue USED | B13: EUR m | C13: =C11 -> 9668 | D13: =D11 -> 11727 | E13: =E11 -> 13247 | F13: =F11 -> 15673 | G13: =G11 -> 17186 | H13: =IF(H12="",H11,H12) -> 19691.923 | I13: =IF(I12="",I11,I12) -> 22144.259 | J13: =IF(J12="",J11,J12) -> 24634.664 | K13: =IF(K12="",K11,K12) -> 27037.057 | L13: =IF(L12="",L11,L12) -> 29442.076
A14: growth | B14: % | D14: =D13/C13-1 -> 0.21297062 | E14: =E13/D13-1 -> 0.12961542 | F14: =F13/E13-1 -> 0.1831358 | G14: =G13/F13-1 -> 0.096535443 | H14: =H13/G13-1 -> 0.14581189 | I14: =I13/H13-1 -> 0.12453511 | J14: =J13/I13-1 -> 0.11246279 | K14: =K13/J13-1 -> 0.097520833 | L14: =L13/K13-1 -> 0.08895268
A16: Reported cost base (history)
A17: Cost of revenue, reported | B17: EUR m | C17: =Inputs!C41 -> 7077 | D17: =Inputs!D41 -> 8801 | E17: =Inputs!E41 -> 9849 | F17: =Inputs!F41 -> 10955 | G17: =Inputs!G41 -> 11690
A18: Gross profit, reported | B18: EUR m | C18: =C13-C17 -> 2591 | D18: =D13-D17 -> 2926 | E18: =E13-E17 -> 3398 | F18: =F13-F17 -> 4718 | G18: =G13-G17 -> 5496
A19: Gross margin, reported | B19: % | C19: =C18/C13 -> 0.26799752 | D19: =D18/D13 -> 0.24950968 | E19: =E18/E13 -> 0.25651091 | F19: =F18/F13 -> 0.30102724 | G19: =G18/G13 -> 0.31979518
A21: Gross margin bridge
A22: Discovery Mode contribution (selected scenario) | B22: % of revenue | C22: ='DM build'!C51 -> 0.0049648324 | D22: ='DM build'!D51 -> 0.0096475727 | E22: ='DM build'!E51 -> 0.015701668 | F22: ='DM build'!F51 -> 0.021655794 | G22: ='DM build'!G51 -> 0.029791691 | H22: ='DM build'!H51 -> 0.030253715 | I22: ='DM build'!I51 -> 0.030730643 | J22: ='DM build'!J51 -> 0.031222475 | ... L22: ='DM build'!L51 -> 0.032250851
A23: Gross margin ex-Discovery Mode | B23: % | C23: =C19-C22 -> 0.26303269 | D23: =D19-D22 -> 0.23986211 | E23: =E19-E22 -> 0.24080924 | F23: =F19-F22 -> 0.27937145 | G23: =G19-G22 -> 0.29000349 | H23: =IF(Inputs!H46="",G23+Inputs!H45/10000,Inputs!H46) -> 0.29500349 | I23: =IF(Inputs!I46="",H23+Inputs!I45/10000,Inputs!I46) -> 0.30000349 | J23: =IF(Inputs!J46="",I23+Inputs!J45/10000,Inputs!J46) -> 0.30500349 | K23: =IF(Inputs!K46="",J23+Inputs!K45/10000,Inputs!K46) -> 0.31000349 | L23: =IF(Inputs!L46="",K23+Inputs!L45/10000,Inputs!L46) -> 0.31500349
A24: Gross margin (reported history / forecast) | B24: % | C24: =C19 -> 0.26799752 | D24: =D19 -> 0.24950968 | E24: =E19 -> 0.25651091 | F24: =F19 -> 0.30102724 | G24: =G19 -> 0.31979518 | H24: =H23+H22 -> 0.32525721 | I24: =I23+I22 -> 0.33073413 | J24: =J23+J22 -> 0.33622597 | K24: =K23+K22 -> 0.3417327 | L24: =L23+L22 -> 0.34725434
A25: Gross profit | B25: EUR m | C25: =C18 -> 2591 | D25: =D18 -> 2926 | E25: =E18 -> 3398 | F25: =F18 -> 4718 | G25: =G18 -> 5496 | H25: =H13*H24 -> 6404.9399 | I25: =I13*I24 -> 7323.8623 | J25: =J13*J24 -> 8282.8138 | K25: =K13*K24 -> 9239.4466 | L25: =L13*L24 -> 10223.889
A26: Cost of revenue | B26: EUR m | C26: =C17 -> 7077 | D26: =D17 -> 8801 | E26: =E17 -> 9849 | F26: =F17 -> 10955 | G26: =G17 -> 11690 | H26: =H13-H25 -> 13286.983 | I26: =I13-I25 -> 14820.397 | J26: =J13-J25 -> 16351.85 | K26: =K13-K25 -> 17797.611 | L26: =L13-L25 -> 19218.187
A27: of which Discovery Mode commission retained (gross profit from DM) | B27: EUR m | C27: =C22*C13 -> 48 | D27: =D22*D13 -> 113.13708 | E27: =E22*E13 -> 208 | F27: =F22*F13 -> 339.41125 | G27: =G22*G13 -> 512 | H27: =H22*H13 -> 595.75383 | I27: =I22*I13 -> 680.50732 | J27: =J22*J13 -> 769.15518 | ... L27: =L22*L13 -> 949.532
A28: Discovery Mode contribution | B28: bp of GM | C28: =C22*10000 -> 49.648324 | D28: =D22*10000 -> 96.475727 | E28: =E22*10000 -> 157.01668 | F28: =F22*10000 -> 216.55794 | G28: =G22*10000 -> 297.91691 | H28: =H22*10000 -> 302.53715 | I28: =I22*10000 -> 307.30643 | J28: =J22*10000 -> 312.22475 | ... L28: =L22*10000 -> 322.50851
A29: Change in DM contribution, y/y | B29: bp | D29: =D28-C28 -> 46.827403 | E29: =E28-D28 -> 60.540956 | F29: =F28-E28 -> 59.541254 | G29: =G28-F28 -> 81.358972 | H29: =H28-G28 -> 4.62024 | I29: =I28-H28 -> 4.76928 | J29: =J28-I28 -> 4.91832 | K29: =K28-J28 -> 5.06736 | L29: =L28-K28 -> 5.2164
A31: History check: how much of the FY2021-FY2025 margin expansion can Discovery Mode explain?
A32: Reported gross margin expansion FY2021 -> FY2025 | B32: bp | C32: =(G24-C24)*10000 -> 517.97665
A33: Discovery Mode contribution change FY2021 -> FY2025 | B33: bp | C33: =G28-C28 -> 248.26858
A34: Share of the expansion explained by Discovery Mode | B34: % | C34: =C33/C32 -> 0.47930459
A35: Cross-check: Investor Day 2026 said 'about a third of the gross margin expansion came from the music business' (music = price/mix, marketplace incl. DM, bundle mechanicals).
A36: Share of the music-driven third explained by Discovery Mode | B36: % | C36: =C34/(1/3) -> 1.4379138
A38: FY2030 check against management targets
A39: FY2030 gross margin, this model (selected scenario + your ex-DM path) | B39: % | C39: =L24 -> 0.34725434
A40: Investor Day 21 May 2026 target range, FY2030 | B40: % | C40: 0.35 | D40: 0.4

Sheet DM build
A1: Discovery Mode gross margin build, all three scenarios
A2: DM saving as % of revenue = s_ctx x s_dm x d x r_rec x m, using the CALIBRATED s_ctx and s_dm from Inputs section F (anchored to Marketplace gross profit unless calibration mode = 0). Spotify retains the commission (20-F: cost of revenue 'reflects discounts provided by certain rights holders in return for promotional activities in connection with marketplace programs').
A4: EUR m unless stated | B4: Unit | C4: FY2021A | D4: FY2022A | E4: FY2023A | F4: FY2024A | G4: FY2025A | H4: FY2026E | I4: FY2027E | J4: FY2028E | K4: FY2029E | L4: FY2030E
A6: Bear scenario
A7: DM-eligible context share of music streams (s_ctx) | B7: % of music streams | C7: =Inputs!C66 -> 0.6662416 | D7: =Inputs!D66 -> 0.64731432 | E7: =Inputs!E66 -> 0.52676021 | F7: =Inputs!F66 -> 0.51893532 | G7: =Inputs!G66 -> 0.60572901 | H7: =Inputs!H66 -> 0.62790658 | I7: =Inputs!I66 -> 0.65230191 | J7: =Inputs!J66 -> 0.67926517 | ... L7: =Inputs!L66 -> 0.74270813
A8: DM-enrolled share of context streams (s_dm) | B8: % of context streams | C8: =Inputs!C72 -> 0.05 | D8: =Inputs!D72 -> 0.1 | E8: =Inputs!E72 -> 0.2 | F8: =Inputs!F72 -> 0.28 | G8: =Inputs!G72 -> 0.33 | H8: =Inputs!H72 -> 0.315 | I8: =Inputs!I72 -> 0.3 | J8: =Inputs!J72 -> 0.285 | ... L8: =Inputs!L72 -> 0.255
A9: Discovery Mode streams as % of all music streams | B9: % of music streams | C9: =C7*C8 -> 0.03331208 | D9: =D7*D8 -> 0.064731432 | E9: =E7*E8 -> 0.10535204 | F9: =F7*F8 -> 0.14530189 | G9: =G7*G8 -> 0.19989057 | H9: =H7*H8 -> 0.19779057 | I9: =I7*I8 -> 0.19569057 | J9: =J7*J8 -> 0.19359057 | ... L9: =L7*L8 -> 0.18939057
A10: Commission on recording royalties (d) | B10: % of royalty | C10: =Inputs!C26 -> 0.3 | D10: =Inputs!D26 -> 0.3 | E10: =Inputs!E26 -> 0.3 | F10: =Inputs!F26 -> 0.3 | G10: =Inputs!G26 -> 0.3 | H10: =Inputs!H26 -> 0.3 | I10: =Inputs!I26 -> 0.3 | J10: =Inputs!J26 -> 0.25 | ... L10: =Inputs!L26 -> 0.25
A11: Recording royalties % of music revenue (r_rec) x music share of revenue (m) | B11: % of total rev | C11: =Inputs!$C$8*Inputs!$C$9 -> 0.4968 | D11: =Inputs!$C$8*Inputs!$C$9 -> 0.4968 | E11: =Inputs!$C$8*Inputs!$C$9 -> 0.4968 | F11: =Inputs!$C$8*Inputs!$C$9 -> 0.4968 | G11: =Inputs!$C$8*Inputs!$C$9 -> 0.4968 | H11: =Inputs!$C$8*Inputs!$C$9 -> 0.4968 | I11: =Inputs!$C$8*Inputs!$C$9 -> 0.4968 | J11: =Inputs!$C$8*Inputs!$C$9 -> 0.4968 | ... L11: =Inputs!$C$8*Inputs!$C$9 -> 0.4968
A12: DM saving as % of total revenue | B12: % of total rev | C12: =C9*C10*C11 -> 0.0049648324 | D12: =D9*D10*D11 -> 0.0096475727 | E12: =E9*E10*E11 -> 0.015701668 | F12: =F9*F10*F11 -> 0.021655794 | G12: =G9*G10*G11 -> 0.029791691 | H12: =H9*H10*H11 -> 0.029478707 | I12: =I9*I10*I11 -> 0.029165723 | J12: =J9*J10*J11 -> 0.024043949 | ... L12: =L9*L10*L11 -> 0.023522309
A13: Total revenue used | B13: EUR m | C13: ='Revenue & GM'!C13 -> 9668 | D13: ='Revenue & GM'!D13 -> 11727 | E13: ='Revenue & GM'!E13 -> 13247 | F13: ='Revenue & GM'!F13 -> 15673 | G13: ='Revenue & GM'!G13 -> 17186 | H13: ='Revenue & GM'!H13 -> 19691.923 | I13: ='Revenue & GM'!I13 -> 22144.259 | J13: ='Revenue & GM'!J13 -> 24634.664 | ... L13: ='Revenue & GM'!L13 -> 29442.076
A14: Discovery Mode gross profit | B14: EUR m | C14: =C12*C13 -> 48 | D14: =D12*D13 -> 113.13708 | E14: =E12*E13 -> 208 | F14: =F12*F13 -> 339.41125 | G14: =G12*G13 -> 512 | H14: =H12*H13 -> 580.49243 | I14: =I12*I13 -> 645.85332 | J14: =J12*J13 -> 592.31461 | ... L14: =L12*L13 -> 692.54561
A15: Gross margin contribution | B15: bp | C15: =C12*10000 -> 49.648324 | D15: =D12*10000 -> 96.475727 | E15: =E12*10000 -> 157.01668 | F15: =F12*10000 -> 216.55794 | G15: =G12*10000 -> 297.91691 | H15: =H12*10000 -> 294.78707 | I15: =I12*10000 -> 291.65723 | J15: =J12*10000 -> 240.43949 | ... L15: =L12*10000 -> 235.22309
A16: change y/y | B16: bp | D16: =D15-C15 -> 46.827403 | E16: =E15-D15 -> 60.540956 | F16: =F15-E15 -> 59.541254 | G16: =G15-F15 -> 81.358972 | H16: =H15-G15 -> -3.12984 | I16: =I15-H15 -> -3.12984 | J16: =J15-I15 -> -51.217738 | K16: =K15-J15 -> -2.6082 | L16: =L15-K15 -> -2.6082
A19: Base scenario
A20: DM-eligible context share of music streams (s_ctx) | B20: % of music streams | C20: =Inputs!C67 -> 0.6662416 | D20: =Inputs!D67 -> 0.64731432 | E20: =Inputs!E67 -> 0.52676021 | F20: =Inputs!F67 -> 0.51893532 | G20: =Inputs!G67 -> 0.60572901 | H20: =Inputs!H67 -> 0.5970311 | I20: =Inputs!I67 -> 0.58911592 | J20: =Inputs!J67 -> 0.58191826 | ... L20: =Inputs!L67 -> 0.56944887
A21: DM-enrolled share of context streams (s_dm) | B21: % of context streams | C21: =Inputs!C73 -> 0.05 | D21: =Inputs!D73 -> 0.1 | E21: =Inputs!E73 -> 0.2 | F21: =Inputs!F73 -> 0.28 | G21: =Inputs!G73 -> 0.33 | H21: =Inputs!H73 -> 0.34 | I21: =Inputs!I73 -> 0.35 | J21: =Inputs!J73 -> 0.36 | ... L21: =Inputs!L73 -> 0.38
A22: Discovery Mode streams as % of all music streams | B22: % of music streams | C22: =C20*C21 -> 0.03331208 | D22: =D20*D21 -> 0.064731432 | E22: =E20*E21 -> 0.10535204 | F22: =F20*F21 -> 0.14530189 | G22: =G20*G21 -> 0.19989057 | H22: =H20*H21 -> 0.20299057 | I22: =I20*I21 -> 0.20619057 | J22: =J20*J21 -> 0.20949057 | ... L22: =L20*L21 -> 0.21639057
A23: Commission on recording royalties (d) | B23: % of royalty | C23: =Inputs!C27 -> 0.3 | D23: =Inputs!D27 -> 0.3 | E23: =Inputs!E27 -> 0.3 | F23: =Inputs!F27 -> 0.3 | G23: =Inputs!G27 -> 0.3 | H23: =Inputs!H27 -> 0.3 | I23: =Inputs!I27 -> 0.3 | J23: =Inputs!J27 -> 0.3 | ... L23: =Inputs!L27 -> 0.3
A24: Recording royalties % of music revenue (r_rec) x music share of revenue (m) | B24: % of total rev | C24: =Inputs!$C$8*Inputs!$C$9 -> 0.4968 | D24: =Inputs!$C$8*Inputs!$C$9 -> 0.4968 | E24: =Inputs!$C$8*Inputs!$C$9 -> 0.4968 | F24: =Inputs!$C$8*Inputs!$C$9 -> 0.4968 | G24: =Inputs!$C$8*Inputs!$C$9 -> 0.4968 | H24: =Inputs!$C$8*Inputs!$C$9 -> 0.4968 | I24: =Inputs!$C$8*Inputs!$C$9 -> 0.4968 | J24: =Inputs!$C$8*Inputs!$C$9 -> 0.4968 | ... L24: =Inputs!$C$8*Inputs!$C$9 -> 0.4968
A25: DM saving as % of total revenue | B25: % of total rev | C25: =C22*C23*C24 -> 0.0049648324 | D25: =D22*D23*D24 -> 0.0096475727 | E25: =E22*E23*E24 -> 0.015701668 | F25: =F22*F23*F24 -> 0.021655794 | G25: =G22*G23*G24 -> 0.029791691 | H25: =H22*H23*H24 -> 0.030253715 | I25: =I22*I23*I24 -> 0.030730643 | J25: =J22*J23*J24 -> 0.031222475 | ... L25: =L22*L23*L24 -> 0.032250851
A26: Total revenue used | B26: EUR m | C26: ='Revenue & GM'!C13 -> 9668 | D26: ='Revenue & GM'!D13 -> 11727 | E26: ='Revenue & GM'!E13 -> 13247 | F26: ='Revenue & GM'!F13 -> 15673 | G26: ='Revenue & GM'!G13 -> 17186 | H26: ='Revenue & GM'!H13 -> 19691.923 | I26: ='Revenue & GM'!I13 -> 22144.259 | J26: ='Revenue & GM'!J13 -> 24634.664 | ... L26: ='Revenue & GM'!L13 -> 29442.076
A27: Discovery Mode gross profit | B27: EUR m | C27: =C25*C26 -> 48 | D27: =D25*D26 -> 113.13708 | E27: =E25*E26 -> 208 | F27: =F25*F26 -> 339.41125 | G27: =G25*G26 -> 512 | H27: =H25*H26 -> 595.75383 | I27: =I25*I26 -> 680.50732 | J27: =J25*J26 -> 769.15518 | ... L27: =L25*L26 -> 949.532
A28: Gross margin contribution | B28: bp | C28: =C25*10000 -> 49.648324 | D28: =D25*10000 -> 96.475727 | E28: =E25*10000 -> 157.01668 | F28: =F25*10000 -> 216.55794 | G28: =G25*10000 -> 297.91691 | H28: =H25*10000 -> 302.53715 | I28: =I25*10000 -> 307.30643 | J28: =J25*10000 -> 312.22475 | ... L28: =L25*10000 -> 322.50851
A29: change y/y | B29: bp | D29: =D28-C28 -> 46.827403 | E29: =E28-D28 -> 60.540956 | F29: =F28-E28 -> 59.541254 | G29: =G28-F28 -> 81.358972 | H29: =H28-G28 -> 4.62024 | I29: =I28-H28 -> 4.76928 | J29: =J28-I28 -> 4.91832 | K29: =K28-J28 -> 5.06736 | L29: =L28-K28 -> 5.2164
A32: Bull scenario
A33: DM-eligible context share of music streams (s_ctx) | B33: % of music streams | C33: =Inputs!C68 -> 0.6662416 | D33: =Inputs!D68 -> 0.64731432 | E33: =Inputs!E68 -> 0.52676021 | F33: =Inputs!F68 -> 0.51893532 | G33: =Inputs!G68 -> 0.60572901 | H33: =Inputs!H68 -> 0.58911592 | I33: =Inputs!I68 -> 0.54741994 | J33: =Inputs!J68 -> 0.53778148 | ... L33: =Inputs!L68 -> 0.52738114
A34: DM-enrolled share of context streams (s_dm) | B34: % of context streams | C34: =Inputs!C74 -> 0.05 | D34: =Inputs!D74 -> 0.1 | E34: =Inputs!E74 -> 0.2 | F34: =Inputs!F74 -> 0.28 | G34: =Inputs!G74 -> 0.33 | H34: =Inputs!H74 -> 0.35 | I34: =Inputs!I74 -> 0.43 | J34: =Inputs!J74 -> 0.455 | ... L34: =Inputs!L74 -> 0.5
A35: Discovery Mode streams as % of all music streams | B35: % of music streams | C35: =C33*C34 -> 0.03331208 | D35: =D33*D34 -> 0.064731432 | E35: =E33*E34 -> 0.10535204 | F35: =F33*F34 -> 0.14530189 | G35: =G33*G34 -> 0.19989057 | H35: =H33*H34 -> 0.20619057 | I35: =I33*I34 -> 0.23539057 | J35: =J33*J34 -> 0.24469057 | ... L35: =L33*L34 -> 0.26369057
A36: Commission on recording royalties (d) | B36: % of royalty | C36: =Inputs!C28 -> 0.3 | D36: =Inputs!D28 -> 0.3 | E36: =Inputs!E28 -> 0.3 | F36: =Inputs!F28 -> 0.3 | G36: =Inputs!G28 -> 0.3 | H36: =Inputs!H28 -> 0.3 | I36: =Inputs!I28 -> 0.3 | J36: =Inputs!J28 -> 0.3 | ... L36: =Inputs!L28 -> 0.3
A37: Recording royalties % of music revenue (r_rec) x music share of revenue (m) | B37: % of total rev | C37: =Inputs!$C$8*Inputs!$C$9 -> 0.4968 | D37: =Inputs!$C$8*Inputs!$C$9 -> 0.4968 | E37: =Inputs!$C$8*Inputs!$C$9 -> 0.4968 | F37: =Inputs!$C$8*Inputs!$C$9 -> 0.4968 | G37: =Inputs!$C$8*Inputs!$C$9 -> 0.4968 | H37: =Inputs!$C$8*Inputs!$C$9 -> 0.4968 | I37: =Inputs!$C$8*Inputs!$C$9 -> 0.4968 | J37: =Inputs!$C$8*Inputs!$C$9 -> 0.4968 | ... L37: =Inputs!$C$8*Inputs!$C$9 -> 0.4968
A38: DM saving as % of total revenue | B38: % of total rev | C38: =C35*C36*C37 -> 0.0049648324 | D38: =D35*D36*D37 -> 0.0096475727 | E38: =E35*E36*E37 -> 0.015701668 | F38: =F35*F36*F37 -> 0.021655794 | G38: =G35*G36*G37 -> 0.029791691 | H38: =H35*H36*H37 -> 0.030730643 | I38: =I35*I36*I37 -> 0.035082611 | J38: =J35*J36*J37 -> 0.036468683 | ... L38: =L35*L36*L37 -> 0.039300443
A39: Total revenue used | B39: EUR m | C39: ='Revenue & GM'!C13 -> 9668 | D39: ='Revenue & GM'!D13 -> 11727 | E39: ='Revenue & GM'!E13 -> 13247 | F39: ='Revenue & GM'!F13 -> 15673 | G39: ='Revenue & GM'!G13 -> 17186 | H39: ='Revenue & GM'!H13 -> 19691.923 | I39: ='Revenue & GM'!I13 -> 22144.259 | J39: ='Revenue & GM'!J13 -> 24634.664 | ... L39: ='Revenue & GM'!L13 -> 29442.076
A40: Discovery Mode gross profit | B40: EUR m | C40: =C38*C39 -> 48 | D40: =D38*D39 -> 113.13708 | E40: =E38*E39 -> 208 | F40: =F38*F39 -> 339.41125 | G40: =G38*G39 -> 512 | H40: =H38*H39 -> 605.14546 | I40: =I38*I39 -> 776.87842 | J40: =J38*J39 -> 898.39376 | ... L40: =L38*L39 -> 1157.0866
A41: Gross margin contribution | B41: bp | C41: =C38*10000 -> 49.648324 | D41: =D38*10000 -> 96.475727 | E41: =E38*10000 -> 157.01668 | F41: =F38*10000 -> 216.55794 | G41: =G38*10000 -> 297.91691 | H41: =H38*10000 -> 307.30643 | I41: =I38*10000 -> 350.82611 | J41: =J38*10000 -> 364.68683 | ... L41: =L38*10000 -> 393.00443
A42: change y/y | B42: bp | D42: =D41-C41 -> 46.827403 | E42: =E41-D41 -> 60.540956 | F42: =F41-E41 -> 59.541254 | G42: =G41-F41 -> 81.358972 | H42: =H41-G41 -> 9.38952 | I42: =I41-H41 -> 43.51968 | J42: =J41-I41 -> 13.86072 | K42: =K41-J41 -> 14.60592 | L42: =L41-K41 -> 13.71168
A45: Selected scenario (feeds Revenue & GM) | C45: =CHOOSE(Inputs!$B$4,"Bear","Base","Bull") -> Base
A46: DM-eligible context share of music streams (s_ctx) | B46: % of music streams | C46: =Inputs!C69 -> 0.6662416 | D46: =Inputs!D69 -> 0.64731432 | E46: =Inputs!E69 -> 0.52676021 | F46: =Inputs!F69 -> 0.51893532 | G46: =Inputs!G69 -> 0.60572901 | H46: =Inputs!H69 -> 0.5970311 | I46: =Inputs!I69 -> 0.58911592 | J46: =Inputs!J69 -> 0.58191826 | ... L46: =Inputs!L69 -> 0.56944887
A47: DM-enrolled share of context streams (s_dm) | B47: % of context streams | C47: =Inputs!C75 -> 0.05 | D47: =Inputs!D75 -> 0.1 | E47: =Inputs!E75 -> 0.2 | F47: =Inputs!F75 -> 0.28 | G47: =Inputs!G75 -> 0.33 | H47: =Inputs!H75 -> 0.34 | I47: =Inputs!I75 -> 0.35 | J47: =Inputs!J75 -> 0.36 | ... L47: =Inputs!L75 -> 0.38
A48: Discovery Mode streams as % of all music streams | B48: % of music streams | C48: =C46*C47 -> 0.03331208 | D48: =D46*D47 -> 0.064731432 | E48: =E46*E47 -> 0.10535204 | F48: =F46*F47 -> 0.14530189 | G48: =G46*G47 -> 0.19989057 | H48: =H46*H47 -> 0.20299057 | I48: =I46*I47 -> 0.20619057 | J48: =J46*J47 -> 0.20949057 | ... L48: =L46*L47 -> 0.21639057
...

Sheet Triangulation
A1: Triangulating the two unknowns: s_ctx (context share) and s_dm (DM share of context)
A2: Spotify has never disclosed either figure. Every row below is a public data point and what it bounds; the selection at the bottom of each section feeds Inputs.
A4: A. What share of music streams happens in Discovery Mode contexts (Radio, Autoplay, Mixes)?
A5: Source | B5: Date | C5: Figure (as published) | D5: Scope and what it implies for DM contexts | E5: Implied low | F5: Implied high | G5: Weight
A6: Spotify F-1 prospectus | B6: Feb 2018 | C6: 'We now program approximately 31% of all listening on Spotify across these and other playlists, compared to less than 20% two years ago.' | D6: All listening; editorial + algorithmic playlists. DM contexts are a subset of programmed listening, so 31% is a ceiling for all programmed, not a DM-context estimate. | E6: 0.08 | F6: 0.2 | G6: Bound
A7: Spotify for Artists, 'Made to Be Found' | B7: 26 Jan 2022 | C7: 'The majority of streams' come from active sessions; 'more than half of new artist discoveries happen in programmed playlists - with over a quarter coming from Spotify Mixes, Radio, and Autoplay.' | D7: Programmed streams < 50%. The 'over a quarter' is a share of discoveries, which skew to algorithmic contexts, so the stream share of Mixes/Radio/Autoplay is below 25%. | E7: 0.08 | F7: 0.22 | G7: Bound
A8: Your Music Marketing sample, via Music Ally | B8: Feb 2024 | C8: 25.3bn streams, several hundred artists: 18.7% of streams from 'algorithmic playlists and mixes' (radio, Daily Mix, Discover Weekly, Release Radar, On Repeat, Repeat Rewind); 'just over 21%' in the last 12 months. | D8: Includes Discover Weekly / Release Radar / On Repeat (not DM contexts); Autoplay treatment unspecified. Stripping the non-DM playlists and adding Autoplay lands around 10-16%. Sample skews to marketed artists. | E8: 0.1 | F8: 0.16 | G8: Primary
A9: Anderson et al. (Spotify Research) WWW 2020; Bello & Garcia 2021 | B9: 2020-21 | C9: 'According to Spotify, up to one-fifth of their streams can be attributed to algorithmic recommendations.' | D9: All algorithmic recommendations, c.2019-20, before Mixes were DM contexts. Upper bound ~20% for everything algorithmic at that time. | E9: 0.08 | F9: 0.2 | G9: Bound
A10: r/musicmarketing corpus (this project) | B10: 2023-26 | C10: DM-context streams as % of enrolled artists' monthly streams: 3.5%, 3.9%, 4.0%, 5.0% (artists with 500k+ monthly streams); 10%; 33%; 33%; 50% (catalog-heavy, best month). Median 7.5%, n = 8. | D10: Indie artists only. Understated where only some songs are enrolled; overstated by the DM boost. Suggests big indie acts sit in single digits while catalog-heavy acts can be a third. | E10: 0.04 | F10: 0.33 | G10: Cross-check
A11: Spotify for Artists, Campaign Kit blog | B11: 2024-25 | C11: 'In 2024, 35% of all discoveries ... [happened] in algorithmic contexts'; '16 billion artist discoveries every month, a third via algorithmic contexts' (2020). | D11: Discoveries, not streams. Confirms algorithmic contexts are growing in importance but gives no stream share. | G11: Context
A13: Full span of the evidence rows above | E13: =MIN(E6:E11) -> 0.04 | F13: =MAX(F6:F11) -> 0.33
A14: Bound and primary rows only (excludes the indie-only Reddit cross-check) | E14: =MAX(E6:E9) -> 0.1 | F14: =MIN(F6:F9) -> 0.16
A15: Primary-source midpoint (Y2M sample, adjusted to DM contexts) | E15: =AVERAGE(E8:F8) -> 0.13
A16: Bookends used for Bear / Bull (FY2025) | E16: 0.09 | F16: 0.2
A17: Selected FY2025 base case (feeds Inputs row 13) | E17: =Inputs!G13 -> 0.14 | F17: Low 9% / high 20% are the Bear-Bull bookends; before Mixes joined (Jan 2024) only Radio + Autoplay counted, modelled at 9-9.5%.
A19: B. What share of DM-context streams is Discovery Mode-enrolled? (cross-check on the 33% assumption)
A20: Logic: enrolled catalog starts with its natural share of context streams (e) and gets boosted b-fold by the DM signal inside a fixed inventory: s_dm = e*b / (e*b + (1 - e)).
A21: Streams from rights holders outside UMG, Sony, WMG and Merlin (FY2025 20-F: the four = ~72%) | D21: 20-F FY2025. These DIY distributors and non-Merlin indies are the catalog Discovery Mode is sold to today. | E21: 0.28
A22: Share of that catalog enrolled, weighted by context streams | D22: Assumption. Self-serve needs 25k+ monthly listeners and 3+ eligible songs; Believe says it moves 'hundreds of thousands of tracks every month' in and out. | E22: 0.45
A23: Add-on: Merlin members and other labels enrolling via Spotify's partnerships team | D23: Assumption (share of context streams). Majors have not opted in as far as public reporting shows. | E23: 0.02
A24: Natural context share of enrolled catalog, e | D24: row 1 x row 2 + row 3 | E24: =E21*E22+E23 -> 0.146
A25: In-context boost from the DM signal, b (campaign lift + 1) | D25: Median Spotify-reported lift across 13 artist screenshots was +214% (discovery_mode_efficacy.xlsx). 2023-24 campaigns: +406%; 2025-26: +78%. | E25: 3.14
A26: Implied s_dm = e*b / (e*b + 1 - e) | D26: Compare with the 33% assumption in Inputs row 20. | E26: =E24*E25/(E24*E25+1-E24) -> 0.34930359
A28: Sensitivity of implied s_dm to enrollment and the boost (what the 'ceiling' question turns on)
A29: Natural context share of enrolled catalog, e ↓ | boost b → | B29: 1.5 | C29: 1.78 | D29: 2 | E29: 2.5 | F29: 3.14 | G29: 4
A30: 0.1 | B30: =$A30*B$29/($A30*B$29+1-$A30) -> 0.14285714 | C30: =$A30*C$29/($A30*C$29+1-$A30) -> 0.16512059 | D30: =$A30*D$29/($A30*D$29+1-$A30) -> 0.18181818 | E30: =$A30*E$29/($A30*E$29+1-$A30) -> 0.2173913 | F30: =$A30*F$29/($A30*F$29+1-$A30) -> 0.25864909 | G30: =$A30*G$29/($A30*G$29+1-$A30) -> 0.30769231
A31: 0.14 | B31: =$A31*B$29/($A31*B$29+1-$A31) -> 0.19626168 | C31: =$A31*C$29/($A31*C$29+1-$A31) -> 0.22466643 | D31: =$A31*D$29/($A31*D$29+1-$A31) -> 0.24561404 | E31: =$A31*E$29/($A31*E$29+1-$A31) -> 0.2892562 | F31: =$A31*F$29/($A31*F$29+1-$A31) -> 0.33825793 | G31: =$A31*G$29/($A31*G$29+1-$A31) -> 0.3943662
A32: 0.17 | B32: =$A32*B$29/($A32*B$29+1-$A32) -> 0.23502304 | C32: =$A32*C$29/($A32*C$29+1-$A32) -> 0.26717288 | D32: =$A32*D$29/($A32*D$29+1-$A32) -> 0.29059829 | E32: =$A32*E$29/($A32*E$29+1-$A32) -> 0.33864542 | F32: =$A32*F$29/($A32*F$29+1-$A32) -> 0.39140636 | G32: =$A32*G$29/($A32*G$29+1-$A32) -> 0.45033113
A33: 0.2 | B33: =$A33*B$29/($A33*B$29+1-$A33) -> 0.27272727 | C33: =$A33*C$29/($A33*C$29+1-$A33) -> 0.30795848 | D33: =$A33*D$29/($A33*D$29+1-$A33) -> 0.33333333 | E33: =$A33*E$29/($A33*E$29+1-$A33) -> 0.38461538 | F33: =$A33*F$29/($A33*F$29+1-$A33) -> 0.43977591 | G33: =$A33*G$29/($A33*G$29+1-$A33) -> 0.5
A34: 0.25 | B34: =$A34*B$29/($A34*B$29+1-$A34) -> 0.33333333 | C34: =$A34*C$29/($A34*C$29+1-$A34) -> 0.37238494 | D34: =$A34*D$29/($A34*D$29+1-$A34) -> 0.4 | E34: =$A34*E$29/($A34*E$29+1-$A34) -> 0.45454545 | F34: =$A34*F$29/($A34*F$29+1-$A34) -> 0.51140065 | G34: =$A34*G$29/($A34*G$29+1-$A34) -> 0.57142857
A35: 0.3 | B35: =$A35*B$29/($A35*B$29+1-$A35) -> 0.39130435 | C35: =$A35*C$29/($A35*C$29+1-$A35) -> 0.43273906 | D35: =$A35*D$29/($A35*D$29+1-$A35) -> 0.46153846 | E35: =$A35*E$29/($A35*E$29+1-$A35) -> 0.51724138 | F35: =$A35*F$29/($A35*F$29+1-$A35) -> 0.57369062 | G35: =$A35*G$29/($A35*G$29+1-$A35) -> 0.63157895
A36: Reading: with ~28% of streams outside the majors and Merlin, e cannot exceed ~30% unless a major opts in, which caps s_dm near 45-57% even at a 2-3x boost. If the per-track boost has faded to the 2025-26 level (b ~1.8), holding 33% needs enrollment closer to 70% of eligible catalog. That is the mechanism behind the Bear case.
A38: C. Marketplace anchor (your view; the inputs live on Inputs sheet, section F)
A39: Marketplace gross profit FY2021 (Investor Day 2022: 'more than EUR 160m') | D39: EUR m | E39: =Inputs!$C$51 -> 160
A40: Multiple by FY2025 (third-party recap of Investor Day 2026: 'about 4x') | E40: =Inputs!$C$52 -> 4
A41: Implied Marketplace gross profit FY2025 | D41: EUR m | E41: =Inputs!$G$53 -> 640
A42: Discovery Mode share of Marketplace gross profit FY2025 (your assumption: at least 80%) | E42: =Inputs!$G$54 -> 0.8
A43: Anchor: Discovery Mode gross profit FY2025 / bp of gross margin | D43: EUR m / bp | E43: =Inputs!$G$55 -> 512 | F43: =Inputs!$G$56*10000 -> 297.91691
A44: DM streams as % of music streams: required by the anchor / as entered in A and B | E44: =Inputs!$G$57 -> 0.19989057 | F44: =Inputs!$G$13*Inputs!$G$20 -> 0.0462
A45: Re-level factor on the product | E45: =Inputs!$G$57/(Inputs!$G$13*Inputs!$G$20) -> 4.3266358
...

Sheet Financials
A1: Spotify reported financials used in the model (EUR m unless stated)
A2: Blue = as reported in 20-F / shareholder letters. Figures marked (v) were derived from disclosed items or search renderings and should be re-checked against the filing tables before external use.
A4: Annual | B4: FY2021 | C4: FY2022 | D4: FY2023 | E4: FY2024 | F4: FY2025 | G4: Source / note
A5: Total revenue | B5: 9668 | C5: 11727 | D5: 13247 | E5: 15673 | F5: 17186 | G5: 20-F FY2021-FY2025 [S1-S4]
A6: Premium revenue | B6: 8460 | C6: 10251 | D6: 11566 | E6: 13819 | F6: 15350 | G6: 20-F; FY2024 (v)
A7: Ad-Supported revenue | B7: 1208 | C7: 1476 | D7: 1681 | E7: 1854 | F7: 1836 | G7: 20-F; FY2024 (v)
A8: Cost of revenue | B8: 7077 | C8: 8801 | D8: 9849 | E8: 10955 | F8: 11690 | G8: 20-F; FY2023-24 derived from reported gross margin (v)
A9: Gross profit | B9: =B5-B8 -> 2591 | C9: =C5-C8 -> 2926 | D9: =D5-D8 -> 3398 | E9: =E5-E8 -> 4718 | F9: =F5-F8 -> 5496 | G9: formula
A10: Gross margin | B10: =B9/B5 -> 0.26799752 | C10: =C9/C5 -> 0.24950968 | D10: =D9/D5 -> 0.25651091 | E10: =E9/E5 -> 0.30102724 | F10: =F9/F5 -> 0.31979518 | G10: formula; reported: 26.8%, 25.0%, 25.6%, 30.1%, 32.0%
A11: Premium gross margin | B11: 0.29 | C11: 0.28 | D11: 0.288 | E11: 0.325 | F11: 0.337 | G11: 20-F; FY2021-22 approx (v)
A12: Ad-Supported gross margin | B12: 0.109 | D12: 0.037 | E12: 0.124 | F12: 0.18 | G12: 20-F; FY2022 not captured
A13: Premium subscribers, year end (m) | B13: 180 | C13: 205 | D13: 236 | E13: 263 | F13: 290 | G13: shareholder letters
A14: Monthly active users, year end (m) | B14: 406 | C14: 489 | D14: 602 | E14: 675 | F14: 751 | G14: shareholder letters
A15: Premium ARPU, monthly (EUR) | B15: 4.29 | C15: 4.52 | D15: 4.39 | E15: 4.69 | F15: 4.63 | G15: shareholder letters; FY2025: FX -0.17, mix -0.14, price +0.25
A16: Streams from UMG, Sony, WMG and Merlin (share) | C16: 0.75 | D16: 0.74 | E16: 0.71 | F16: 0.72 | G16: 20-F risk factors; FY2022 via Music Ally
A18: Quarterly (latest)
A19: Quarter | B19: Revenue | C19: Gross margin | D19: Premium GM | E19: Ad GM | F19: Subs (m) | G19: Source / note
A20: Q1 2025 | B20: 4190 | C20: 0.316 | G20: 6-K, 29 Apr 2025
A21: Q2 2025 | B21: 4190 | C21: 0.315 | G21: 6-K, 29 Jul 2025
A22: Q3 2025 | B22: 4270 | C22: 0.316 | D22: 0.332 | E22: 0.184 | F22: 281 | G22: 6-K, 4 Nov 2025
A23: Q4 2025 | B23: 4530 | C23: 0.331 | F23: 290 | G23: deck, 10 Feb 2026; 'content cost favorability'
A24: Q1 2026 | B24: 4530 | C24: 0.33 | D24: 0.348 | E24: 0.13 | F24: 293 | G24: 6-K, 28 Apr 2026
A25: Q2 2026 | B25: 4780 | C25: 0.334 | D25: 0.349 | E25: 0.191 | F25: 300 | G25: 6-K, Aug 2026; ARPU EUR 4.89 (+7.4% cc)
A26: Q3 2026 guide | B26: 5000 | C26: 0.329 | G26: Q2 2026 letter guidance
A28: Management statements that anchor the mechanism
A29: 20-F FY2024 and FY2025: cost of revenue 'also reflects discounts provided by certain rights holders in return for promotional activities in connection with marketplace programs'.
A30: 20-F FY2025: Premium cost of revenue rose on 'increased rates for certain licensors ... partially offset by benefits from certain marketplace programs'.
A31: Q2 2024 call (Ben Kung): gross margin 'outperformance was driven primarily by music content cost favorability and marketplace'.
A32: Investor Day 8 Jun 2022: Marketplace gross profit 'more than EUR 160m' in 2021 (8x 2018); Discovery Mode revenue +224% y/y with 'over 50 labels and distributors'; marketplace 'the primary factor in growing our music gross margins'.
A33: Investor Day 21 May 2026: FY2030 targets of 35-40% gross margin and >20% operating margin; 'about a third of the gross margin expansion came from the music business'; Marketplace gross profit about 4x 2021 (third-party recap).
A34: MIDiA (2025): 'When a label uses Discovery Mode, Spotify gets an extra 17% of gross margin' on those streams, i.e. the 30% commission on a ~56% recording share.

Sheet Sources
A1: Sources
A2: Collected 2 Oct 2026. Primary documents were read through search-engine renderings because the research environment could not fetch sec.gov and spotify.com directly; re-open before quoting externally.
A4: # | B4: Document | C4: URL
A5: S1 | B5: Spotify 20-F FY2025 | C5: https://www.sec.gov/Archives/edgar/data/1639920/000162828026006874/ck0001639920-20251231.htm
A6: S2 | B6: Spotify 20-F FY2024 | C6: https://www.sec.gov/Archives/edgar/data/1639920/000163992025000003/ck0001639920-20241231.htm
A7: S3 | B7: Spotify 20-F FY2023 | C7: https://www.sec.gov/Archives/edgar/data/1639920/000163992024000004/ck0001639920-20231231.htm
A8: S4 | B8: Spotify 20-F FY2022 | C8: https://www.sec.gov/Archives/edgar/data/1639920/000163992023000004/ck0001639920-20221231.htm
A9: S5 | B9: Q4 2025 shareholder letter (6-K) | C9: https://www.sec.gov/Archives/edgar/data/1639920/000114036126004482/ef20065075_ex99-1.htm
A10: S6 | B10: Q1 2026 shareholder letter (6-K) | C10: https://www.sec.gov/Archives/edgar/data/0001639920/000114036126017211/ef20071303_ex99-1.htm
A11: S7 | B11: Q2 2026 shareholder letter (6-K) | C11: https://www.sec.gov/Archives/edgar/data/0001639920/000114036126031044/ef20078867_ex99-1.htm
A12: S8 | B12: Q3 2025 shareholder letter (6-K) | C12: https://www.sec.gov/Archives/edgar/data/1639920/000114036125040271/ef20057592_ex99-1.htm
A13: S9 | B13: Q4 2025 shareholder deck | C13: https://s29.q4cdn.com/175625835/files/doc_financials/2025/q4/Q4-2025-Shareholder-Deck-FINAL.pdf
A14: S10 | B14: Q2 2024 earnings call prepared remarks | C14: https://s29.q4cdn.com/175625835/files/doc_financials/2024/q2/Q2-24-Earnings-Call-Prepared-Remarks.pdf
A15: S11 | B15: Investor Day 2022 transcript (8 Jun 2022) | C15: https://s29.q4cdn.com/175625835/files/doc_presentation/SPOTIFY-2022-INVESTOR-DAY-TRANSCRIPT.pdf
... A52: S48 | B52: Analyst view (2 Oct 2026): Discovery Mode is at least 80% of Marketplace gross profit | C52: user input; drives Inputs section F
