Workbook

Sheet Summary
A1: Spotify Discovery Mode: is the boost fading?
A2: Evidence from 70 first-hand artist reports on r/musicmarketing (Oct 2020 - Oct 2026) and 35 Spotify for Artists screenshots. Green cells link to the data sheets.
A4: Key numbers
A5: Median Spotify-reported lift, campaigns Aug 2023 - Nov 2024 (n = 4) | B5: ='Campaign lifts'!$G$13 -> 4.0591695
A6: Median Spotify-reported lift, campaigns Jan 2025 - Jul 2026 (n = 3) | B6: ='Campaign lifts'!$G$14 -> 0.77991651
A7: Median saves + adds per Discovery Mode listener (8 campaigns) | B7: =Engagement!$E$18 -> 0.012422383
A8: Median saves per listener, artists' overall audience (4 dashboards) | B8: =Engagement!$E$19 -> 0.19854954
A9: Share of first-hand reports that went up: artists under 10k listeners | B9: ='Artist pairs'!$F$34 -> 1
A10: Share of first-hand reports that went up: artists with 10k+ listeners | B10: ='Artist pairs'!$F$37 -> 0.38888889
A11: First-hand reports saying Discover Weekly / algorithmic streams fell | B11: =Reference!$B$13&" of "&Reference!$B$8 -> 12 of 70
A12: Median Discovery Mode share of monthly streams (established artists) | B12: =Reference!$B$56 -> 0.075
A14: The argument
A15: 1. Mechanism first. Discovery Mode is a relative boost inside a fixed pool of Radio and Autoplay slots. Every new enrollee dilutes the others, so the per-track payoff must fall as enrollment grows. Symptoms: in one Dec 2023 campaign 4 of 6 enrolled songs got zero Discovery Mode streams; in 2025 one artist found 7 of 12 enrolled songs at 0-100 radio streams while still enrolled.
A16: 2. Spotify's own lift metric is shrinking. Even on the flattering Radio/Autoplay-only measure, the 2025-26 campaign reports show a fraction of the 2023-24 lifts (chart 1; 'Campaign lifts' sheet).
A17: 3. The lift is hollow. The one artist who checked total streams found Spotify claiming +55% while the song's total fell. Discovery Mode listeners keep the song about 1% of the time versus roughly 20% for an artist's normal audience, and the latest campaign in the set has the lowest engagement of all (chart 2; 'Engagement' sheet).
A18: 4. Enrollment has become defensive. Artists who stay say they re-enrolled out of fear or 'would not take it out again'; opting out halved one song's daily streams. For a new artist the pitch is now 'give up 30% to avoid losing ground', not 'give up 30% to grow' ('On-off cases' sheet).
A19: 5. It still works only where the royalties barely matter. Every report from artists under 10k listeners went up; above 10k it is a coin flip (chart 3; 'Artist pairs' sheet). The addressable pool for the margin lever is the long tail.
A21: Where it breaks
A22: The 18 artist-reported before/after pairs trend toward 'Up' over time (2023: 1 up / 5 down; 2025-26: 3 up / 0 down). The defensible reading is mix shift: the 2023 losers were 30k-80k-listener artists in the early rollout, the later winners are mostly small. State that; do not rely on the pairs for the time claim.
A23: Sample sizes are tiny (7 campaign lifts, 18 pairs) and self-selected from one subreddit. The 2026 platform-wide drops some artists report could be an algorithm change unrelated to the program.
A25: Chart 1. Spotify-reported lift by campaign date (the headline chart)
A44: Chart 2. Discovery Mode listeners rarely keep the song
A72: Chart 3. Reports of streams going up, by artist size

Sheet Campaign lifts
A1: Spotify campaign reports: Discovery Mode-context streams, before vs during
A2: Streams in Radio, Autoplay and Mixes during the campaign vs the 28 days before, as shown in artists' Spotify for Artists screenshots. Blue = input read from the screenshot; black = formula.
A4: Campaign month | B4: Label | C4: Source (r/musicmarketing id) | D4: Songs enrolled | E4: DM-context streams, campaign | F4: DM-context streams, prior 28 days | G4: Reported lift | H4: Era | I4: Lift: 2023-24 campaigns | J4: Lift: 2025-26 campaigns | K4: Campaign listeners | L4: New listeners | M4: Saves + adds per listener | N4: Songs that gained | O4: Songs reported | P4: Note
A5: 45139 | B5: Aug 2023 | C5: 15woi7w | E5: 445475 | F5: 91662 | G5: =IF(F5="","",E5/F5-1) -> 3.8599747 | H5: =IF(YEAR(A5)<=2024,"2023-24","2025-26") -> 2023-24 | I5: =G5 -> 3.8599747 | K5: 192090 | L5: 105307 | M5: 0.010573169 | P5: Aug 1-20 only; 'results insane'
A6: 45566 | B6: Oct 2024 (a) | C6: 1g1fk0o | D6: 8 | E6: 5658 | F6: 1076 | G6: =IF(F6="","",E6/F6-1) -> 4.2583643 | H6: =IF(YEAR(A6)<=2024,"2023-24","2025-26") -> 2023-24 | I6: =G6 -> 4.2583643 | K6: 4755 | M6: 0.011987382 | N6: 8 | O6: 8
A7: 45566 | B7: Oct 2024 (b) | C7: 1geig0k | D7: 4 | E7: 3011 | F7: 359 | G7: =IF(F7="","",E7/F7-1) -> 7.3871866 | H7: =IF(YEAR(A7)<=2024,"2023-24","2025-26") -> 2023-24 | I7: =G7 -> 7.3871866 | K7: 1723 | L7: 932 | M7: 0.048171793 | N7: 3 | O7: 4
A8: 45597 | B8: Nov 2024 | C8: 1h46nzy | D8: 4 | E8: 46995 | F8: 16336 | G8: =IF(F8="","",E8/F8-1) -> 1.8767752 | H8: =IF(YEAR(A8)<=2024,"2023-24","2025-26") -> 2023-24 | I8: =G8 -> 1.8767752 | K8: 25167 | L8: 21328 | M8: 0.010728335 | P8: ~25k monthly listeners
A9: 45658 | B9: Jan 2025 | C9: 1ig7963 (text) | D9: 1 | E9: 7404 | F9: 4777 | G9: =IF(F9="","",E9/F9-1) -> 0.54992673 | H9: =IF(YEAR(A9)<=2024,"2023-24","2025-26") -> 2025-26 | J9: =G9 -> 0.54992673 | P9: Spotify reported +55% lift, but the same song's TOTAL streams fell from ~46k/month (Oct-Dec) to 43k in Jan
A10: 45931 | B10: Oct 2025 | C10: 1omcbrg | D10: 7 | E10: 39156 | F10: 10195 | G10: =IF(F10="","",E10/F10-1) -> 2.8407062 | H10: =IF(YEAR(A10)<=2024,"2023-24","2025-26") -> 2025-26 | J10: =G10 -> 2.8407062 | K10: 27807 | M10: 0.017333765 | N10: 7 | O10: 7
A11: 46204 | B11: Jul 2026 | C11: 1uy70w1 (text) | D11: 3 | E11: 7675 | F11: 4312 | G11: =IF(F11="","",E11/F11-1) -> 0.77991651 | H11: =IF(YEAR(A11)<=2024,"2023-24","2025-26") -> 2025-26 | J11: =G11 -> 0.77991651 | K11: 5911 | L11: 5243 | M11: 0.012857385 | N11: 3 | O11: 3
A13: Median reported lift, 2023-24 campaigns | G13: =MEDIAN(G5:G8) -> 4.0591695 | H13: =COUNT(G5:G8)&" campaigns" -> 4 campaigns
A14: Median reported lift, 2025-26 campaigns | G14: =MEDIAN(G9:G11) -> 0.77991651 | H14: =COUNT(G9:G11)&" campaigns" -> 3 campaigns
A15: Median reported lift, all campaigns with a before figure | G15: =MEDIAN(G5:G11) -> 2.8407062
A16: Latest campaign lift as a share of the earliest | G16: =G11/G5 -> 0.20205223
A18: Campaign reports without a prior-28-day figure (engagement only)
A19: Campaign month | B19: Label | C19: Source (r/musicmarketing id) | D19: Songs enrolled | E19: DM-context streams, campaign | F19: DM-context streams, prior 28 days | G19: Reported lift | H19: Era | I19: Lift: 2023-24 campaigns | J19: Lift: 2025-26 campaigns | K19: Campaign listeners | L19: New listeners | M19: Saves + adds per listener | N19: Songs that gained | O19: Songs reported | P19: Note
A20: 45261 | B20: Dec 2023 | C20: 18lveoc | D20: 6 | E20: 1816 | G20: =IF(F20="","",E20/F20-1) | H20: =IF(YEAR(A20)<=2024,"2023-24","2025-26") -> 2023-24 | K20: 1306 | M20: 0.018376723 | N20: 2 | O20: 6 | P20: 4 of 6 songs got 0 DM streams (incl. top songs)
A21: 46266 | B21: Sep 2026 | C21: 1wu7cam | D21: 7 | E21: 27994 | G21: =IF(F21="","",E21/F21-1) | H21: =IF(YEAR(A21)<=2024,"2023-24","2025-26") -> 2025-26 | K21: 22689 | M21: 0.0068315043 | P21: Intent 0.19-1.10% per song
A23: Reported lift = campaign streams / prior-28-day streams - 1. Where the screenshot showed only the lift, the prior-28-day figure is streams / (1 + lift).
A24: These counts cover only Radio, Autoplay and Mixes. They do not show whether the song's total streams rose; the Jan 2025 case is the one artist who checked, and total streams fell.
A25: Saves + adds per listener = (saves + playlist adds) / campaign listeners, from the same screenshot.
A26: Source: screenshots posted to r/musicmarketing, identified by post id. Collected via the Arctic Shift archive, read by hand.

Sheet Artist pairs
A1: Artists' own before/after numbers (every first-hand report that gave both)
A2: Blue = as reported by the artist; black = formula. 'Flat' = change within +/-5%.
A4: Date posted | B4: Year | C4: Measure | D4: Monthly listeners at start | E4: Size band | F4: Before | G4: After | H4: Change | I4: Direction | J4: Source | K4: What the artist said
A5: 45212 | B5: =YEAR(A5) -> 2023 | C5: Monthly listeners | D5: 37500 | E5: =IF(D5="","not stated",IF(D5<10000,"Under 10k",IF(D5<50000,"10k-50k","50k+"))) -> 10k-50k | F5: 37500 | G5: 19000 | H5: =G5/F5-1 -> -0.49333333 | I5: =IF(ABS(H5)<0.05,"Flat",IF(H5>0,"Up","Down")) -> Down | J5: 176v311/k2zctt7/k3tx6dh | K5: Organic 35-40k listeners; after 3 months of DM down to 19k, no follows/saves from DM, Fans Also Like 'destroyed'.
A6: 45213 | B6: =YEAR(A6) -> 2023 | C6: Monthly listeners | D6: 80000 | E6: =IF(D6="","not stated",IF(D6<10000,"Under 10k",IF(D6<50000,"10k-50k","50k+"))) -> 50k+ | F6: 80000 | G6: 52000 | H6: =G6/F6-1 -> -0.35 | I6: =IF(ABS(H6)<0.05,"Flat",IF(H6>0,"Up","Down")) -> Down | J6: k4ox17o | K6: Discover Weekly streams fell, radio rose; saves/adds from DM 'terrible'.
A7: 45213 | B7: =YEAR(A7) -> 2023 | C7: Monthly listeners | D7: 80000 | E7: =IF(D7="","not stated",IF(D7<10000,"Under 10k",IF(D7<50000,"10k-50k","50k+"))) -> 50k+ | F7: 80000 | G7: 40000 | H7: =G7/F7-1 -> -0.5 | I7: =IF(ABS(H7)<0.05,"Flat",IF(H7>0,"Up","Down")) -> Down | J7: k4pk3ug | K7: Blames Spotify pushing Discover Weekly less after DM.
A8: 45226 | B8: =YEAR(A8) -> 2023 | C8: Radio streams / month | E8: =IF(D8="","not stated",IF(D8<10000,"Under 10k",IF(D8<50000,"10k-50k","50k+"))) -> not stated | F8: 1800 | G8: 20000 | H8: =G8/F8-1 -> 10.111111 | I8: =IF(ABS(H8)<0.05,"Flat",IF(H8>0,"Up","Down")) -> Up | J8: k6lhdlu | K8: Radio ~1,800/month before DM -> ~20,000/month after several months (releases weekly).
A9: 45240 | B9: =YEAR(A9) -> 2023 | C9: Monthly listeners | D9: 30000 | E9: =IF(D9="","not stated",IF(D9<10000,"Under 10k",IF(D9<50000,"10k-50k","50k+"))) -> 10k-50k | F9: 30000 | G9: 8700 | H9: =G9/F9-1 -> -0.71 | I9: =IF(ABS(H9)<0.05,"Flat",IF(H9>0,"Up","Down")) -> Down | J9: k79yvek | K9: One song on DM in Sept (0.90% intent); skipped Oct and Discover Weekly 'suppressed'; re-enrolled out of fear.
A10: 45261 | B10: =YEAR(A10) -> 2023 | C10: Monthly listeners | D10: 30000 | E10: =IF(D10="","not stated",IF(D10<10000,"Under 10k",IF(D10<50000,"10k-50k","50k+"))) -> 10k-50k | F10: 30000 | G10: 5000 | H10: =G10/F10-1 -> -0.83333333 | I10: =IF(ABS(H10)<0.05,"Flat",IF(H10>0,"Up","Down")) -> Down | J10: kbb4arn | K10: Beta: first campaign gave a bump; second campaign listeners fell 30k -> 5k (normal range 10-20k).
A11: 45349 | B11: =YEAR(A11) -> 2024 | C11: Streams / month | E11: =IF(D11="","not stated",IF(D11<10000,"Under 10k",IF(D11<50000,"10k-50k","50k+"))) -> not stated | F11: 10000 | G11: 50000 | H11: =G11/F11-1 -> 4 | I11: =IF(ABS(H11)<0.05,"Flat",IF(H11>0,"Up","Down")) -> Up | J11: kspq2mj | K11: 'Totally down to discovery mode'; not every song works.
A12: 45352 | B12: =YEAR(A12) -> 2024 | C12: Streams / day | E12: =IF(D12="","not stated",IF(D12<10000,"Under 10k",IF(D12<50000,"10k-50k","50k+"))) -> not stated | F12: 40000 | G12: 15000 | H12: =G12/F12-1 -> -0.625 | I12: =IF(ABS(H12)<0.05,"Flat",IF(H12>0,"Up","Down")) -> Down | J12: 1b43vbm | K12: Song at ~40k/day; fell the month it was enrolled and never recovered; also pulled from Discover Weekly.
A13: 45352 | B13: =YEAR(A13) -> 2024 | C13: Radio streams / month | E13: =IF(D13="","not stated",IF(D13<10000,"Under 10k",IF(D13<50000,"10k-50k","50k+"))) -> not stated | F13: 4000 | G13: 150 | H13: =G13/F13-1 -> -0.9625 | I13: =IF(ABS(H13)<0.05,"Flat",IF(H13>0,"Up","Down")) -> Down | J13: ksx3w9s | K13: Last DM month: 150 streams; month without DM: 4k on radio alone.
A14: 45352 | B14: =YEAR(A14) -> 2024 | C14: Monthly listeners | D14: 2000 | E14: =IF(D14="","not stated",IF(D14<10000,"Under 10k",IF(D14<50000,"10k-50k","50k+"))) -> Under 10k | F14: 2000 | G14: 7500 | H14: =G14/F14-1 -> 2.75 | I14: =IF(ABS(H14)<0.05,"Flat",IF(H14>0,"Up","Down")) -> Up | J14: kszo2zz
A15: 45364 | B15: =YEAR(A15) -> 2024 | C15: Streams / month | E15: =IF(D15="","not stated",IF(D15<10000,"Under 10k",IF(D15<50000,"10k-50k","50k+"))) -> not stated | F15: 1000000 | G15: 300000 | H15: =G15/F15-1 -> -0.7 | I15: =IF(ABS(H15)<0.05,"Flat",IF(H15>0,"Up","Down")) -> Down | J15: ktmj79o | K15: ~1M streams/month -> 300k 'literally overnight'; never came back after stopping.
A16: 45518 | B16: =YEAR(A16) -> 2024 | C16: Discover Weekly streams / week | E16: =IF(D16="","not stated",IF(D16<10000,"Under 10k",IF(D16<50000,"10k-50k","50k+"))) -> not stated | F16: 5000 | G16: 190 | H16: =G16/F16-1 -> -0.962 | I16: =IF(ABS(H16)<0.05,"Flat",IF(H16>0,"Up","Down")) -> Down | J16: li52lv4/lve66bg | K16: Best track ~5k DW streams/week; 3 weeks on DM = 567 DW streams total; took 4 months to recover.
A17: 45649 | B17: =YEAR(A17) -> 2024 | C17: Monthly listeners | D17: 25000 | E17: =IF(D17="","not stated",IF(D17<10000,"Under 10k",IF(D17<50000,"10k-50k","50k+"))) -> 10k-50k | F17: 25000 | G17: 60000 | H17: =G17/F17-1 -> 1.4 | I17: =IF(ABS(H17)<0.05,"Flat",IF(H17>0,"Up","Down")) -> Up | J17: m3i1jez | K17: ~30k DM streams month 1, 40k month 2.
A18: 45653 | B18: =YEAR(A18) -> 2024 | C18: Monthly listeners | D18: 5000 | E18: =IF(D18="","not stated",IF(D18<10000,"Under 10k",IF(D18<50000,"10k-50k","50k+"))) -> Under 10k | F18: 5000 | G18: 44000 | H18: =G18/F18-1 -> 7.8 | I18: =IF(ABS(H18)<0.05,"Flat",IF(H18>0,"Up","Down")) -> Up | J18: m3ys1wz | K18: Meta ads + DM; much of growth via radio.
A19: 45690 | B19: =YEAR(A19) -> 2025 | C19: Streams / month | D19: 60000 | E19: =IF(D19="","not stated",IF(D19<10000,"Under 10k",IF(D19<50000,"10k-50k","50k+"))) -> 50k+ | F19: 36655 | G19: 36549 | H19: =G19/F19-1 -> -0.0028918292 | I19: =IF(ABS(H19)<0.05,"Flat",IF(H19>0,"Up","Down")) -> Flat | J19: 1ig7963 | K19: Song A: Dec 36,655 streams -> Jan 36,549 while Spotify reported +69% lift. Song B: ~46k/month -> 43k while Spotify credited 7,404 DM streams (+55%).
A20: 45909 | B20: =YEAR(A20) -> 2025 | C20: Monthly listeners | D20: 10000 | E20: =IF(D20="","not stated",IF(D20<10000,"Under 10k",IF(D20<50000,"10k-50k","50k+"))) -> 10k-50k | F20: 10000 | G20: 20000 | H20: =G20/F20-1 -> 1 | I20: =IF(ABS(H20)<0.05,"Flat",IF(H20>0,"Up","Down")) -> Up | J20: nd42847
A21: 45909 | B21: =YEAR(A21) -> 2025 | C21: Monthly listeners | D21: 100 | E21: =IF(D21="","not stated",IF(D21<10000,"Under 10k",IF(D21<50000,"10k-50k","50k+"))) -> Under 10k | F21: 100 | G21: 700 | H21: =G21/F21-1 -> 6 | I21: =IF(ABS(H21)<0.05,"Flat",IF(H21>0,"Up","Down")) -> Up | J21: nd5w63f | K21: One track on DM ~800 streams/month; fans at shows cite it.
A22: 46067 | B22: =YEAR(A22) -> 2026 | C22: Streams / day | D22: 100000 | E22: =IF(D22="","not stated",IF(D22<10000,"Under 10k",IF(D22<50000,"10k-50k","50k+"))) -> 50k+ | F22: 500 | G22: 1000 | H22: =G22/F22-1 -> 1 | I22: =IF(ABS(H22)<0.05,"Flat",IF(H22>0,"Up","Down")) -> Up | J22: 1r4op37 | K22: Taking the song OUT of DM cut it from ~1,000 to ~500 streams/day; 'would not take it out again'.
A24: Direction by year posted (these 18 numeric pairs)
A25: Year | B25: Up | C25: Down | D25: Flat | E25: Total | F25: Avg listeners at start, Down cases
A26: 2023 | B26: =COUNTIFS($B$5:$B$22,VALUE(A26),$I$5:$I$22,"Up") -> 1 | C26: =COUNTIFS($B$5:$B$22,VALUE(A26),$I$5:$I$22,"Down") -> 5 | D26: =COUNTIFS($B$5:$B$22,VALUE(A26),$I$5:$I$22,"Flat") -> 0 | E26: =SUM(B26:D26) -> 6 | F26: =IFERROR(AVERAGEIFS($D$5:$D$22,$B$5:$B$22,VALUE(A26),$I$5:$I$22,"Down"),"size not stated") -> 51500
A27: 2024 | B27: =COUNTIFS($B$5:$B$22,VALUE(A27),$I$5:$I$22,"Up") -> 4 | C27: =COUNTIFS($B$5:$B$22,VALUE(A27),$I$5:$I$22,"Down") -> 4 | D27: =COUNTIFS($B$5:$B$22,VALUE(A27),$I$5:$I$22,"Flat") -> 0 | E27: =SUM(B27:D27) -> 8 | F27: =IFERROR(AVERAGEIFS($D$5:$D$22,$B$5:$B$22,VALUE(A27),$I$5:$I$22,"Down"),"size not stated") -> size not stated
A28: 2025 | B28: =COUNTIFS($B$5:$B$22,VALUE(A28),$I$5:$I$22,"Up") -> 2 | C28: =COUNTIFS($B$5:$B$22,VALUE(A28),$I$5:$I$22,"Down") -> 0 | D28: =COUNTIFS($B$5:$B$22,VALUE(A28),$I$5:$I$22,"Flat") -> 1 | E28: =SUM(B28:D28) -> 3 | F28: =IFERROR(AVERAGEIFS($D$5:$D$22,$B$5:$B$22,VALUE(A28),$I$5:$I$22,"Down"),"size not stated") -> size not stated
A29: 2026 | B29: =COUNTIFS($B$5:$B$22,VALUE(A29),$I$5:$I$22,"Up") -> 1 | C29: =COUNTIFS($B$5:$B$22,VALUE(A29),$I$5:$I$22,"Down") -> 0 | D29: =COUNTIFS($B$5:$B$22,VALUE(A29),$I$5:$I$22,"Flat") -> 0 | E29: =SUM(B29:D29) -> 1 | F29: =IFERROR(AVERAGEIFS($D$5:$D$22,$B$5:$B$22,VALUE(A29),$I$5:$I$22,"Down"),"size not stated") -> size not stated
A30: Caveat: by year, these pairs trend toward 'Up', not away from it. The 2023 losers were all 30k-80k-listener artists in the early rollout; most later winners are small artists. Read it as a change in who posts, not proof the program improved.
A32: Direction by audience size at the start (all first-hand reports that stated a size, n = 26)
A33: Size band | B33: Up | C33: Mixed / flat | D33: Down | E33: Total | F33: Share up
A34: Under 10k | B34: 8 | C34: 0 | D34: 0 | E34: =SUM(B34:D34) -> 8 | F34: =B34/E34 -> 1
A35: 10k-50k | B35: 4 | C35: 1 | D35: 4 | E35: =SUM(B35:D35) -> 9 | F35: =B35/E35 -> 0.44444444
A36: 50k+ | B36: 3 | C36: 3 | D36: 3 | E36: =SUM(B36:D36) -> 9 | F36: =B36/E36 -> 0.33333333
A37: 10k and above | B37: =SUM(B35:B36) -> 7 | C37: =SUM(C35:C36) -> 4 | D37: =SUM(D35:D36) -> 7 | E37: =SUM(B37:D37) -> 18 | F37: =B37/E37 -> 0.38888889
A38: Counts come from the hand-coded set of 70 first-hand reports (not only the 18 with numbers); 26 of them stated an audience size. 'Mixed / flat' pools the report's 'mixed' and 'flat' codes.

Sheet Engagement
A1: How often listeners keep the song: saves + playlist adds per listener
A2: Discovery Mode campaign listeners (Spotify campaign report) vs artists' overall audience (Spotify for Artists dashboard). Blue = input.
A4: Group | B4: Campaign / artist | C4: Source | D4: Listeners | E4: Saves + adds per listener | F4: Discovery Mode listeners | G4: Overall audience
A5: Discovery Mode listeners | B5: Aug 2023 campaign | C5: 15woi7w | D5: 192090 | E5: 0.010573169 | F5: =E5 -> 0.010573169
A6: Discovery Mode listeners | B6: Dec 2023 campaign | C6: 18lveoc | D6: 1306 | E6: 0.018376723 | F6: =E6 -> 0.018376723
A7: Discovery Mode listeners | B7: Oct 2024 campaign (a) | C7: 1g1fk0o | D7: 4755 | E7: 0.011987382 | F7: =E7 -> 0.011987382
A8: Discovery Mode listeners | B8: Oct 2024 campaign (b) | C8: 1geig0k | D8: 1723 | E8: 0.048171793 | F8: =E8 -> 0.048171793
A9: Discovery Mode listeners | B9: Nov 2024 campaign | C9: 1h46nzy | D9: 25167 | E9: 0.010728335 | F9: =E9 -> 0.010728335
A10: Discovery Mode listeners | B10: Oct 2025 campaign | C10: 1omcbrg | D10: 27807 | E10: 0.017333765 | F10: =E10 -> 0.017333765
A11: Discovery Mode listeners | B11: Jul 2026 campaign | C11: 1uy70w1 | D11: 5911 | E11: 0.012857385 | F11: =E11 -> 0.012857385
A12: Discovery Mode listeners | B12: Sep 2026 campaign | C12: 1wu7cam | D12: 22689 | E12: 0.0068315043 | F12: =E12 -> 0.0068315043
A13: Overall audience | B13: Artist 17gqiej, 12 months | C13: 17gqiej | E13: 0.24525392 | G13: =E13 -> 0.24525392
A14: Overall audience | B14: Artist 1q4bb7s, all time | C14: 1q4bb7s | E14: 0.18248588 | G14: =E14 -> 0.18248588
A15: Overall audience | B15: Artist 1rvflj9, 12 months | C15: 1rvflj9 | E15: 0.21461319 | G15: =E15 -> 0.21461319
A16: Overall audience | B16: Kublaii (1hn3dhf), 12 months | C16: 1hn3dhf | E16: 0.080622942 | G16: =E16 -> 0.080622942
A18: Median, Discovery Mode listeners | E18: =MEDIAN(E5:E12) -> 0.012422383
A19: Median, overall audience | E19: =MEDIAN(E13:E16) -> 0.19854954
A20: Overall audience keeps the song this many times more often | E20: =E19/E18 -> 15.983208
A22: Discovery Mode rate = (saves + playlist adds) / campaign listeners, from the campaign report. Overall rate = saves / listeners from the artist's dashboard. Different artists and definitions, so read as orders of magnitude.

Sheet On-off cases
A1: What happened when Discovery Mode was switched on or off
A2: Cases where an artist's own graphs show the switch. Blue = as reported; black = formula.
A4: Source | B4: Change | C4: Measure | D4: Before | E4: After | F4: Change | G4: What happened
A5: 1and042 | B5: DM on (Apr 2023) | C5: Radio & autoplay listeners / day | D5: 70 | E5: 900 | F5: =IF(OR(D5="",E5=""),"",E5/D5-1) -> 11.857143 | G5: ~70/day before -> ~400 right after -> ~900-1,200 a year later; weekly releases throughout.
A6: 1q4bb7s | B6: DM on (Dec 1, 2025) | C6: Artist streams / month | D6: 195000 | E6: 280000 | F6: =IF(OR(D6="",E6=""),"",E6/D6-1) -> 0.43589744 | G6: Nov ~195k -> Dec ~280k (back to Oct level). Song-level daily streams: 2,646 -> ~4,500; 270 -> ~900; 553 -> ~1,300. Popularity of 4 promoted songs +4-6 points, top song -2. Followers/day unchanged.
A7: 1rvflj9 | B7: DM off (Oct 2025) then on | C7: Radio & autoplay streams / day | D7: 7000 | E7: 2000 | F7: =IF(OR(D7="",E7=""),"",E7/D7-1) -> -0.71428571 | G7: ~6-9k/day Jul-Sep with DM -> ~2k/day in October with DM off -> 6-11k/day after re-enrolling. Then an ~80% collapse in Mar 2026 with DM on.
A8: 1r4op37 (text) | B8: DM off | C8: Song streams / day | D8: 1000 | E8: 500 | F8: =IF(OR(D8="",E8=""),"",E8/D8-1) -> -0.5 | G8: Spotify flagged the song 'not recommended'; removing it halved daily streams.
A9: ksx3w9s (text) | B9: DM off | C9: Radio streams / month | D9: 150 | E9: 4000 | F9: =IF(OR(D9="",E9=""),"",E9/D9-1) -> 25.666667 | G9: Opposite case: 150 DM streams in last DM month; 4k radio the month after leaving.
A10: 1t81jjd | B10: DM off + Meta ads | C10: Song radio streams (28 days) | E10: 74 | F10: =IF(OR(D10="",E10=""),"",E10/D10-1) | G10: 7 of 12 songs had fallen to 0-100 radio streams in DM; after opting out, radio stayed at 74 even with ads (saves +270%).
A12: Why it matters for the framing: artists who stay enrolled describe it as defensive (re-enrolled out of fear; 'would not take it out again'). Switching off cut radio streams by 50-70% in two charted cases. For an artist deciding whether to enroll for the first time, the pitch has become 'pay 30% to avoid losing ground'.

Sheet Reference
A1: Corpus, extra series and method
A3: Corpus
A4: r/musicmarketing posts since Oct 2020 (Arctic Shift archive) | B4: 27088
A5: Posts mentioning Discovery Mode | B5: 130
A6: Comments in those threads | B6: 1953
A7: Artist experiences coded | B7: 73
A8: of which first-hand | B8: 70
A9: first-hand: streams went up | B9: 39
A10: first-hand: streams went down | B10: 21
A11: first-hand: mixed | B11: 7
A12: first-hand: flat | B12: 3
A13: First-hand reports saying Discover Weekly / algorithmic streams fell after opting in | B13: 12
A14: Spotify for Artists screenshots read (7 more had been deleted) | B14: 35
A15: Share of first-hand reports that went up | B15: =B9/B8 -> 0.55714286
A17: Spotify-reported 'stream lift' figures quoted in posts and screenshots (%) | D17: Order as extracted; dates not attached, so this list cannot be used for a time trend.
A18: Lift 1 | B18: 2.77
A19: Lift 2 | B19: 9.15
A20: Lift 3 | B20: 11.92
A21: Lift 4 | B21: 1.5
A22: Lift 5 | B22: 20
A23: Lift 6 | B23: 30
A24: Lift 7 | B24: 60
A25: Lift 8 | B25: 1.53
A26: Lift 9 | B26: 0.69
A27: Lift 10 | B27: 0.55
A28: Lift 11 | B28: 0.78
A29: Lift 12 | B29: 2.14
A30: Lift 13 | B30: 1.69
A31: Median | B31: =MEDIAN(B18:B30) -> 2.14
A33: Intent rate per song quoted by artists (saves + adds / listeners, %) | D33: Spotify's own engagement measure for a Discovery Mode song. Order as extracted.
A34: Intent 1 | B34: 0.015
A35: Intent 2 | B35: 0.009
A36: Intent 3 | B36: 0.02
A37: Intent 4 | B37: 0.0266
A38: Intent 5 | B38: 0.01
A39: Intent 6 | B39: 0.0079
A40: Intent 7 | B40: 0.01
A41: Intent 8 | B41: 0.0121
A42: Intent 9 | B42: 0.004
A43: Intent 10 | B43: 0.007
...
