Workbook

Sheet Inputs
A1: Spotify gross margin driver model: Discovery Mode and autoplay growth
A2: Blue = hardcoded input; black = formula; green = link to another sheet; yellow = key lever to set from the expert calls. Currency in EUR millions. Percentages stored as fractions.
A4: A. Reported anchors (Spotify filings and shareholder letters)
B5: Value | F5: Source / note
A6: FY2025 total revenue (EUR m) | B6: 17186 | F6: Spotify FY2025 20-F: revenue EUR 17,186m (Premium 15,350m; Ad-Supported 1,836m).
A7: FY2025 Premium revenue (EUR m) | B7: 15350 | F7: Spotify FY2025 20-F.
A8: FY2025 Ad-Supported revenue (EUR m) | B8: 1836 | F8: Spotify FY2025 20-F.
A9: FY2025 consolidated gross margin | B9: 0.32 | F9: Spotify FY2025 20-F (rounded 32%); quarterly path 31.6% / 31.5% / 31.6% / 33.1%.
A10: FY2025 Premium gross margin | B10: 0.34 | F10: Spotify FY2025 20-F (rounded 34%; 33% in FY2024, 29% in FY2023).
A11: Q2 2026 consolidated gross margin (reported) | B11: 0.334 | F11: Q2 2026 shareholder letter: 33.4%, +193 bps YoY; Premium 35% vs 33%.
A12: Q3 2026 gross margin guidance | B12: 0.329 | F12: Q2 2026 shareholder letter: Q3 guide 32.9% on EUR 5.0bn revenue (+14% YoY).
A13: 2030 gross margin target: low end | B13: 0.35 | F13: Investor Day, May 21 2026: 35-40% gross margin by 2030, mid-teens revenue CAGR.
A14: 2030 gross margin target: high end | B14: 0.4 | F14: Investor Day, May 21 2026.
A15: Marketplace gross profit contribution, 2021 (EUR m) | B15: 160 | F15: Investor Day June 2022: 'more than EUR 160 million' in 2021 (under EUR 20m in 2018). Treated as the floor.
A16: Marketplace gross profit multiple, 2025 vs 2021 | B16: 4 | F16: Investor Day May 2026: 2025 marketplace gross profit was four times 2021. Marketplace = Discovery Mode + Marquee + Showcase.
A17: Music royalty pool, FY2025, after all discounts (EUR m) | B17: 10100 | F17: Loud & Clear 2026: USD 11bn paid to music rights holders in 2025, converted at ~1.09 USD/EUR. Approximates the pool the DM discount is taken from; pre-discount pool is ~3% higher.
A18: Derived: FY2025 marketplace gross profit (EUR m) | B18: =B15*B16 -> 640 | F18: 2021 contribution x the 2025/2021 multiple. A floor, because the 2021 figure was stated as more than 160.
A19: Derived: FY2025 marketplace contribution to consolidated GM | B19: =B18/B6 -> 0.037239614 | F19: Share of revenue. Multiply by 10,000 for basis points.
A20: Derived: FY2025 music royalty pool as % of revenue | B20: =B17/B6 -> 0.58768765
A22: B. Discovery Mode structural parameters (the levers the expert calls should pin down)
B23: Value | F23: Source / note
A24: DM royalty discount on DM-context streams | B24: 0.3 | F24: Program term: rights holder accepts a 30% lower royalty on streams delivered in Radio, Autoplay and (since Jan 2024) Mixes. Could change at label renewals or under regulatory pressure.
A25: Eligible-surface share of streams, 2025 (Radio + Autoplay + Mixes) | B25: 0.18 | F25: KEY LEVER 'e'. Not disclosed. Spotify: 33% of discoveries happen in algorithmic contexts; third parties put algorithmic listening near 40% of streams, of which Radio/Autoplay/Mixes is a subset; enrolled established artists in the DM workbook report DM-context at 3.5-5% of their streams. Plausible range 12-25%. This is what 'autoplay growth' moves.
A26: Discovery Mode share of marketplace gross profit, 2025 | B26: 0.45 | F26: KEY LEVER. Not disclosed. Marquee/Showcase are booked as Ad-Supported revenue (+EUR 58m in 2024 from marketplace growth); DM is a reduction of cost of revenue. Range 35-65%. Used only to calibrate the 2025 enrolled share below.
A27: Base revenue growth 2026E | B27: 0.14 | F27: Q3 2026 guide +14% YoY; 2030 target mid-teens CAGR.
A28: Base revenue growth 2027E | B28: 0.13 | F28: Assumption.
A29: Base revenue growth 2028E | B29: 0.12 | F29: Assumption.
A30: Music royalty pool as % of revenue, forecast (held flat) | B30: =B20 -> 0.58768765 | F30: Linked to FY2025 derived value; royalties are the greater of a % of revenue and per-subscriber minimums, so the pool scales with revenue.
A32: C. Calibration of the 2025 enrolled share (solve for 's' from the top-down marketplace figure)
A33: Top-down FY2025 DM gross profit (EUR m) | B33: =B18*B26 -> 288
A34: Royalty pool on eligible surfaces (EUR m) = pool x e | B34: =B17*B25 -> 1818
A35: Implied enrolled share of eligible-surface streams, 2025 ('s') | B35: =IF(B34*B24=0,0,B33/(B34*B24)) -> 0.52805281 | F35: s = DM gross profit / (pool x e x discount). This is Topic 2 in the triangulation matrix: replace with the expert-call figure when available and the sheet re-solves nothing else; set DM share (B26) so that B35 matches the calls.
A36: Ceiling: DM gross profit if 100% of eligible-surface streams enrolled, 2025 (EUR m) | B36: =B34*B24 -> 545.4
A37: Ceiling as share of FY2025 revenue | B37: =B36/B6 -> 0.031735133
A38: Remaining runway at current surfaces and discount (EUR m) | B38: =B36-B33 -> 257.4
A39: Remaining runway as share of FY2025 revenue | B39: =B38/B6 -> 0.014977307 | F39: The whole remaining DM lever at today's surfaces is this many points of margin, and it shrinks in bps terms as revenue grows. Only 'e' (autoplay share, new surfaces) or the discount rate can expand it.
A41: D. Sensitivity: implied 2025 enrolled share 's' for combinations of e (rows) and DM share of marketplace GP (columns)
A42: e \ DM share of marketplace GP | B42: 0.35 | C42: 0.45 | D42: 0.55 | E42: 0.65
A43: 0.12 | B43: =IF($A43*$B$24=0,0,($B$18*B$42)/($B$17*$A43*$B$24)) -> 0.61606161 | C43: =IF($A43*$B$24=0,0,($B$18*C$42)/($B$17*$A43*$B$24)) -> 0.79207921 | D43: =IF($A43*$B$24=0,0,($B$18*D$42)/($B$17*$A43*$B$24)) -> 0.96809681 | E43: =IF($A43*$B$24=0,0,($B$18*E$42)/($B$17*$A43*$B$24)) -> 1.1441144
A44: 0.15 | B44: =IF($A44*$B$24=0,0,($B$18*B$42)/($B$17*$A44*$B$24)) -> 0.49284928 | C44: =IF($A44*$B$24=0,0,($B$18*C$42)/($B$17*$A44*$B$24)) -> 0.63366337 | D44: =IF($A44*$B$24=0,0,($B$18*D$42)/($B$17*$A44*$B$24)) -> 0.77447745 | E44: =IF($A44*$B$24=0,0,($B$18*E$42)/($B$17*$A44*$B$24)) -> 0.91529153
...

Sheet Scenarios
A1: Gross margin bridge under three Discovery Mode / autoplay paths
A2: Each block: set the yearly path of e (eligible-surface share) and s (enrolled share) and the Marquee/Showcase growth rate. DM gross profit = royalty pool x e x s x discount. Blue inputs; everything else is formula.
A4: Common lines
A5: Year | B5: 2025A | C5: 2026E | D5: 2027E | E5: 2028E
A6: Revenue growth | C6: =Inputs!B27 -> 0.14 | D6: =Inputs!B28 -> 0.13 | E6: =Inputs!B29 -> 0.12
A7: Revenue (EUR m) | B7: =Inputs!B6 -> 17186 | C7: =B7*(1+C6) -> 19592.04 | D7: =C7*(1+D6) -> 22139.005 | E7: =D7*(1+E6) -> 24795.686
A8: Music royalty pool (EUR m) = revenue x pool % | B8: =Inputs!B17 -> 10100 | C8: =C7*Inputs!$B$30 -> 11514 | D8: =D7*Inputs!$B$30 -> 13010.82 | E8: =E7*Inputs!$B$30 -> 14572.118
A9: DM discount rate | B9: =Inputs!$B$24 -> 0.3 | C9: =Inputs!$B$24 -> 0.3 | D9: =Inputs!$B$24 -> 0.3 | E9: =Inputs!$B$24 -> 0.3
A10: Other gross margin drivers, cumulative vs 2025 (pricing, audiobooks, podcasts, ad mix): INPUT, replace from your P&L model | B10: 0 | C10: 100 | D10: 180 | E10: 240 | F10: Basis points. Default set so the 'Slowing' case lands near H1 2026 actuals (33.0-33.4%) and the Q3 guide (32.9%): i.e. ~+100 bps in 2026 from everything except Discovery Mode and Marquee. Replace with your own non-marketplace bridge.
A11: FY2025 gross margin (base) | B11: =Inputs!B9 -> 0.32
A12: Reference: Q3 2026 guide / 2030 target midpoint | C12: =Inputs!B12 -> 0.329 | E12: =(Inputs!B13+Inputs!B14)/2 -> 0.375 | F12: 2030 midpoint shown in the 2028E column only as a direction marker, not a 2028 forecast.
A14: Scenario A: continued growth (the street-style path)
A15: Autoplay / programmed listening keeps gaining share (e +1.5 pt a year, including new surfaces such as Smart Shuffle or DJ sessions), enrollment keeps rising (s +8 pts a year), Marquee/Showcase grows 20% a year. Roughly extends the 2021-25 marketplace growth rate.
A16: Year | B16: 2025A | C16: 2026E | D16: 2027E | E16: 2028E
A17: e: eligible-surface share of streams (Radio + Autoplay + Mixes) | B17: =Inputs!$B$25 -> 0.18 | C17: 0.195 | D17: 0.21 | E17: 0.225
A18: s: enrolled share of eligible-surface streams | B18: =Inputs!$B$35 -> 0.52805281 | C18: 0.61 | D18: 0.69 | E18: 0.77
A19: DM-context enrolled streams as share of all streams = e x s | B19: =B17*B18 -> 0.095049505 | C19: =C17*C18 -> 0.11895 | D19: =D17*D18 -> 0.1449 | E19: =E17*E18 -> 0.17325
A20: Discovery Mode gross profit (EUR m) = pool x e x s x discount | B20: =B$8*B19*B$9 -> 288 | C20: =C$8*C19*C$9 -> 410.87709 | D20: =D$8*D19*D$9 -> 565.58035 | E20: =E$8*E19*E$9 -> 757.38585
A21: DM contribution to consolidated gross margin (bps) | B21: =B20/B$7*10000 -> 167.57826 | C21: =C20/C$7*10000 -> 209.71634 | D21: =D20/D$7*10000 -> 255.46782 | E21: =E20/E$7*10000 -> 305.45066
A22: DM contribution: change vs 2025 (bps) | B22: 0 | C22: =C21-$B21 -> 42.138078 | D22: =D21-$B21 -> 87.889561 | E22: =E21-$B21 -> 137.8724
A23: Marquee + Showcase gross profit growth (input) | C23: 0.2 | D23: 0.2 | E23: 0.2
A24: Marquee + Showcase gross profit (EUR m) | B24: =Inputs!$B$18-Inputs!$B$33 -> 352 | C24: =B24*(1+C23) -> 422.4 | D24: =C24*(1+D23) -> 506.88 | E24: =D24*(1+E23) -> 608.256
A25: Marquee + Showcase contribution to gross margin (bps) | B25: =B24/B$7*10000 -> 204.81788 | C25: =C24/C$7*10000 -> 215.59776 | D25: =D24/D$7*10000 -> 228.95338 | E25: =E24/E$7*10000 -> 245.30719
A26: Marquee + Showcase: change vs 2025 (bps) | B26: 0 | C26: =C25-$B25 -> 10.779888 | D26: =D25-$B25 -> 24.135502 | E26: =E25-$B25 -> 40.489314
A27: Total marketplace gross profit (EUR m) | B27: =B20+B24 -> 640 | C27: =C20+C24 -> 833.27709 | D27: =D20+D24 -> 1072.4603 | E27: =E20+E24 -> 1365.6419
A28: Implied marketplace gross profit growth | C28: =C27/B27-1 -> 0.30199545 | D28: =D27/C27-1 -> 0.28703928 | E28: =E27/D27-1 -> 0.27337282
A29: Gross margin = 2025 base + other drivers + DM change + Marquee change | B29: =$B$11+(B$10+B22+B26)/10000 -> 0.32 | C29: =$B$11+(C$10+C22+C26)/10000 -> 0.3352918 | D29: =$B$11+(D$10+D22+D26)/10000 -> 0.34920251 | E29: =$B$11+(E$10+E22+E26)/10000 -> 0.36183617
A30: Gross margin expansion vs 2025 (bps) | B30: =(B29-$B$11)*10000 -> 0 | C30: =(C29-$B$11)*10000 -> 152.91797 | D30: =(D29-$B$11)*10000 -> 292.02506 | E30: =(E29-$B$11)*10000 -> 418.36171
A31: Of which from marketplace (DM + Marquee), bps | B31: =B22+B26 -> 0 | C31: =C22+C26 -> 52.917966 | D31: =D22+D26 -> 112.02506 | E31: =E22+E26 -> 178.36171
A33: Scenario B: slowing (the thesis in the two workbooks)
A34: Autoplay share plateaus (e flat): Reddit mentions of autoplay/recs peaked in 2025, DJ/Smart Shuffle discussion has halved from 2024, Smart Shuffle became removable in April 2025. Enrollment still creeps up because staying in is defensive (s +3 pts a year) but new surfaces do not arrive. Marquee/Showcase +10% a year.
A35: Year | B35: 2025A | C35: 2026E | D35: 2027E | E35: 2028E
A36: e: eligible-surface share of streams (Radio + Autoplay + Mixes) | B36: =Inputs!$B$25 -> 0.18 | C36: 0.18 | D36: 0.18 | E36: 0.18
A37: s: enrolled share of eligible-surface streams | B37: =Inputs!$B$35 -> 0.52805281 | C37: 0.56 | D37: 0.59 | E37: 0.62
A38: DM-context enrolled streams as share of all streams = e x s | B38: =B36*B37 -> 0.095049505 | C38: =C36*C37 -> 0.1008 | D38: =D36*D37 -> 0.1062 | E38: =E36*E37 -> 0.1116
A39: Discovery Mode gross profit (EUR m) = pool x e x s x discount | B39: =B$8*B38*B$9 -> 288 | C39: =C$8*C38*C$9 -> 348.18336 | D39: =D$8*D38*D$9 -> 414.52473 | E39: =E$8*E38*E$9 -> 487.87452
A40: DM contribution to consolidated gross margin (bps) | B40: =B39/B$7*10000 -> 167.57826 | C40: =C39/C$7*10000 -> 177.71675 | D40: =D39/D$7*10000 -> 187.23729 | E40: =E39/E$7*10000 -> 196.75783
A41: DM contribution: change vs 2025 (bps) | B41: 0 | C41: =C40-$B40 -> 10.138485 | D41: =D40-$B40 -> 19.659025 | E41: =E40-$B40 -> 29.179565
A42: Marquee + Showcase gross profit growth (input) | C42: 0.1 | D42: 0.1 | E42: 0.1
A43: Marquee + Showcase gross profit (EUR m) | B43: =Inputs!$B$18-Inputs!$B$33 -> 352 | C43: =B43*(1+C42) -> 387.2 | D43: =C43*(1+D42) -> 425.92 | E43: =D43*(1+E42) -> 468.512
...

Sheet Sensitivity 2028
A1: DM contribution to 2028E consolidated gross margin (bps) for combinations of e (rows) and s (columns)
A2: Uses the common revenue path and discount from Scenarios. Compare any cell with the 2025 contribution (bottom) to read the incremental bps.
A4: e \ s | B4: 0.4 | C4: 0.5 | D4: 0.6 | E4: 0.7 | F4: 0.8 | G4: 0.9 | H4: 1
A5: 0.12 | B5: =Scenarios!$E$8*$A5*B$4*Scenarios!$E$9/Scenarios!$E$7*10000 -> 84.627022 | C5: =Scenarios!$E$8*$A5*C$4*Scenarios!$E$9/Scenarios!$E$7*10000 -> 105.78378 | D5: =Scenarios!$E$8*$A5*D$4*Scenarios!$E$9/Scenarios!$E$7*10000 -> 126.94053 | E5: =Scenarios!$E$8*$A5*E$4*Scenarios!$E$9/Scenarios!$E$7*10000 -> 148.09729 | F5: =Scenarios!$E$8*$A5*F$4*Scenarios!$E$9/Scenarios!$E$7*10000 -> 169.25404 | G5: =Scenarios!$E$8*$A5*G$4*Scenarios!$E$9/Scenarios!$E$7*10000 -> 190.4108 | H5: =Scenarios!$E$8*$A5*H$4*Scenarios!$E$9/Scenarios!$E$7*10000 -> 211.56755
A6: 0.15 | B6: =Scenarios!$E$8*$A6*B$4*Scenarios!$E$9/Scenarios!$E$7*10000 -> 105.78378 | C6: =Scenarios!$E$8*$A6*C$4*Scenarios!$E$9/Scenarios!$E$7*10000 -> 132.22972 | D6: =Scenarios!$E$8*$A6*D$4*Scenarios!$E$9/Scenarios!$E$7*10000 -> 158.67567 | E6: =Scenarios!$E$8*$A6*E$4*Scenarios!$E$9/Scenarios!$E$7*10000 -> 185.12161 | F6: =Scenarios!$E$8*$A6*F$4*Scenarios!$E$9/Scenarios!$E$7*10000 -> 211.56755 | G6: =Scenarios!$E$8*$A6*G$4*Scenarios!$E$9/Scenarios!$E$7*10000 -> 238.0135 | H6: =Scenarios!$E$8*$A6*H$4*Scenarios!$E$9/Scenarios!$E$7*10000 -> 264.45944
A7: 0.18 | B7: =Scenarios!$E$8*$A7*B$4*Scenarios!$E$9/Scenarios!$E$7*10000 -> 126.94053 | C7: =Scenarios!$E$8*$A7*C$4*Scenarios!$E$9/Scenarios!$E$7*10000 -> 158.67567 | D7: =Scenarios!$E$8*$A7*D$4*Scenarios!$E$9/Scenarios!$E$7*10000 -> 190.4108 | E7: =Scenarios!$E$8*$A7*E$4*Scenarios!$E$9/Scenarios!$E$7*10000 -> 222.14593 | F7: =Scenarios!$E$8*$A7*F$4*Scenarios!$E$9/Scenarios!$E$7*10000 -> 253.88107 | G7: =Scenarios!$E$8*$A7*G$4*Scenarios!$E$9/Scenarios!$E$7*10000 -> 285.6162 | H7: =Scenarios!$E$8*$A7*H$4*Scenarios!$E$9/Scenarios!$E$7*10000 -> 317.35133
A8: 0.21 | B8: =Scenarios!$E$8*$A8*B$4*Scenarios!$E$9/Scenarios!$E$7*10000 -> 148.09729 | C8: =Scenarios!$E$8*$A8*C$4*Scenarios!$E$9/Scenarios!$E$7*10000 -> 185.12161 | D8: =Scenarios!$E$8*$A8*D$4*Scenarios!$E$9/Scenarios!$E$7*10000 -> 222.14593 | E8: =Scenarios!$E$8*$A8*E$4*Scenarios!$E$9/Scenarios!$E$7*10000 -> 259.17025 | F8: =Scenarios!$E$8*$A8*F$4*Scenarios!$E$9/Scenarios!$E$7*10000 -> 296.19458 | G8: =Scenarios!$E$8*$A8*G$4*Scenarios!$E$9/Scenarios!$E$7*10000 -> 333.2189 | H8: =Scenarios!$E$8*$A8*H$4*Scenarios!$E$9/Scenarios!$E$7*10000 -> 370.24322
A9: 0.24 | B9: =Scenarios!$E$8*$A9*B$4*Scenarios!$E$9/Scenarios!$E$7*10000 -> 169.25404 | C9: =Scenarios!$E$8*$A9*C$4*Scenarios!$E$9/Scenarios!$E$7*10000 -> 211.56755 | D9: =Scenarios!$E$8*$A9*D$4*Scenarios!$E$9/Scenarios!$E$7*10000 -> 253.88107 | E9: =Scenarios!$E$8*$A9*E$4*Scenarios!$E$9/Scenarios!$E$7*10000 -> 296.19458 | F9: =Scenarios!$E$8*$A9*F$4*Scenarios!$E$9/Scenarios!$E$7*10000 -> 338.50809 | G9: =Scenarios!$E$8*$A9*G$4*Scenarios!$E$9/Scenarios!$E$7*10000 -> 380.8216 | H9: =Scenarios!$E$8*$A9*H$4*Scenarios!$E$9/Scenarios!$E$7*10000 -> 423.13511
A11: 2025A DM contribution (bps), from Inputs | B11: =Inputs!B33/Inputs!B6*10000 -> 167.57826
A12: 2025A e and s | B12: =Inputs!B25 -> 0.18 | C12: =Inputs!B35 -> 0.52805281
A13: Reading: at the calibrated e (18%) you need s to rise by roughly 10 pts per year just to add ~30 bps by 2028; with e flat and s flat the DM lever adds nothing further. Cells to the right of s = 100% are impossible.

Sheet Evidence
A1: What the two workbooks say, mapped to the model's levers
A2: Counts are copied from data/spotify_autoplay_sentiment.xlsx and data/discovery_mode_efficacy.xlsx (blue); ratios are formulas. See the memo for method caveats.
A4: 1. Autoplay / recommendation discussion on r/spotify + r/truespotify (lever: e)
A5: Metric | B5: 2023 | C5: 2024 | D5: 2025 | E5: 2026 YTD | F5: Lever | G5: Reading
A6: All posts | B6: 67394 | C6: 72114 | D6: 45831 | E6: 25026
A7: Posts about autoplay / recommendations | B7: 4793 | C7: 7156 | D7: 5425 | E7: 2574
A8: Share of all posts | B8: =B7/B6 -> 0.071119091 | C8: =C7/C6 -> 0.099231772 | D8: =D7/D6 -> 0.11836966 | E8: =E7/E6 -> 0.10285303 | F8: e | G8: Share rose through 2025 and slipped in 2026 YTD. Weak evidence of a plateau: the 2026 archive is thin for Jul-Sep, and total subreddit volume is falling.
A9: Posts mentioning DJ / daylist / Smart Shuffle | B9: 947 | C9: 1231 | D9: 778 | E9: 411
A10: as share of autoplay posts | B10: =B9/B7 -> 0.1975798 | C10: =C9/C7 -> 0.17202348 | D10: =D9/D7 -> 0.14341014 | E10: =E9/E7 -> 0.15967366 | F10: e | G10: The AI DJ / Smart Shuffle novelty is fading: mention share fell from 20% to 16%. Smart Shuffle became removable in April 2025 (959-upvote post).
A11: Posts mentioning Discover Weekly / Release Radar | B11: 367 | C11: 572 | D11: 567 | E11: 257
A12: as share of autoplay posts | B12: =B11/B7 -> 0.076569998 | C12: =C11/C7 -> 0.079932923 | D12: =D11/D7 -> 0.10451613 | E12: =E11/E7 -> 0.0998446
A13: Posts on AI-generated music | B13: 15 | C13: 43 | D13: 169 | E13: 119
A14: as share of autoplay posts | B14: =B13/B7 -> 0.0031295639 | C14: =C13/C7 -> 0.0060089435 | D14: =D13/D7 -> 0.031152074 | E14: =E13/E7 -> 0.046231546 | F14: e (quality) | G14: From 0.3% to 4.6% of topic posts. The clean-up Spotify announced in Sept 2025 (AI labels, spam filter) trims recommendation inventory and is the main channel by which e could fall.
A15: Posts on paid / pushed content (Discovery Mode, payola, sponsored) | B15: 24 | C15: 89 | D15: 55 | E15: 47
A16: as share of autoplay posts | B16: =B15/B7 -> 0.0050073023 | C16: =C15/C7 -> 0.012437116 | D16: =D15/D7 -> 0.010138249 | E16: =E15/E7 -> 0.018259518 | F16: backlash | G16: Listener-side awareness of paid placement is small but at its highest in 2026. Only one of the 4,000 scored posts says 'discovery mode' by name: listeners do not see the program, they see 'sponsored recs'.
A18: 2. Sentiment of the scored sample (1,000 posts per year)
A19: Metric | B19: 2023 | C19: 2024 | D19: 2025 | E19: 2026 YTD | F19: Lever | G19: Reading
A20: Negative, all scored posts | B20: 340 | C20: 366 | D20: 391 | E20: 424
A21: Positive, all scored posts | B21: 232 | C21: 246 | D21: 279 | E21: 242
A22: Share negative, headline | B22: =B20/1000 -> 0.34 | C22: =C20/1000 -> 0.366 | D22: =D20/1000 -> 0.391 | E22: =E20/1000 -> 0.424
A23: Net sentiment (positive minus negative share) | B23: =(B21-B20)/1000 -> -0.108 | C23: =(C21-C20)/1000 -> -0.12 | D23: =(D21-D20)/1000 -> -0.112 | E23: =(E21-E20)/1000 -> -0.182
A24: Deleted / removed posts in sample (title only) | B24: 262 | C24: 143 | D24: 39 | E24: 47
A25: Negative among deleted / removed | B25: 60 | C25: 30 | D25: 8 | E25: 9
A26: Share negative, intact posts only (the cleaner series) | B26: =(B20-B25)/(1000-B24) -> 0.37940379 | C26: =(C20-C25)/(1000-C24) -> 0.39206534 | D26: =(D20-D25)/(1000-D24) -> 0.39854318 | E26: =(E20-E25)/(1000-E24) -> 0.43546695 | F26: e, churn | G26: Deleted posts score ~21% negative vs ~40% for intact ones and were 26% of the 2023 sample but 4-5% of 2025-26. On intact posts the deterioration is ~5-6 pts, not 8. Still rising, with 2026 H1 the worst half; 2026 Q3 improved to 39%.
A27: Share of scored posts with cancel / switch language | B27: 0.006 | C27: 0.014 | D27: 0.012 | E27: 0.024 | G27: Regex on cancel / unsubscribe / switched to Apple, Tidal, YouTube / goodbye Spotify. 56 posts in total; directional only.
A28: Discovery love posts, share positive | B28: 0.71 | C28: 0.44 | D28: 0.71 | E28: 0.68 | G28: The pro-recommendation pocket is stable at ~1-2% of topic posts: the user base is polarising, not uniformly souring.
A30: 3. Discovery Mode efficacy (lever: s and the discount)
A31: Metric | B31: Value | C31: n | F31: Lever | G31: Reading
A32: Median Spotify-reported lift, campaigns Aug 2023 - Nov 2024 | B32: 4.06 | C32: 4 | F32: s | G32: Lift = DM-context streams in campaign / prior 28 days - 1. n = 4 vs 3: the gap is not statistically meaningful (Mann-Whitney p ~ 0.1) and the metric rewards songs with a tiny prior base.
A33: Median Spotify-reported lift, campaigns Jan 2025 - Jul 2026 | B33: 0.78 | C33: 3 | F33: s | G33: Direction is consistent with a crowded pool: a fixed set of Radio/Autoplay slots shared by more enrolled tracks.
A34: Saves + playlist adds per DM listener (median, 8 campaigns) | B34: 0.0124 | C34: 8 | F34: quality | G34: Spotify's own 'intent' metric. 0.7-4.8% per campaign; latest (Sep 2026) is the lowest at 0.68%.
A35: Saves per listener, artists' overall audience (median, 4 dashboards) | B35: 0.1985 | C35: 4 | F35: quality | G35: Different definition (saves only, 12 months) so read as order of magnitude: DM streams are ~16x lower intent. They still carry a royalty, at 70%.
A36: Share of first-hand reports that went up: artists under 10k listeners | B36: 1 | C36: 8 | F36: s | G36: All eight small artists went up; the long tail will keep enrolling.
A37: Share of first-hand reports that went up: artists 10k+ listeners | B37: 0.389 | C37: 18 | F37: s | G37: Above 10k it is a coin flip; mid-size indies are the enrollment that can leave.
A38: First-hand reports (all) | B38: 0.557 | C38: 70 | F38: s | G38: 39 up / 21 down / 7 mixed / 3 flat.
A39: DM-context streams as share of an enrolled artist's streams, established artists | B39: 0.04 | C39: 4 | F39: e | G39: 3.5-5% for 500k+ monthly-stream artists; 33-50% for catalog-heavy or tiny artists. The workbook's 7.5% 'median' mixes both groups.
A40: Switching DM off: change in radio / autoplay streams per day (two charted cases) | B40: -0.6 | C40: 2 | F40: s (defensive) | G40: -50% and -71%. Enrollment has become defensive, which supports enrollment creeping up even as the lift fades: good for s, bad for the program's reputation.

Sheet Notes
A1: Method, sources and caveats
A3: Mechanics | B3: Discovery Mode is a royalty discount, not revenue: 'Cost of revenue also reflects discounts provided by certain rights holders in return for promotional activities in connection with marketplace programs' (Spotify 20-F). Marquee and Showcase are sold to labels and booked as Ad-Supported revenue. So DM lifts Premium and Ad-Supported gross margin in proportion to where DM streams occur; Marquee lifts Ad-Supported revenue at near-100% margin.
A4: Why DM is a bounded lever | B4: DM reallocates a fixed pool of Radio / Autoplay / Mixes slots among enrolled tracks; it does not create streams (the Jan 2025 case: Spotify reported +55% in DM contexts while the song's total streams fell). Spotify's saving is therefore enrolled DM-context streams x 30% of their royalty, regardless of whether the artist gains. The ceiling is e x discount x royalty pool; only a larger e (autoplay share, new surfaces) or a bigger discount raises it.
A5: Why 'slowing' is a margin headwind, not just slower help | B5: Gross margin is a ratio. With revenue compounding at 12-14%, marketplace gross profit must grow at least that fast to hold its bps contribution; 2021-25 it grew ~41% a year. Scenario B (+8-12% a year) is close to zero incremental bps; Scenario C is negative.
A6: Calibration | B6: Marketplace gross profit 2025 ~ EUR 640m (4 x 'more than EUR 160m' in 2021) ~ 370 bps of consolidated GM. DM's share is undisclosed; at 45% it is ~EUR 290m ~ 170 bps. With e = 18% and a EUR 10.1bn royalty pool, that implies ~53% of eligible-surface streams are enrolled. Topic 2 and Topic 3 of the triangulation matrix exist to replace these two guesses.
A7: What the Reddit data can and cannot say | B7: r/spotify + r/truespotify posts, Arctic Shift archive, 210k posts. The topic share (7% -> 12% -> 10%) is the best proxy for autoplay salience, not usage. The sentiment model (twitter-roberta) scores overall tone, not tone toward the algorithm; deleted posts bias early years toward neutral; 2026 coverage is thin after June. Treat sentiment as a direction-of-travel input to e, worth no more than +/- 1 pt a year.
A8: What the DM data can and cannot say | B8: 70 first-hand artist reports and 35 screenshots from r/musicmarketing, self-selected. 7 campaign lifts (n = 4 vs 3 by era), 18 before/after pairs that actually trend toward 'Up' over time (mix shift toward small artists). The 'Reference' sheet's undated lift list mixes multiples and percentages and should not be used. Use the workbook for mechanism and direction, not magnitudes.
A9: Sources | B9: Spotify FY2025 20-F; Q1 and Q2 2026 shareholder letters (sec.gov 6-K exhibits); Investor Day June 8 2022 transcript (marketplace EUR 160m+ in 2021); Investor Day May 21 2026 recap (marketplace 4x since 2021; 35-40% GM by 2030); Loud & Clear 2026 (USD 11bn royalties 2025); artists.spotify.com Discovery Mode page (+50% saves, +44% playlist adds, +37% follows in month one; 33% of discoveries in algorithmic contexts); Billboard reporting on House Judiciary scrutiny and manager-reported fade of lifts from 200-300% to 20-30%.
A10: Reproduce | B10: analysis/build_gm_model.py builds this workbook; data/ holds the two source workbooks.
